Workbook
Name Аварийный: Нагрузка_щитов!$V$23:$AA$27
Name Автомат_номиналы: Справочная!$F$4:$G$13
Name гофра_пвх: Справочная_потребители!$Z$4:$AB$9
Name гофра_пнд: Справочная_потребители!$AD$4:$AF$9
Name ДГУ_итог: Нагрузка_щитов!$V$23:$AA$27
Name Для_диапазонов: 'В Акад'!$B$3:$M$4000
Name Для_расчета_кабелей: Кабельный_журнал!$I$5:$W$1000
Name Исходные_данные: 'Исходные данные'!$A$3:$AU$1000
Name Итог_щит_1: Нагрузка_щитов!$V$5:$AA$9
Name Итог_щит_2: Нагрузка_щитов!$V$14:$AA$18
Name Кабель_диаметр: Справочная_потребители!$T$4:$X$503
Name Кабель_номиналы: Справочная!$I$4:$J$19
Name Кабель_обозначение: Справочная!$L$4:$N$51
Name Кабель_сопротивление: Справочная!$B$4:$D$18
Name Кабельный_журнал: INDIRECT(Диапазоны!$C$34):INDIRECT(Диапазоны!$F$34)
Name Нагрузка_диапазон_1: Нагрузка_щитов!$D$2:$J$1000
Name Нумерация_щитов_1: Разбивка_по_щитам!$A$3:$A$1000
Name Нумерация_щитов_2: Разбивка_по_щитам!$B$3:$B$1000
Name Потребители_обозначение: Справочная!$P$4:$T$1000
Name Разбивка_нумерация_1: Разбивка_по_щитам!$A$3:$U$1000
Name Разбивка_нумерация_2: Разбивка_по_щитам!$B$3:$U$1000
Name Разбивка_нумерация_4: Разбивка_по_щитам!$D$2:$U$1000
Name Разбивка_нумерация_5: Разбивка_по_щитам!$E$2:$U$1000
Name Секция_1: Нагрузка_щитов!$V$5:$AA$9
Name Секция_2: Нагрузка_щитов!$V$14:$AA$18
Name Спецификация: Спецификация!$B$52:$J$225
Name Спецификация: Спецификация!$B$3:$J$175
Name Справочная_двигатели: Справочная_потребители!$B$4:$K$37
Name Справочная_ЛЭД: Справочная_потребители!$M$4:$O$19
Name Справочная_ПТО: Справочная!$AE$4:$AF$200
Name Щит_1: INDIRECT(Диапазоны!$C$4):INDIRECT(Диапазоны!$F$4)
Name Щит_2: INDIRECT(Диапазоны!$C$5):INDIRECT(Диапазоны!$F$5)
Name Этаж_обозначение: Справочная!$Y$4:$AB$19

Sheet Краткое руководство
C1: Версия таблицы 1.05 Демо | E1: Ведомость изменений | H1: Ведомость неисправляемых ошибок
B2: 1 | C2: Нельзя добавлять строки | E2: 1.01 Демо | F2: Создание таблицы | H2: Все резервы идут под одинаковой фазой, нет возможности задать в ручную
B3: 2 | C3: НЕЛЬЗЯ трогать ячейки выделенные синим цветом!!! | E3: 1.02 Демо | F3: Исправлены некоторые ошибки в расчетах
B4: 3 | C4: НЕЛЬЗЯ вставлять столбцы | E4: 1.03 Демо | F4: Добавлено выделение ячеек красным при нарушении потерь напряжения, добавлено выделение ячейки с кол-вом электроприемников
B5: 4 | C5: Нельзя вырезать данные (ctrl+x) | E5: 1.04а Демо | F5: 1.Исправлена ошибка автоназвания потребителя, если нет порядкового номера. 2.Добавлена возможность корректировки Кс и косинуса на листе "Нагрузка_Щитов" (ошибка защиты листа). 3.Начато исправление ошибки ненахождение артикулов на ПК с разделительным знаком "," в таблице ПТО в справочной.
B6: 5 | C6: Листы расставлены в порядке заполнения (Справочная>Исходные данные>Разбивка по щитам>ТКЗ>Нагрузка щитов>Спецификация), прочие листы - системные | E6: 1.04.2а Демо | F6: Исправлены некоторые ошибки в расчетах
B7: 6 | C7: На листе "Кабельный журнал" есть сводная таблица кабелей | E7: 1.04.2б Демо | F7: Добавлен лист токов КЗ для тестирования, добавлена справочная с Iп (не внедрен в расчеты)
B8: 7 | C8: На листе "Кабельный журнал" есть сводная таблица артикулов прокладки | E8: 1.04.2в Демо | F8: Исправлены некоторые ошибки в диапазонах
B9: 8 | C9: Номинал автомата нужен для расчета сечения кабеля, для других целей не используется | E9: 1.05 Демо | F9: Добавлен расчет пусковых токов, добавлен авто Cos(фи) (Нагрузка_щитов) Добавлен расчет КРМ + рекомндация по установке КРМ (Нагрузка_щитов)
B10: 9 | C10: Все ячейки, кроме нужных - заблокированы
B11: 10 | C11: Если какая-то ячейка выделилась красным - значит есть нарушение (ГОСТа, расчета или иное), меняй значения во вводимых данных. Выделенная ячейка как-то связана с ошибкой

Sheet Справочная
L2: Заполнить!!! | AE2: ПТО
B3: Сечение | C3: Индуктивное, Ом/км | D3: Активное, Ом/км | F3: Ток | G3: Автомат | I3: Ток | J3: Кабель | L3: Обознач | M3: Кабель | N3: Сечение (1-да; 2 -нет) | P3: Обознач | Q3: Потребитель | R3: Опуск | S3: 1 - этаж/2 - шлейф | T3: Пусковой ток 1 - нет/2 - двигатель/3-свет | V3: Обознач | W3: Расшифровка | Y3: Обознач | Z3: Этаж | AA3: Подъем | AB3: По другим этажам | AE3: Кабель | AF3: Артикул | AG3: Тип кабеля | AH3: Кол-во жил | AI3: Сечение | AJ3: Пол/Потолок
B4: 0.75 | C4: 0.13 | D4: 0.0175 | F4: 0 | G4: 6 | I4: 0 | J4: 1.5 | L4: мс | M4: ВВГнг(А)-LS | N4: 1 | P4: R | Q4: Розеточная группа | R4: 3 | S4: 1 | T4: 1 | V4: тпв | W4: Труба жесткая ПВХ | Y4: 00 | Z4: Подвальный этаж | AE4: =AG4&" ("&AH4&"х"&AI4&") "&AJ4 -> ВВГнг(А)-LS (2х1,5) 1 | AF4: МСК001 | AG4: ВВГнг(А)-LS | AH4: 2 | AI4: 1.5 | AJ4: 1
B5: 1 | C5: 0.12 | D5: 0.0175 | F5: 5.4 | G5: 10 | I5: 19 | J5: 2.5 | L5: мфр | M5: ВВГнг(А)-FRLS | N5: 1 | P5: FR | Q5: Фасадные розетки | R5: 7 | S5: 2 | T5: 1 | V5: тпн | W5: Труба жесткая ПНД | Y5: 0 | Z5: Цокольный этаж | AE5: =AG5&" ("&AH5&"х"&AI5&") "&AJ5 -> ВВГнг(А)-LS (2х1,5) 2 | AF5: МСК002 | AG5: ВВГнг(А)-LS | AH5: 2 | AI5: 1.5 | AJ5: 2
B6: 1.5 | C6: 0.11 | D6: 0.0175 | F6: 9 | G6: 16 | I6: 25 | J6: 4 | L6: ютп | M6: UTP 5e 4x2x0.51 | N6: 2 | P6: L | Q6: Осветительная группа | R6: 2 | S6: 1 | T6: 3 | V6: гпв | W6: Труба гофрированная ПВХ | Y6: 1 | Z6: Первый этаж | AE6: =AG6&" ("&AH6&"х"&AI6&") "&AJ6 -> ВВГнг(А)-LS (2х2,5) 1 | AF6: МСК003 | AG6: ВВГнг(А)-LS | AH6: 2 | AI6: 2.5 | AJ6: 1
B7: 2.5 | C7: 0.1 | D7: 0.0175 | F7: 14.4 | G7: 20 | I7: 33 | J7: 6 | L7: pe | M7: ПуГВ | N7: 1 | P7: FL | Q7: Фасадное освещение | R7: 4 | S7: 2 | T7: 3 | V7: гпн | W7: Труба гофрированная ПНД | Y7: 2 | Z7: Второй этаж | AE7: =AG7&" ("&AH7&"х"&AI7&") "&AJ7 -> ВВГнг(А)-LS (2х2,5) 2 | AF7: МСК004 | AG7: ВВГнг(А)-LS | AH7: 2 | AI7: 2.5 | AJ7: 2
B8: 4 | C8: 0.095 | D8: 0.0175 | F8: 18 | G8: 25 | I8: 42 | J8: 10 | L8: мб | M8: ВБШвнг(А)-LS | N8: 1 | P8: КУП | Q8: Коробка уравнивания потенциалов | R8: 5 | S8: 1 | T8: 1 | Y8: 3 | Z8: Третий этаж | AE8: =AG8&" ("&AH8&"х"&AI8&") "&AJ8 -> ВВГнг(А)-LS (3х1,5) 1 | AF8: МСК005 | AG8: ВВГнг(А)-LS | AH8: 3 | AI8: 1.5 | AJ8: 1
B9: 6 | C9: 0.09 | D9: 0.0175 | F9: 22.5 | G9: 32 | I9: 58 | J9: 16 | L9: кмс | M9: КГВВнг(А)-LS | N9: 1 | P9: РЕ | Q9: Точка заземления | R9: 4 | S9: 1 | T9: 1 | Y9: 4 | Z9: Четвёртый этаж | AE9: =AG9&" ("&AH9&"х"&AI9&") "&AJ9 -> ВВГнг(А)-LS (3х1,5) 2 | AF9: МСК006 | AG9: ВВГнг(А)-LS | AH9: 3 | AI9: 1.5 | AJ9: 2
B10: 10 | C10: 0.073 | D10: 0.0175 | F10: 28.8 | G10: 40 | I10: 78 | J10: 25 | L10: кмб | M10: КВБбШвнг(А)-LS 14x2.5 | N10: 2 | P10: SH | Q10: Привод штор | R10: 2 | S10: 1 | T10: 1 | AE10: =AG10&" ("&AH10&"х"&AI10&") "&AJ10 -> ВВГнг(А)-LS (3х2,5) 1 | AF10: МСК007 | AG10: ВВГнг(А)-LS | AH10: 3 | AI10: 2.5 | AJ10: 1
B11: 16 | C11: 0.0675 | D11: 0.0175 | F11: 36 | G11: 50 | I11: 104 | J11: 35 | L11: мфр | M11: ППГнг(А)-FRHF | N11: 1 | P11: LD | Q11: LED-подсветка | R11: 3 | S11: 1 | T11: 3 | AE11: =AG11&" ("&AH11&"х"&AI11&") "&AJ11 -> ВВГнг(А)-LS (3х2,5) 2 | AF11: МСК008 | AG11: ВВГнг(А)-LS | AH11: 3 | AI11: 2.5 | AJ11: 2
B12: 25 | C12: 0.0662 | D12: 0.0175 | F12: 45 | G12: 63 | I12: 127 | J12: 50 | L12: мшф | M12: ППГнг(А)-HF | N12: 1 | P12: LT | Q12: Трековое освещение | R12: 2 | S12: 1 | T12: 3 | AE12: =AG12&" ("&AH12&"х"&AI12&") "&AJ12 -> ВВГнг(А)-LS (3х4) 1 | AF12: МСК009 | AG12: ВВГнг(А)-LS | AH12: 3 | AI12: 4 | AJ12: 1
B13: 35 | C13: 0.0637 | D13: 0.0175 | F13: 56.7 | G13: Не исп | I13: 155 | J13: 70 | L13: кн | M13: J-Y(St)Y 2х2х0.8 | N13: 2 | P13: DA | Q13: Шина DALI | R13: 2 | S13: 2 | T13: 1 | AE13: =AG13&" ("&AH13&"х"&AI13&") "&AJ13 -> ВВГнг(А)-LS (3х4) 2 | AF13: МСК010 | AG13: ВВГнг(А)-LS | AH13: 3 | AI13: 4 | AJ13: 2
B14: 50 | C14: 0.0625 | D14: 0.0175 | I14: 196 | J14: 95 | L14: кф | M14: КИПЭВ 2х2х0.6 | N14: 2 | P14: ЭОК | Q14: Электрообогрев кровли и водостоков | R14: 2 | S14: 2 | T14: 1 | AE14: =AG14&" ("&AH14&"х"&AI14&") "&AJ14 -> ВВГнг(А)-LS (3х6) 1 | AF14: МСК011 | AG14: ВВГнг(А)-LS | AH14: 3 | AI14: 6 | AJ14: 1
B15: 70 | C15: 0.0612 | D15: 0.0175 | I15: 242 | J15: 120 | L15: кс | M15: КСПВГ 4х0.35 | N15: 2 | P15: V | Q15: Вытяжной вентилятор | R15: 2 | S15: 1 | T15: 1 | AE15: =AG15&" ("&AH15&"х"&AI15&") "&AJ15 -> ВВГнг(А)-LS (3х6) 2 | AF15: МСК012 | AG15: ВВГнг(А)-LS | AH15: 3 | AI15: 6 | AJ15: 2
B16: 95 | C16: 0.0602 | D16: 0.0175 | I16: 280 | J16: 150 | L16: фтп | M16: FTP 5e 4x2x0.51 | N16: 2 | P16: П | Q16: Приточная установка | R16: 4 | S16: 2 | T16: 1 | AE16: =AG16&" ("&AH16&"х"&AI16&") "&AJ16 -> ВВГнг(А)-LS (5х1,5) 1 | AF16: МСК013 | AG16: ВВГнг(А)-LS | AH16: 5 | AI16: 1.5 | AJ16: 1
B17: 150 | C17: 0.0596 | D17: 0.0175 | I17: 321 | J17: 185 | L17: эк | M17: МКЭШнг(A)-LS | N17: 1 | P17: НБ | Q17: Наружный блок кондиционирования | R17: 4 | S17: 2 | T17: 1 | AE17: =AG17&" ("&AH17&"х"&AI17&") "&AJ17 -> ВВГнг(А)-LS (5х1,5) 2 | AF17: МСК014 | AG17: ВВГнг(А)-LS | AH17: 5 | AI17: 1.5 | AJ17: 2
B18: 185 | C18: 0.0596 | D18: 0.0175 | I18: 369 | J18: 240 | L18: 5pe | M18: 5ПуГВ | N18: 1 | P18: К | Q18: Внутренний блок кондиционирования | R18: 2 | S18: 1 | T18: 1 | AE18: =AG18&" ("&AH18&"х"&AI18&") "&AJ18 -> ВВГнг(А)-LS (5х2,5) 1 | AF18: МСК015 | AG18: ВВГнг(А)-LS | AH18: 5 | AI18: 2.5 | AJ18: 1
I19: 438 | J19: Не исп | L19: 5мс | M19: 5хВВГнг(А)-LS | N19: 1 | P19: У | Q19: Увлажнитель | R19: 3 | S19: 2 | T19: 1 | AE19: =AG19&" ("&AH19&"х"&AI19&") "&AJ19 -> ВВГнг(А)-LS (5х2,5) 2 | AF19: МСК016 | AG19: ВВГнг(А)-LS | AH19: 5 | AI19: 2.5 | AJ19: 2
L20: 5мс2 | M20: 5хВВГнг(А)-LS | N20: 1 | P20: В | Q20: Вытяжная установка | R20: 4 | S20: 2 | T20: 1 | AE20: =AG20&" ("&AH20&"х"&AI20&") "&AJ20 -> ВВГнг(А)-LS (5х4) 1 | AF20: МСК017 | AG20: ВВГнг(А)-LS | AH20: 5 | AI20: 4 | AJ20: 1
P21: КЛ | Q21: Привод клапана вентиляции | R21: 3 | S21: 2 | T21: 1 | AE21: =AG21&" ("&AH21&"х"&AI21&") "&AJ21 -> ВВГнг(А)-LS (5х4) 2 | AF21: МСК018 | AG21: ВВГнг(А)-LS | AH21: 5 | AI21: 4 | AJ21: 2
P22: FLD | Q22: Фасадная подсветка | R22: 4 | S22: 2 | T22: 3 | AE22: =AG22&" ("&AH22&"х"&AI22&") "&AJ22 -> ВВГнг(А)-LS (5х6) 1 | AF22: МСК019 | AG22: ВВГнг(А)-LS | AH22: 5 | AI22: 6 | AJ22: 1
P23: ВРУ | Q23: Кабель от ВРУ | R23: 0 | S23: 2 | T23: 1 | AE23: =AG23&" ("&AH23&"х"&AI23&") "&AJ23 -> ВВГнг(А)-LS (5х6) 2 | AF23: МСК020 | AG23: ВВГнг(А)-LS | AH23: 5 | AI23: 6 | AJ23: 2
P24: Ввод | Q24: Вводной кабель | R24: 0 | S24: 2 | T24: 1 | AE24: =AG24&" ("&AH24&"х"&AI24&") "&AJ24 -> ВВГнг(А)-LS (5х10) 1 | AF24: МСК021 | AG24: ВВГнг(А)-LS | AH24: 5 | AI24: 10 | AJ24: 1
P25: ТЕ-О | Q25: Сервопривод отопления | R25: 2 | S25: 1 | T25: 1 | AE25: =AG25&" ("&AH25&"х"&AI25&") "&AJ25 -> ВВГнг(А)-LS (5х10) 2 | AF25: МСК022 | AG25: ВВГнг(А)-LS | AH25: 5 | AI25: 10 | AJ25: 2
P26: ТЕ-П | Q26: Сервопривод тёплого пола | R26: 2 | S26: 1 | T26: 1 | AE26: =AG26&" ("&AH26&"х"&AI26&") "&AJ26 -> ВВГнг(А)-LS (5х16) 1 | AF26: МСК023 | AG26: ВВГнг(А)-LS | AH26: 5 | AI26: 16 | AJ26: 1
P27: ЭК | Q27: Кран с электроприводом | R27: 2 | S27: 1 | T27: 1 | AE27: =AG27&" ("&AH27&"х"&AI27&") "&AJ27 -> ВВГнг(А)-LS (5х16) 2 | AF27: МСК024 | AG27: ВВГнг(А)-LS | AH27: 5 | AI27: 16 | AJ27: 2
AE28: =AG28&" ("&AH28&"х"&AI28&") "&AJ28 -> ВВГнг(А)-LS (5х25) 1 | AF28: МСК025 | AG28: ВВГнг(А)-LS | AH28: 5 | AI28: 25 | AJ28: 1
P29: ЩС-ГМ | Q29: Щит гидромассажной ванны | R29: 2 | S29: 2 | T29: 1 | AE29: =AG29&" ("&AH29&"х"&AI29&") "&AJ29 -> ВВГнг(А)-LS (5х25) 2 | AF29: МСК026 | AG29: ВВГнг(А)-LS | AH29: 5 | AI29: 25 | AJ29: 2
P30: ЩС-ГК | Q30: Щит горячей купели | R30: 2 | S30: 2 | T30: 1 | AE30: =AG30&" ("&AH30&"х"&AI30&") "&AJ30 -> ВВГнг(А)-LS (5х35) 1 | AF30: МСК027 | AG30: ВВГнг(А)-LS | AH30: 5 | AI30: 35 | AJ30: 1
P31: ЩС-ХК | Q31: Щит холодной купели | R31: 2 | S31: 2 | T31: 1 | AE31: =AG31&" ("&AH31&"х"&AI31&") "&AJ31 -> ВВГнг(А)-LS (5х35) 2 | AF31: МСК028 | AG31: ВВГнг(А)-LS | AH31: 5 | AI31: 35 | AJ31: 2
P32: ЩС-Б | Q32: Щит бассейна | R32: 2 | S32: 2 | T32: 1 | AE32: =AG32&" ("&AH32&"х"&AI32&") "&AJ32 -> ВВГнг(А)-LS (5х50) 1 | AF32: МСК029 | AG32: ВВГнг(А)-LS | AH32: 5 | AI32: 50 | AJ32: 1
AE33: =AG33&" ("&AH33&"х"&AI33&") "&AJ33 -> ВВГнг(А)-LS (5х50) 2 | AF33: МСК030 | AG33: ВВГнг(А)-LS | AH33: 5 | AI33: 50 | AJ33: 2
AE34: =AG34&" ("&AH34&"х"&AI34&") "&AJ34 -> ВВГнг(А)-LS (5х95) 1 | AF34: МСК031 | AG34: ВВГнг(А)-LS | AH34: 5 | AI34: 95 | AJ34: 1
P35: РМ | Q35: Контакты реле РМ в щите ЩОПС | R35: 0 | S35: 2 | T35: 1 | AE35: =AG35&" ("&AH35&"х"&AI35&") "&AJ35 -> ВВГнг(А)-LS (5х95) 2 | AF35: МСК032 | AG35: ВВГнг(А)-LS | AH35: 5 | AI35: 95 | AJ35: 2
P36: WD | Q36: Датчик протечки | R36: 1 | S36: 1 | T36: 1 | AE36: =AG36&" ("&AH36&"х"&AI36&") "&AJ36 -> ВВГнг(А)-LS (5х120) 1 | AF36: МСК033 | AG36: ВВГнг(А)-LS | AH36: 5 | AI36: 120 | AJ36: 1
P37: VK | Q37: Выключатель кнопочный/сухой контакт | R37: 2 | S37: 1 | T37: 1 | AE37: =AG37&" ("&AH37&"х"&AI37&") "&AJ37 -> ВВГнг(А)-LS (5х120) 2 | AF37: МСК034 | AG37: ВВГнг(А)-LS | AH37: 5 | AI37: 120 | AJ37: 2
P38: KNX | Q38: Шина оборудования KNX | R38: 2 | S38: 1 | T38: 1 | AE38: =AG38&" ("&AH38&"х"&AI38&") "&AJ38 -> ВВГнг(А)-LS (5х95) 1 | AF38: МСК035 | AG38: ВВГнг(А)-LS | AH38: 5 | AI38: 95 | AJ38: 1
P39: EIB | Q39: Шина датчиков присутствия KNX | R39: 3 | S39: 1 | T39: 1 | AE39: =AG39&" ("&AH39&"х"&AI39&") "&AJ39 -> ВВГнг(А)-LS (5х95) 2 | AF39: МСК036 | AG39: ВВГнг(А)-LS | AH39: 5 | AI39: 95 | AJ39: 2
P40: Н | Q40: Насос в ИТП | R40: 3 | S40: 2 | T40: 1 | AE40: =AG40&" ("&AH40&"х"&AI40&") "&AJ40 -> ВВГнг(А)-LS (5х120) 1 | AF40: МСК037 | AG40: ВВГнг(А)-LS | AH40: 5 | AI40: 120 | AJ40: 1
P41: СПД | Q41: Станция повышения давления | R41: 3 | S41: 2 | T41: 1 | AE41: =AG41&" ("&AH41&"х"&AI41&") "&AJ41 -> ВВГнг(А)-LS (5х120) 2 | AF41: МСК038 | AG41: ВВГнг(А)-LS | AH41: 5 | AI41: 120 | AJ41: 2
...

Sheet Исходные данные
A1: 1 | B1: 2 | C1: 3 | D1: 4 | E1: 5 | F1: 6 | G1: 7 | H1: 8 | I1: 9 | J1: 10 | K1: 11 | L1: 12 | M1: 13 | N1: 14 | O1: 15 | P1: 16 | Q1: 17 | R1: 18 | S1: 19 | T1: 20 | U1: 21 | V1: 22 | W1: 23 | X1: 24 | Y1: 25 | Z1: 26 | AA1: 27 | AB1: 28 | AC1: 29 | AD1: 30 | AE1: 31 | AF1: 32 | AG1: 33 | AH1: 34 | AI1: 35 | AJ1: 36 | AK1: 37 | AL1: 38 | AM1: 39 | AN1: 40 | AO1: 41 | AP1: 42 | AQ1: 43 | AR1: 44 | AS1: 45 | AT1: 46 | AU1: 47
B2: Наименование | C2: Наименование (ручное) | D2: Номер линии | E2: Мощность, кВт | F2: Напряжение | G2: Кол-во потребителей (для длины) | H2: Кол-во фаз | I2: Длина линии (по плану) | J2: Лоток | K2: Гофра ПВХ | L2: Гофра ПНД | M2: Длина линии (Итог) | N2: Марку кабеля | O2: Кол-во жил | P2: Косинус | Q2: Коэффициент спроса | R2: Сечение (ручное) | S2: автомат (ручное) | T2: Потолок - 1/Пол - 2 | U2: Ток | V2: Автомат | W2: Сечение | X2: Активное сопротивление | Y2: Индуктивное сопротивление | Z2: Коэффициент фазности | AA2: Синус | AB2: Потери, В | AC2: Потери, % | AD2: Уровень напряжения | AE2: Кабель | AF2: Кабель проиежуточный | AG2: Для потерь | AH2: Помещение | AI2: Потребитель | AJ2: Этаж/Шлейф | AK2: Наименование | AL2: ток | AM2: мощность | AN2: номер линии | AO2: УГО (заполняется в двг!) | AP2: Кабель | AQ2: Для наименования | AR2: Для наименования | AS2: Iпуск 1 | AT2: Iпуск 2 | AU2: Iпуск
A3: =D3 -> 0 | B3: =IFERROR(IF(VLOOKUP(AI3,Потребители_обозначение,4,FALSE)=1,VLOOKUP(AI3,Потребители_обозначение,2,FALSE)&" "&VLOOKUP(AJ3,Этаж_обозначение,2,FALSE)&" Пом. №"&AH3,VLOOKUP(AI3,Потребители_обозначение,2,FALSE)&" Шлейф №"&AJ3),VLOOKUP(D3,Потребители_обозначение,2,FALSE)) -> #N/A | M3: =IFERROR(IF(VLOOKUP(AI3,Потребители_обозначение,4,FALSE)=1,VLOOKUP(AI3,Потребители_обозначение,3,FALSE)*(G3*2-1)+I3+VLOOKUP(AJ3,Этаж_обозначение,3,FALSE)+VLOOKUP(AJ3,Этаж_обозначение,4,FALSE),VLOOKUP(AI3,Потребители_обозначение,3,FALSE)*(G3*2-1)+I3),I3) -> 0 | P3: =IF(VLOOKUP(AI3,Потребители_обозначение,5,FALSE)=2,_xlfn.IFS(H3=3,VLOOKUP(E3,Справочная_двигатели,8,FALSE),H3=1,VLOOKUP(E3,Справочная_двигатели,10,TRUE)),0.95) -> #N/A | U3: =_xlfn.IFS(H3=1,E3*1000/220,H3=3,E3/0.38/1.732) -> #N/A | V3: =IF(S3=0,VLOOKUP(U3,Автомат_номиналы,2,TRUE),S3) -> #N/A | W3: =IF(R3=0,VLOOKUP(V3,Кабель_номиналы,2,TRUE),R3) -> #N/A | X3: =VLOOKUP(W3,Кабель_сопротивление,3,FALSE) -> #N/A | Y3: =VLOOKUP(W3,Кабель_сопротивление,2,FALSE) -> #N/A | Z3: {=_xlfn.IFS(H3=1,2,H3=3,1)} -> #N/A | AA3: =ROUND(SIN(ACOS(P3)),2) -> #N/A | AB3: =Z3*(X3*I3/W3+Y3*I3*AA3/1000)*U3 -> #N/A | AC3: =ROUNDUP(AB3/220*100,2) -> #N/A | AD3: =_xlfn.IFS(H3=3,380,H3=1,220) -> #N/A | AE3: =VLOOKUP(N3,Кабель_обозначение,2,FALSE) -> #N/A | AF3: =IF(VLOOKUP(N3,Кабель_обозначение,3,FALSE)=1,AE3&" ("&O3&"х"&W3&")",AE3) -> #N/A | AG3: =IFERROR(IF(AC3>4.5,1,2),0) -> 0 | AH3: =IFERROR(LEFT(AR3,SEARCH(".",AR3)-1),AR3) | AI3: =IFERROR(LEFT(A3,SEARCH(".",A3)-1),A3) -> 0 | AJ3: =IFERROR(LEFT(AQ3,SEARCH(".",AQ3)-1),AQ3) -> #VALUE! | AK3: =IF(C3=0,B3,C3) -> #N/A | AL3: =ROUNDUP(U3,2) -> #N/A | AM3: =E3 -> 0 | AN3: =D3 -> 0 | AP3: =IF(W3=0,AE3,AF3&" L="&M3&"-"&AC3&"%") -> #N/A | AQ3: =RIGHT(A3,LEN(A3)-SEARCH(".",A3)) -> #VALUE! | AR3: =IFERROR(RIGHT(AQ3,LEN(AQ3)-SEARCH(".",AQ3)),"") | AS3: =IFERROR(IF(VLOOKUP(AI3,Потребители_обозначение,5,FALSE)=2,_xlfn.IFS(H3=3,VLOOKUP(E3,Справочная_двигатели,3,FALSE),H3=1,VLOOKUP(E3,Справочная_двигатели,5,TRUE)),0),0) -> 0 | AT3: =IFERROR(IF(VLOOKUP(AI3,Потребители_обозначение,5,FALSE)=3,VLOOKUP(E3,Справочная_ЛЭД,2,TRUE),0),0) -> 0 | AU3: =IF(AS3=0,AT3,AS3) -> 0
A4: =D4 -> Ввод.1 | B4: =IFERROR(IF(VLOOKUP(AI4,Потребители_обозначение,4,FALSE)=1,VLOOKUP(AI4,Потребители_обозначение,2,FALSE)&" "&VLOOKUP(AJ4,Этаж_обозначение,2,FALSE)&" Пом. №"&AH4,VLOOKUP(AI4,Потребители_обозначение,2,FALSE)&" Шлейф №"&AJ4),VLOOKUP(D4,Потребители_обозначение,2,FALSE)) -> Вводной кабель Шлейф №1 | C4: Основной ввод в дом №1 | D4: Ввод.1 | F4: 400 | G4: 1 | H4: 3 | M4: =IFERROR(IF(VLOOKUP(AI4,Потребители_обозначение,4,FALSE)=1,VLOOKUP(AI4,Потребители_обозначение,3,FALSE)*(G4*2-1)+I4+VLOOKUP(AJ4,Этаж_обозначение,3,FALSE)+VLOOKUP(AJ4,Этаж_обозначение,4,FALSE),VLOOKUP(AI4,Потребители_обозначение,3,FALSE)*(G4*2-1)+I4),I4) -> 0 | P4: =IF(VLOOKUP(AI4,Потребители_обозначение,5,FALSE)=2,_xlfn.IFS(H4=3,VLOOKUP(E4,Справочная_двигатели,8,FALSE),H4=1,VLOOKUP(E4,Справочная_двигатели,10,TRUE)),0.95) -> 0.95 | U4: =_xlfn.IFS(H4=1,E4*1000/220,H4=3,E4/0.38/1.732) -> 0 | V4: =IF(S4=0,VLOOKUP(U4,Автомат_номиналы,2,TRUE),S4) -> 6 | W4: =IF(R4=0,VLOOKUP(V4,Кабель_номиналы,2,TRUE),R4) -> 1.5 | X4: =VLOOKUP(W4,Кабель_сопротивление,3,FALSE) -> 0.0175 | Y4: =VLOOKUP(W4,Кабель_сопротивление,2,FALSE) -> 0.11 | Z4: {=_xlfn.IFS(H4=1,2,H4=3,1)} -> 1 | AA4: =ROUND(SIN(ACOS(P4)),2) -> 0.31 | AB4: =Z4*(X4*I4/W4+Y4*I4*AA4/1000)*U4 -> 0 | AC4: =ROUNDUP(AB4/220*100,2) -> 0 | AD4: =_xlfn.IFS(H4=3,380,H4=1,220) -> 380 | AE4: =VLOOKUP(N4,Кабель_обозначение,2,FALSE) -> #N/A | AF4: =IF(VLOOKUP(N4,Кабель_обозначение,3,FALSE)=1,AE4&" ("&O4&"х"&W4&")",AE4) -> #N/A | AG4: =IFERROR(IF(AC4>4.5,1,2),0) -> 2 | AH4: =IFERROR(LEFT(AR4,SEARCH(".",AR4)-1),AR4) | AI4: =IFERROR(LEFT(A4,SEARCH(".",A4)-1),A4) -> Ввод | AJ4: =IFERROR(LEFT(AQ4,SEARCH(".",AQ4)-1),AQ4) -> 1 | AK4: =IF(C4=0,B4,C4) -> Основной ввод в дом №1 | AL4: =ROUNDUP(U4,2) -> 0 | AM4: =E4 -> 0 | AN4: =D4 -> Ввод.1 | AP4: =IF(W4=0,AE4,AF4&" L="&M4&"-"&AC4&"%") -> #N/A | AQ4: =RIGHT(A4,LEN(A4)-SEARCH(".",A4)) -> 1 | AR4: =IFERROR(RIGHT(AQ4,LEN(AQ4)-SEARCH(".",AQ4)),"") | AS4: =IFERROR(IF(VLOOKUP(AI4,Потребители_обозначение,5,FALSE)=2,_xlfn.IFS(H4=3,VLOOKUP(E4,Справочная_двигатели,3,FALSE),H4=1,VLOOKUP(E4,Справочная_двигатели,5,TRUE)),0),0) -> 0 | AT4: =IFERROR(IF(VLOOKUP(AI4,Потребители_обозначение,5,FALSE)=3,VLOOKUP(E4,Справочная_ЛЭД,2,TRUE),0),0) -> 0 | AU4: =IF(AS4=0,AT4,AS4) -> 0
A5: =D5 -> Ввод.2 | B5: =IFERROR(IF(VLOOKUP(AI5,Потребители_обозначение,4,FALSE)=1,VLOOKUP(AI5,Потребители_обозначение,2,FALSE)&" "&VLOOKUP(AJ5,Этаж_обозначение,2,FALSE)&" Пом. №"&AH5,VLOOKUP(AI5,Потребители_обозначение,2,FALSE)&" Шлейф №"&AJ5),VLOOKUP(D5,Потребители_обозначение,2,FALSE)) -> Вводной кабель Шлейф №2 | C5: Основной ввод в дом №2 | D5: Ввод.2 | F5: 400 | G5: 1 | H5: 3 | M5: =IFERROR(IF(VLOOKUP(AI5,Потребители_обозначение,4,FALSE)=1,VLOOKUP(AI5,Потребители_обозначение,3,FALSE)*(G5*2-1)+I5+VLOOKUP(AJ5,Этаж_обозначение,3,FALSE)+VLOOKUP(AJ5,Этаж_обозначение,4,FALSE),VLOOKUP(AI5,Потребители_обозначение,3,FALSE)*(G5*2-1)+I5),I5) -> 0 | P5: =IF(VLOOKUP(AI5,Потребители_обозначение,5,FALSE)=2,_xlfn.IFS(H5=3,VLOOKUP(E5,Справочная_двигатели,8,FALSE),H5=1,VLOOKUP(E5,Справочная_двигатели,10,TRUE)),0.95) -> 0.95 | U5: =_xlfn.IFS(H5=1,E5*1000/220,H5=3,E5/0.38/1.732) -> 0 | V5: =IF(S5=0,VLOOKUP(U5,Автомат_номиналы,2,TRUE),S5) -> 6 | W5: =IF(VLOOKUP(N5,Кабель_обозначение,3,FALSE)=1,IF(R5=0,VLOOKUP(V5,Кабель_номиналы,2,TRUE),R5),0) -> #N/A | X5: =VLOOKUP(W5,Кабель_сопротивление,3,FALSE) -> #N/A | Y5: =VLOOKUP(W5,Кабель_сопротивление,2,FALSE) -> #N/A | Z5: {=_xlfn.IFS(H5=1,2,H5=3,1)} -> 1 | AA5: =ROUND(SIN(ACOS(P5)),2) -> 0.31 | AB5: =Z5*(X5*I5/W5+Y5*I5*AA5/1000)*U5 -> #N/A | AC5: =ROUNDUP(AB5/220*100,2) -> #N/A | AD5: =_xlfn.IFS(H5=3,380,H5=1,220) -> 380 | AE5: =VLOOKUP(N5,Кабель_обозначение,2,FALSE) -> #N/A | AF5: =IF(VLOOKUP(N5,Кабель_обозначение,3,FALSE)=1,AE5&" ("&O5&"х"&W5&")",AE5) -> #N/A | AG5: =IFERROR(IF(AC5>4.5,1,2),0) -> 0 | AH5: =IFERROR(LEFT(AR5,SEARCH(".",AR5)-1),AR5) | AI5: =IFERROR(LEFT(A5,SEARCH(".",A5)-1),A5) -> Ввод | AJ5: =IFERROR(LEFT(AQ5,SEARCH(".",AQ5)-1),AQ5) -> 2 | AK5: =IF(C5=0,B5,C5) -> Основной ввод в дом №2 | AL5: =ROUNDUP(U5,2) -> 0 | AM5: =E5 -> 0 | AN5: =D5 -> Ввод.2 | AP5: =IF(W5=0,AE5,AF5&" L="&M5&"-"&AC5&"%") -> #N/A | AQ5: =RIGHT(A5,LEN(A5)-SEARCH(".",A5)) -> 2 | AR5: =IFERROR(RIGHT(AQ5,LEN(AQ5)-SEARCH(".",AQ5)),"") | AS5: =IFERROR(IF(VLOOKUP(AI5,Потребители_обозначение,5,FALSE)=2,_xlfn.IFS(H5=3,VLOOKUP(E5,Справочная_двигатели,3,FALSE),H5=1,VLOOKUP(E5,Справочная_двигатели,5,TRUE)),0),0) -> 0 | AT5: =IFERROR(IF(VLOOKUP(AI5,Потребители_обозначение,5,FALSE)=3,VLOOKUP(E5,Справочная_ЛЭД,2,TRUE),0),0) -> 0 | AU5: =IF(AS5=0,AT5,AS5) -> 0
A6: =D6 -> ЩОВ-01 | B6: =IFERROR(IF(VLOOKUP(AI6,Потребители_обозначение,4,FALSE)=1,VLOOKUP(AI6,Потребители_обозначение,2,FALSE)&" "&VLOOKUP(AJ6,Этаж_обозначение,2,FALSE)&" Пом. №"&AH6,VLOOKUP(AI6,Потребители_обозначение,2,FALSE)&" Шлейф №"&AJ6),VLOOKUP(D6,Потребители_обозначение,2,FALSE)) -> #N/A | C6: Щит вентиляции ЩОВ-01 Цокольный этаж этаж Пом. №0.001Тб | D6: ЩОВ-01 | E6: 13.06 | F6: 400 | G6: 1 | H6: 3 | I6: 15 | J6: 0 | K6: 15 | L6: 0 | M6: =IFERROR(IF(VLOOKUP(AI6,Потребители_обозначение,4,FALSE)=1,VLOOKUP(AI6,Потребители_обозначение,3,FALSE)*(G6*2-1)+I6+VLOOKUP(AJ6,Этаж_обозначение,3,FALSE)+VLOOKUP(AJ6,Этаж_обозначение,4,FALSE),VLOOKUP(AI6,Потребители_обозначение,3,FALSE)*(G6*2-1)+I6),I6) -> 15 | N6: мс | O6: 5 | P6: 0.95 | Q6: 0.5 | R6: 6 | S6: 25 | U6: =_xlfn.IFS(H6=1,E6*1000/220,H6=3,E6/0.38/1.732) -> 19.843199 | V6: =IF(S6=0,VLOOKUP(U6,Автомат_номиналы,2,TRUE),S6) -> 25 | W6: =IF(R6=0,VLOOKUP(V6,Кабель_номиналы,2,TRUE),R6) -> 6 | X6: =VLOOKUP(W6,Кабель_сопротивление,3,FALSE) -> 0.0175 | Y6: =VLOOKUP(W6,Кабель_сопротивление,2,FALSE) -> 0.09 | Z6: {=_xlfn.IFS(H6=1,2,H6=3,1)} -> 1 | AA6: =ROUND(SIN(ACOS(P6)),2) -> 0.31 | AB6: =Z6*(X6*I6/W6+Y6*I6*AA6/1000)*U6 -> 0.87644434 | AC6: =ROUNDUP(AB6/220*100,2) -> 0.4 | AD6: =_xlfn.IFS(H6=3,380,H6=1,220) -> 380 | AE6: =VLOOKUP(N6,Кабель_обозначение,2,FALSE) -> ВВГнг(А)-LS | AF6: =IF(VLOOKUP(N6,Кабель_обозначение,3,FALSE)=1,AE6&" ("&O6&"х"&W6&")",AE6) -> ВВГнг(А)-LS (5х6) | AG6: =IFERROR(IF(AC6>4.5,1,2),0) -> 2 | AH6: =IFERROR(LEFT(AR6,SEARCH(".",AR6)-1),AR6) | AI6: =IFERROR(LEFT(A6,SEARCH(".",A6)-1),A6) -> ЩОВ-01 | AJ6: =IFERROR(LEFT(AQ6,SEARCH(".",AQ6)-1),AQ6) -> #VALUE! | AK6: =IF(C6=0,B6,C6) -> Щит вентиляции ЩОВ-01 Цокольный этаж этаж Пом. №0.001Тб | AL6: =ROUNDUP(U6,2) -> 19.85 | AM6: =E6 -> 13.06 | AN6: =D6 -> ЩОВ-01 | AP6: =IF(W6=0,AE6,AF6&" L="&M6&"-"&AC6&"%") -> ВВГнг(А)-LS (5х6) L=15-0,4% | AQ6: =RIGHT(A6,LEN(A6)-SEARCH(".",A6)) -> #VALUE! | AR6: =IFERROR(RIGHT(AQ6,LEN(AQ6)-SEARCH(".",AQ6)),"") | AS6: =IFERROR(IF(VLOOKUP(AI6,Потребители_обозначение,5,FALSE)=2,_xlfn.IFS(H6=3,VLOOKUP(E6,Справочная_двигатели,3,FALSE),H6=1,VLOOKUP(E6,Справочная_двигатели,5,TRUE)),0),0) -> 0 | AT6: =IFERROR(IF(VLOOKUP(AI6,Потребители_обозначение,5,FALSE)=3,VLOOKUP(E6,Справочная_ЛЭД,2,TRUE),0),0) -> 0 | AU6: =IF(AS6=0,AT6,AS6) -> 0
A7: =D7 -> ЩОВ-001 | B7: =IFERROR(IF(VLOOKUP(AI7,Потребители_обозначение,4,FALSE)=1,VLOOKUP(AI7,Потребители_обозначение,2,FALSE)&" "&VLOOKUP(AJ7,Этаж_обозначение,2,FALSE)&" Пом. №"&AH7,VLOOKUP(AI7,Потребители_обозначение,2,FALSE)&" Шлейф №"&AJ7),VLOOKUP(D7,Потребители_обозначение,2,FALSE)) -> #N/A | C7: Щит вентиляции ЩОВ-001 Подвальный этаж этаж Пом. №00.006Т | D7: ЩОВ-001 | E7: 211.22 | F7: 400 | G7: 1 | H7: 3 | I7: 58 | J7: 39 | K7: =M7-8-J7 -> 11 | L7: 0 | M7: =IFERROR(IF(VLOOKUP(AI7,Потребители_обозначение,4,FALSE)=1,VLOOKUP(AI7,Потребители_обозначение,3,FALSE)*(G7*2-1)+I7+VLOOKUP(AJ7,Этаж_обозначение,3,FALSE)+VLOOKUP(AJ7,Этаж_обозначение,4,FALSE),VLOOKUP(AI7,Потребители_обозначение,3,FALSE)*(G7*2-1)+I7),I7) -> 58 | N7: 5мс2 | O7: 1 | P7: 0.95 | Q7: 0.5 | R7: 185 | S7: 400 | U7: =_xlfn.IFS(H7=1,E7*1000/220,H7=3,E7/0.38/1.732) -> 320.925 | V7: =IF(S7=0,VLOOKUP(U7,Автомат_номиналы,2,TRUE),S7) -> 400 | W7: =IF(R7=0,VLOOKUP(V7,Кабель_номиналы,2,TRUE),R7) -> 185 | X7: =VLOOKUP(W7,Кабель_сопротивление,3,FALSE) -> 0.0175 | Y7: =VLOOKUP(W7,Кабель_сопротивление,2,FALSE) -> 0.0596 | Z7: {=_xlfn.IFS(H7=1,2,H7=3,1)} -> 1 | AA7: =ROUND(SIN(ACOS(P7)),2) -> 0.31 | AB7: =Z7*(X7*I7/W7+Y7*I7*AA7/1000)*U7 -> 2.1046565 | AC7: =ROUNDUP(AB7/220*100,2) -> 0.96 | AD7: =_xlfn.IFS(H7=3,380,H7=1,220) -> 380 | AE7: =VLOOKUP(N7,Кабель_обозначение,2,FALSE) -> 5хВВГнг(А)-LS | AF7: =IF(VLOOKUP(N7,Кабель_обозначение,3,FALSE)=1,AE7&" ("&O7&"х"&W7&")",AE7) -> 5хВВГнг(А)-LS (1х185) | AG7: =IFERROR(IF(AC7>4.5,1,2),0) -> 2 | AH7: =IFERROR(LEFT(AR7,SEARCH(".",AR7)-1),AR7) | AI7: =IFERROR(LEFT(A7,SEARCH(".",A7)-1),A7) -> ЩОВ-001 | AJ7: =IFERROR(LEFT(AQ7,SEARCH(".",AQ7)-1),AQ7) -> #VALUE! | AK7: =IF(C7=0,B7,C7) -> Щит вентиляции ЩОВ-001 Подвальный этаж этаж Пом. №00.006Т | AL7: =ROUNDUP(U7,2) -> 320.93 | AM7: =E7 -> 211.22 | AN7: =D7 -> ЩОВ-001 | AP7: =IF(W7=0,AE7,AF7&" L="&M7&"-"&AC7&"%") -> 5хВВГнг(А)-LS (1х185) L=58-0,96% | AQ7: =RIGHT(A7,LEN(A7)-SEARCH(".",A7)) -> #VALUE! | AR7: =IFERROR(RIGHT(AQ7,LEN(AQ7)-SEARCH(".",AQ7)),"") | AS7: =IFERROR(IF(VLOOKUP(AI7,Потребители_обозначение,5,FALSE)=2,_xlfn.IFS(H7=3,VLOOKUP(E7,Справочная_двигатели,3,FALSE),H7=1,VLOOKUP(E7,Справочная_двигатели,5,TRUE)),0),0) -> 0 | AT7: =IFERROR(IF(VLOOKUP(AI7,Потребители_обозначение,5,FALSE)=3,VLOOKUP(E7,Справочная_ЛЭД,2,TRUE),0),0) -> 0 | AU7: =IF(AS7=0,AT7,AS7) -> 0
A8: =D8 -> ЩОВ-002 | B8: =IFERROR(IF(VLOOKUP(AI8,Потребители_обозначение,4,FALSE)=1,VLOOKUP(AI8,Потребители_обозначение,2,FALSE)&" "&VLOOKUP(AJ8,Этаж_обозначение,2,FALSE)&" Пом. №"&AH8,VLOOKUP(AI8,Потребители_обозначение,2,FALSE)&" Шлейф №"&AJ8),VLOOKUP(D8,Потребители_обозначение,2,FALSE)) -> #N/A | C8: Щит вентиляции ЩОВ-002 Подвальный этаж этаж Пом. №00.003Т | D8: ЩОВ-002 | E8: 6.99 | F8: 400 | G8: 1 | H8: 3 | I8: 46 | J8: 29 | K8: =M8-5-J8 -> 12 | L8: 0 | M8: =IFERROR(IF(VLOOKUP(AI8,Потребители_обозначение,4,FALSE)=1,VLOOKUP(AI8,Потребители_обозначение,3,FALSE)*(G8*2-1)+I8+VLOOKUP(AJ8,Этаж_обозначение,3,FALSE)+VLOOKUP(AJ8,Этаж_обозначение,4,FALSE),VLOOKUP(AI8,Потребители_обозначение,3,FALSE)*(G8*2-1)+I8),I8) -> 46 | N8: мс | O8: 5 | P8: 0.95 | Q8: 0.5 | R8: 4 | S8: 16 | U8: =_xlfn.IFS(H8=1,E8*1000/220,H8=3,E8/0.38/1.732) -> 10.620518 | V8: =IF(S8=0,VLOOKUP(U8,Автомат_номиналы,2,TRUE),S8) -> 16 | W8: =IF(R8=0,VLOOKUP(V8,Кабель_номиналы,2,TRUE),R8) -> 4 | X8: =VLOOKUP(W8,Кабель_сопротивление,3,FALSE) -> 0.0175 | Y8: =VLOOKUP(W8,Кабель_сопротивление,2,FALSE) -> 0.095 | Z8: {=_xlfn.IFS(H8=1,2,H8=3,1)} -> 1 | AA8: =ROUND(SIN(ACOS(P8)),2) -> 0.31 | AB8: =Z8*(X8*I8/W8+Y8*I8*AA8/1000)*U8 -> 2.1517668 | AC8: =ROUNDUP(AB8/220*100,2) -> 0.98 | AD8: =_xlfn.IFS(H8=3,380,H8=1,220) -> 380 | AE8: =VLOOKUP(N8,Кабель_обозначение,2,FALSE) -> ВВГнг(А)-LS | AF8: =IF(VLOOKUP(N8,Кабель_обозначение,3,FALSE)=1,AE8&" ("&O8&"х"&W8&")",AE8) -> ВВГнг(А)-LS (5х4) | AG8: =IFERROR(IF(AC8>4.5,1,2),0) -> 2 | AH8: =IFERROR(LEFT(AR8,SEARCH(".",AR8)-1),AR8) | AI8: =IFERROR(LEFT(A8,SEARCH(".",A8)-1),A8) -> ЩОВ-002 | AJ8: =IFERROR(LEFT(AQ8,SEARCH(".",AQ8)-1),AQ8) -> #VALUE! | AK8: =IF(C8=0,B8,C8) -> Щит вентиляции ЩОВ-002 Подвальный этаж этаж Пом. №00.003Т | AL8: =ROUNDUP(U8,2) -> 10.63 | AM8: =E8 -> 6.99 | AN8: =D8 -> ЩОВ-002 | AP8: =IF(W8=0,AE8,AF8&" L="&M8&"-"&AC8&"%") -> ВВГнг(А)-LS (5х4) L=46-0,98% | AQ8: =RIGHT(A8,LEN(A8)-SEARCH(".",A8)) -> #VALUE! | AR8: =IFERROR(RIGHT(AQ8,LEN(AQ8)-SEARCH(".",AQ8)),"") | AS8: =IFERROR(IF(VLOOKUP(AI8,Потребители_обозначение,5,FALSE)=2,_xlfn.IFS(H8=3,VLOOKUP(E8,Справочная_двигатели,3,FALSE),H8=1,VLOOKUP(E8,Справочная_двигатели,5,TRUE)),0),0) -> 0 | AT8: =IFERROR(IF(VLOOKUP(AI8,Потребители_обозначение,5,FALSE)=3,VLOOKUP(E8,Справочная_ЛЭД,2,TRUE),0),0) -> 0 | AU8: =IF(AS8=0,AT8,AS8) -> 0
A9: =D9 -> ЩОВ-2 | B9: =IFERROR(IF(VLOOKUP(AI9,Потребители_обозначение,4,FALSE)=1,VLOOKUP(AI9,Потребители_обозначение,2,FALSE)&" "&VLOOKUP(AJ9,Этаж_обозначение,2,FALSE)&" Пом. №"&AH9,VLOOKUP(AI9,Потребители_обозначение,2,FALSE)&" Шлейф №"&AJ9),VLOOKUP(D9,Потребители_обозначение,2,FALSE)) -> #N/A | C9: Щит вентиляции ЩОВ-2 Техэтаж этаж Пом. №3.001Т | D9: ЩОВ-2 | E9: 11.09 | F9: 400 | G9: 1 | H9: 3 | I9: 56 | J9: 40 | K9: =M9-5-J9 -> 11 | L9: 0 | M9: =IFERROR(IF(VLOOKUP(AI9,Потребители_обозначение,4,FALSE)=1,VLOOKUP(AI9,Потребители_обозначение,3,FALSE)*(G9*2-1)+I9+VLOOKUP(AJ9,Этаж_обозначение,3,FALSE)+VLOOKUP(AJ9,Этаж_обозначение,4,FALSE),VLOOKUP(AI9,Потребители_обозначение,3,FALSE)*(G9*2-1)+I9),I9) -> 56 | N9: мс | O9: 5 | P9: 0.95 | Q9: 0.5 | R9: 4 | S9: 20 | U9: =_xlfn.IFS(H9=1,E9*1000/220,H9=3,E9/0.38/1.732) -> 16.850006 | V9: =IF(S9=0,VLOOKUP(U9,Автомат_номиналы,2,TRUE),S9) -> 20 | W9: =IF(R9=0,VLOOKUP(V9,Кабель_номиналы,2,TRUE),R9) -> 4 | X9: =VLOOKUP(W9,Кабель_сопротивление,3,FALSE) -> 0.0175 | Y9: =VLOOKUP(W9,Кабель_сопротивление,2,FALSE) -> 0.095 | Z9: {=_xlfn.IFS(H9=1,2,H9=3,1)} -> 1 | AA9: =ROUND(SIN(ACOS(P9)),2) -> 0.31 | AB9: =Z9*(X9*I9/W9+Y9*I9*AA9/1000)*U9 -> 4.1560405 | AC9: =ROUNDUP(AB9/220*100,2) -> 1.89 | AD9: =_xlfn.IFS(H9=3,380,H9=1,220) -> 380 | AE9: =VLOOKUP(N9,Кабель_обозначение,2,FALSE) -> ВВГнг(А)-LS | AF9: =IF(VLOOKUP(N9,Кабель_обозначение,3,FALSE)=1,AE9&" ("&O9&"х"&W9&")",AE9) -> ВВГнг(А)-LS (5х4) | AG9: =IFERROR(IF(AC9>4.5,1,2),0) -> 2 | AH9: =IFERROR(LEFT(AR9,SEARCH(".",AR9)-1),AR9) | AI9: =IFERROR(LEFT(A9,SEARCH(".",A9)-1),A9) -> ЩОВ-2 | AJ9: =IFERROR(LEFT(AQ9,SEARCH(".",AQ9)-1),AQ9) -> #VALUE! | AK9: =IF(C9=0,B9,C9) -> Щит вентиляции ЩОВ-2 Техэтаж этаж Пом. №3.001Т | AL9: =ROUNDUP(U9,2) -> 16.86 | AM9: =E9 -> 11.09 | AN9: =D9 -> ЩОВ-2 | AP9: =IF(W9=0,AE9,AF9&" L="&M9&"-"&AC9&"%") -> ВВГнг(А)-LS (5х4) L=56-1,89% | AQ9: =RIGHT(A9,LEN(A9)-SEARCH(".",A9)) -> #VALUE! | AR9: =IFERROR(RIGHT(AQ9,LEN(AQ9)-SEARCH(".",AQ9)),"") | AS9: =IFERROR(IF(VLOOKUP(AI9,Потребители_обозначение,5,FALSE)=2,_xlfn.IFS(H9=3,VLOOKUP(E9,Справочная_двигатели,3,FALSE),H9=1,VLOOKUP(E9,Справочная_двигатели,5,TRUE)),0),0) -> 0 | AT9: =IFERROR(IF(VLOOKUP(AI9,Потребители_обозначение,5,FALSE)=3,VLOOKUP(E9,Справочная_ЛЭД,2,TRUE),0),0) -> 0 | AU9: =IF(AS9=0,AT9,AS9) -> 0
A10: =D10 -> ЩР-001 | B10: =IFERROR(IF(VLOOKUP(AI10,Потребители_обозначение,4,FALSE)=1,VLOOKUP(AI10,Потребители_обозначение,2,FALSE)&" "&VLOOKUP(AJ10,Этаж_обозначение,2,FALSE)&" Пом. №"&AH10,VLOOKUP(AI10,Потребители_обозначение,2,FALSE)&" Шлейф №"&AJ10),VLOOKUP(D10,Потребители_обозначение,2,FALSE)) -> #N/A | C10: Щит распределительный ЩР-001 Подвальный этаж этаж Пом. №00.004Т | D10: ЩР-001 | E10: 11.86 | F10: 400 | G10: 1 | H10: 3 | I10: 41 | J10: 25 | K10: =M10-5-J10 -> 11 | L10: 0 | M10: =IFERROR(IF(VLOOKUP(AI10,Потребители_обозначение,4,FALSE)=1,VLOOKUP(AI10,Потребители_обозначение,3,FALSE)*(G10*2-1)+I10+VLOOKUP(AJ10,Этаж_обозначение,3,FALSE)+VLOOKUP(AJ10,Этаж_обозначение,4,FALSE),VLOOKUP(AI10,Потребители_обозначение,3,FALSE)*(G10*2-1)+I10),I10) -> 41 | N10: мс | O10: 5 | P10: 0.95 | Q10: 0.5 | R10: 4 | S10: 20 | U10: =_xlfn.IFS(H10=1,E10*1000/220,H10=3,E10/0.38/1.732) -> 18.019934 | V10: =IF(S10=0,VLOOKUP(U10,Автомат_номиналы,2,TRUE),S10) -> 20 | W10: =IF(R10=0,VLOOKUP(V10,Кабель_номиналы,2,TRUE),R10) -> 4 | X10: =VLOOKUP(W10,Кабель_сопротивление,3,FALSE) -> 0.0175 | Y10: =VLOOKUP(W10,Кабель_сопротивление,2,FALSE) -> 0.095 | Z10: {=_xlfn.IFS(H10=1,2,H10=3,1)} -> 1 | AA10: =ROUND(SIN(ACOS(P10)),2) -> 0.31 | AB10: =Z10*(X10*I10/W10+Y10*I10*AA10/1000)*U10 -> 3.2540839 | AC10: =ROUNDUP(AB10/220*100,2) -> 1.48 | AD10: =_xlfn.IFS(H10=3,380,H10=1,220) -> 380 | AE10: =VLOOKUP(N10,Кабель_обозначение,2,FALSE) -> ВВГнг(А)-LS | AF10: =IF(VLOOKUP(N10,Кабель_обозначение,3,FALSE)=1,AE10&" ("&O10&"х"&W10&")",AE10) -> ВВГнг(А)-LS (5х4) | AG10: =IFERROR(IF(AC10>4.5,1,2),0) -> 2 | AH10: =IFERROR(LEFT(AR10,SEARCH(".",AR10)-1),AR10) | AI10: =IFERROR(LEFT(A10,SEARCH(".",A10)-1),A10) -> ЩР-001 | AJ10: =IFERROR(LEFT(AQ10,SEARCH(".",AQ10)-1),AQ10) -> #VALUE! | AK10: =IF(C10=0,B10,C10) -> Щит распределительный ЩР-001 Подвальный этаж этаж Пом. №00.004Т | AL10: =ROUNDUP(U10,2) -> 18.02 | AM10: =E10 -> 11.86 | AN10: =D10 -> ЩР-001 | AP10: =IF(W10=0,AE10,AF10&" L="&M10&"-"&AC10&"%") -> ВВГнг(А)-LS (5х4) L=41-1,48% | AQ10: =RIGHT(A10,LEN(A10)-SEARCH(".",A10)) -> #VALUE! | AR10: =IFERROR(RIGHT(AQ10,LEN(AQ10)-SEARCH(".",AQ10)),"") | AS10: =IFERROR(IF(VLOOKUP(AI10,Потребители_обозначение,5,FALSE)=2,_xlfn.IFS(H10=3,VLOOKUP(E10,Справочная_двигатели,3,FALSE),H10=1,VLOOKUP(E10,Справочная_двигатели,5,TRUE)),0),0) -> 0 | AT10: =IFERROR(IF(VLOOKUP(AI10,Потребители_обозначение,5,FALSE)=3,VLOOKUP(E10,Справочная_ЛЭД,2,TRUE),0),0) -> 0 | AU10: =IF(AS10=0,AT10,AS10) -> 0
A11: =D11 -> ЩР-01 | B11: =IFERROR(IF(VLOOKUP(AI11,Потребители_обозначение,4,FALSE)=1,VLOOKUP(AI11,Потребители_обозначение,2,FALSE)&" "&VLOOKUP(AJ11,Этаж_обозначение,2,FALSE)&" Пом. №"&AH11,VLOOKUP(AI11,Потребители_обозначение,2,FALSE)&" Шлейф №"&AJ11),VLOOKUP(D11,Потребители_обозначение,2,FALSE)) -> #N/A | C11: Щит распределительный ЩР-01 Цокольный этаж этаж Пом. №0.001Т | D11: ЩР-01 | E11: 24.41 | F11: 400 | G11: 1 | H11: 3 | I11: 14 | J11: 0 | K11: 14 | L11: 0 | M11: =IFERROR(IF(VLOOKUP(AI11,Потребители_обозначение,4,FALSE)=1,VLOOKUP(AI11,Потребители_обозначение,3,FALSE)*(G11*2-1)+I11+VLOOKUP(AJ11,Этаж_обозначение,3,FALSE)+VLOOKUP(AJ11,Этаж_обозначение,4,FALSE),VLOOKUP(AI11,Потребители_обозначение,3,FALSE)*(G11*2-1)+I11),I11) -> 14 | N11: мс | O11: 5 | P11: 0.95 | Q11: 0.5 | R11: 10 | S11: 40 | U11: =_xlfn.IFS(H11=1,E11*1000/220,H11=3,E11/0.38/1.732) -> 37.088246 | V11: =IF(S11=0,VLOOKUP(U11,Автомат_номиналы,2,TRUE),S11) -> 40 | W11: =IF(R11=0,VLOOKUP(V11,Кабель_номиналы,2,TRUE),R11) -> 10 | X11: =VLOOKUP(W11,Кабель_сопротивление,3,FALSE) -> 0.0175 | Y11: =VLOOKUP(W11,Кабель_сопротивление,2,FALSE) -> 0.073 | Z11: {=_xlfn.IFS(H11=1,2,H11=3,1)} -> 1 | AA11: =ROUND(SIN(ACOS(P11)),2) -> 0.31 | AB11: =Z11*(X11*I11/W11+Y11*I11*AA11/1000)*U11 -> 0.92041233 | AC11: =ROUNDUP(AB11/220*100,2) -> 0.42 | AD11: =_xlfn.IFS(H11=3,380,H11=1,220) -> 380 | AE11: =VLOOKUP(N11,Кабель_обозначение,2,FALSE) -> ВВГнг(А)-LS | AF11: =IF(VLOOKUP(N11,Кабель_обозначение,3,FALSE)=1,AE11&" ("&O11&"х"&W11&")",AE11) -> ВВГнг(А)-LS (5х10) | AG11: =IFERROR(IF(AC11>4.5,1,2),0) -> 2 | AH11: =IFERROR(LEFT(AR11,SEARCH(".",AR11)-1),AR11) | AI11: =IFERROR(LEFT(A11,SEARCH(".",A11)-1),A11) -> ЩР-01 | AJ11: =IFERROR(LEFT(AQ11,SEARCH(".",AQ11)-1),AQ11) -> #VALUE! | AK11: =IF(C11=0,B11,C11) -> Щит распределительный ЩР-01 Цокольный этаж этаж Пом. №0.001Т | AL11: =ROUNDUP(U11,2) -> 37.09 | AM11: =E11 -> 24.41 | AN11: =D11 -> ЩР-01 | AP11: =IF(W11=0,AE11,AF11&" L="&M11&"-"&AC11&"%") -> ВВГнг(А)-LS (5х10) L=14-0,42% | AQ11: =RIGHT(A11,LEN(A11)-SEARCH(".",A11)) -> #VALUE! | AR11: =IFERROR(RIGHT(AQ11,LEN(AQ11)-SEARCH(".",AQ11)),"") | AS11: =IFERROR(IF(VLOOKUP(AI11,Потребители_обозначение,5,FALSE)=2,_xlfn.IFS(H11=3,VLOOKUP(E11,Справочная_двигатели,3,FALSE),H11=1,VLOOKUP(E11,Справочная_двигатели,5,TRUE)),0),0) -> 0 | AT11: =IFERROR(IF(VLOOKUP(AI11,Потребители_обозначение,5,FALSE)=3,VLOOKUP(E11,Справочная_ЛЭД,2,TRUE),0),0) -> 0 | AU11: =IF(AS11=0,AT11,AS11) -> 0
A12: =D12 -> ЩР-1 | B12: =IFERROR(IF(VLOOKUP(AI12,Потребители_обозначение,4,FALSE)=1,VLOOKUP(AI12,Потребители_обозначение,2,FALSE)&" "&VLOOKUP(AJ12,Этаж_обозначение,2,FALSE)&" Пом. №"&AH12,VLOOKUP(AI12,Потребители_обозначение,2,FALSE)&" Шлейф №"&AJ12),VLOOKUP(D12,Потребители_обозначение,2,FALSE)) -> #N/A | C12: Щит распределительный ЩР-1 Первый этаж этаж Пом. №1.003Б | D12: ЩР-1 | E12: 34.84 | F12: 400 | G12: 1 | H12: 3 | I12: =15+8+6+30+6 -> 65 | J12: =15+6+30 -> 51 | K12: =M12-5-J12 -> 9 | L12: 0 | M12: =IFERROR(IF(VLOOKUP(AI12,Потребители_обозначение,4,FALSE)=1,VLOOKUP(AI12,Потребители_обозначение,3,FALSE)*(G12*2-1)+I12+VLOOKUP(AJ12,Этаж_обозначение,3,FALSE)+VLOOKUP(AJ12,Этаж_обозначение,4,FALSE),VLOOKUP(AI12,Потребители_обозначение,3,FALSE)*(G12*2-1)+I12),I12) -> 65 | N12: мс | O12: 5 | P12: 0.95 | Q12: 0.5 | R12: 16 | S12: 63 | U12: =_xlfn.IFS(H12=1,E12*1000/220,H12=3,E12/0.38/1.732) -> 52.935456 | V12: =IF(S12=0,VLOOKUP(U12,Автомат_номиналы,2,TRUE),S12) -> 63 | W12: =IF(R12=0,VLOOKUP(V12,Кабель_номиналы,2,TRUE),R12) -> 16 | X12: =VLOOKUP(W12,Кабель_сопротивление,3,FALSE) -> 0.0175 | Y12: =VLOOKUP(W12,Кабель_сопротивление,2,FALSE) -> 0.0675 | Z12: {=_xlfn.IFS(H12=1,2,H12=3,1)} -> 1 | AA12: =ROUND(SIN(ACOS(P12)),2) -> 0.31 | AB12: =Z12*(X12*I12/W12+Y12*I12*AA12/1000)*U12 -> 3.8353789 | AC12: =ROUNDUP(AB12/220*100,2) -> 1.75 | AD12: =_xlfn.IFS(H12=3,380,H12=1,220) -> 380 | AE12: =VLOOKUP(N12,Кабель_обозначение,2,FALSE) -> ВВГнг(А)-LS | AF12: =IF(VLOOKUP(N12,Кабель_обозначение,3,FALSE)=1,AE12&" ("&O12&"х"&W12&")",AE12) -> ВВГнг(А)-LS (5х16) | AG12: =IFERROR(IF(AC12>4.5,1,2),0) -> 2 | AH12: =IFERROR(LEFT(AR12,SEARCH(".",AR12)-1),AR12) | AI12: =IFERROR(LEFT(A12,SEARCH(".",A12)-1),A12) -> ЩР-1 | AJ12: =IFERROR(LEFT(AQ12,SEARCH(".",AQ12)-1),AQ12) -> #VALUE! | AK12: =IF(C12=0,B12,C12) -> Щит распределительный ЩР-1 Первый этаж этаж Пом. №1.003Б | AL12: =ROUNDUP(U12,2) -> 52.94 | AM12: =E12 -> 34.84 | AN12: =D12 -> ЩР-1 | AP12: =IF(W12=0,AE12,AF12&" L="&M12&"-"&AC12&"%") -> ВВГнг(А)-LS (5х16) L=65-1,75% | AQ12: =RIGHT(A12,LEN(A12)-SEARCH(".",A12)) -> #VALUE! | AR12: =IFERROR(RIGHT(AQ12,LEN(AQ12)-SEARCH(".",AQ12)),"") | AS12: =IFERROR(IF(VLOOKUP(AI12,Потребители_обозначение,5,FALSE)=2,_xlfn.IFS(H12=3,VLOOKUP(E12,Справочная_двигатели,3,FALSE),H12=1,VLOOKUP(E12,Справочная_двигатели,5,TRUE)),0),0) -> 0 | AT12: =IFERROR(IF(VLOOKUP(AI12,Потребители_обозначение,5,FALSE)=3,VLOOKUP(E12,Справочная_ЛЭД,2,TRUE),0),0) -> 0 | AU12: =IF(AS12=0,AT12,AS12) -> 0
A13: =D13 -> ЩР-2 | B13: =IFERROR(IF(VLOOKUP(AI13,Потребители_обозначение,4,FALSE)=1,VLOOKUP(AI13,Потребители_обозначение,2,FALSE)&" "&VLOOKUP(AJ13,Этаж_обозначение,2,FALSE)&" Пом. №"&AH13,VLOOKUP(AI13,Потребители_обозначение,2,FALSE)&" Шлейф №"&AJ13),VLOOKUP(D13,Потребители_обозначение,2,FALSE)) -> #N/A | C13: Щит распределительный ЩР-2 Техэтаж этаж Пом. №3.001Т | D13: ЩР-2 | E13: 9.98 | F13: 400 | G13: 1 | H13: 3 | I13: 56 | J13: 40 | K13: =M13-5-J13 -> 11 | L13: 0 | M13: =IFERROR(IF(VLOOKUP(AI13,Потребители_обозначение,4,FALSE)=1,VLOOKUP(AI13,Потребители_обозначение,3,FALSE)*(G13*2-1)+I13+VLOOKUP(AJ13,Этаж_обозначение,3,FALSE)+VLOOKUP(AJ13,Этаж_обозначение,4,FALSE),VLOOKUP(AI13,Потребители_обозначение,3,FALSE)*(G13*2-1)+I13),I13) -> 56 | N13: мс | O13: 5 | P13: 0.95 | Q13: 0.5 | R13: 4 | S13: 16 | U13: =_xlfn.IFS(H13=1,E13*1000/220,H13=3,E13/0.38/1.732) -> 15.163486 | V13: =IF(S13=0,VLOOKUP(U13,Автомат_номиналы,2,TRUE),S13) -> 16 | W13: =IF(R13=0,VLOOKUP(V13,Кабель_номиналы,2,TRUE),R13) -> 4 | X13: =VLOOKUP(W13,Кабель_сопротивление,3,FALSE) -> 0.0175 | Y13: =VLOOKUP(W13,Кабель_сопротивление,2,FALSE) -> 0.095 | Z13: {=_xlfn.IFS(H13=1,2,H13=3,1)} -> 1 | AA13: =ROUND(SIN(ACOS(P13)),2) -> 0.31 | AB13: =Z13*(X13*I13/W13+Y13*I13*AA13/1000)*U13 -> 3.7400617 | AC13: =ROUNDUP(AB13/220*100,2) -> 1.71 | AD13: =_xlfn.IFS(H13=3,380,H13=1,220) -> 380 | AE13: =VLOOKUP(N13,Кабель_обозначение,2,FALSE) -> ВВГнг(А)-LS | AF13: =IF(VLOOKUP(N13,Кабель_обозначение,3,FALSE)=1,AE13&" ("&O13&"х"&W13&")",AE13) -> ВВГнг(А)-LS (5х4) | AG13: =IFERROR(IF(AC13>4.5,1,2),0) -> 2 | AH13: =IFERROR(LEFT(AR13,SEARCH(".",AR13)-1),AR13) | AI13: =IFERROR(LEFT(A13,SEARCH(".",A13)-1),A13) -> ЩР-2 | AJ13: =IFERROR(LEFT(AQ13,SEARCH(".",AQ13)-1),AQ13) -> #VALUE! | AK13: =IF(C13=0,B13,C13) -> Щит распределительный ЩР-2 Техэтаж этаж Пом. №3.001Т | AL13: =ROUNDUP(U13,2) -> 15.17 | AM13: =E13 -> 9.98 | AN13: =D13 -> ЩР-2 | AP13: =IF(W13=0,AE13,AF13&" L="&M13&"-"&AC13&"%") -> ВВГнг(А)-LS (5х4) L=56-1,71% | AQ13: =RIGHT(A13,LEN(A13)-SEARCH(".",A13)) -> #VALUE! | AR13: =IFERROR(RIGHT(AQ13,LEN(AQ13)-SEARCH(".",AQ13)),"") | AS13: =IFERROR(IF(VLOOKUP(AI13,Потребители_обозначение,5,FALSE)=2,_xlfn.IFS(H13=3,VLOOKUP(E13,Справочная_двигатели,3,FALSE),H13=1,VLOOKUP(E13,Справочная_двигатели,5,TRUE)),0),0) -> 0 | AT13: =IFERROR(IF(VLOOKUP(AI13,Потребители_обозначение,5,FALSE)=3,VLOOKUP(E13,Справочная_ЛЭД,2,TRUE),0),0) -> 0 | AU13: =IF(AS13=0,AT13,AS13) -> 0
A14: =D14 -> ЩС-Б | B14: =IFERROR(IF(VLOOKUP(AI14,Потребители_обозначение,4,FALSE)=1,VLOOKUP(AI14,Потребители_обозначение,2,FALSE)&" "&VLOOKUP(AJ14,Этаж_обозначение,2,FALSE)&" Пом. №"&AH14,VLOOKUP(AI14,Потребители_обозначение,2,FALSE)&" Шлейф №"&AJ14),VLOOKUP(D14,Потребители_обозначение,2,FALSE)) -> Щит бассейна | C14: Щит бассейна ЩС-Б Подвальный этаж этаж Пом. №00.002Тб | D14: ЩС-Б | E14: 24.99 | F14: 400 | G14: 1 | H14: 3 | I14: 51 | J14: 35 | K14: =M14-5-J14 -> 13 | L14: 0 | M14: =IFERROR(IF(VLOOKUP(AI14,Потребители_обозначение,4,FALSE)=1,VLOOKUP(AI14,Потребители_обозначение,3,FALSE)*(G14*2-1)+I14+VLOOKUP(AJ14,Этаж_обозначение,3,FALSE)+VLOOKUP(AJ14,Этаж_обозначение,4,FALSE),VLOOKUP(AI14,Потребители_обозначение,3,FALSE)*(G14*2-1)+I14),I14) -> 53 | N14: мс | O14: 5 | P14: 0.95 | Q14: 0.5 | R14: 10 | S14: 40 | U14: =_xlfn.IFS(H14=1,E14*1000/220,H14=3,E14/0.38/1.732) -> 37.969491 | V14: =IF(S14=0,VLOOKUP(U14,Автомат_номиналы,2,TRUE),S14) -> 40 | W14: =IF(R14=0,VLOOKUP(V14,Кабель_номиналы,2,TRUE),R14) -> 10 | X14: =VLOOKUP(W14,Кабель_сопротивление,3,FALSE) -> 0.0175 | Y14: =VLOOKUP(W14,Кабель_сопротивление,2,FALSE) -> 0.073 | Z14: {=_xlfn.IFS(H14=1,2,H14=3,1)} -> 1 | AA14: =ROUND(SIN(ACOS(P14)),2) -> 0.31 | AB14: =Z14*(X14*I14/W14+Y14*I14*AA14/1000)*U14 -> 3.4325988 | AC14: =ROUNDUP(AB14/220*100,2) -> 1.57 | AD14: =_xlfn.IFS(H14=3,380,H14=1,220) -> 380 | AE14: =VLOOKUP(N14,Кабель_обозначение,2,FALSE) -> ВВГнг(А)-LS | AF14: =IF(VLOOKUP(N14,Кабель_обозначение,3,FALSE)=1,AE14&" ("&O14&"х"&W14&")",AE14) -> ВВГнг(А)-LS (5х10) | AG14: =IFERROR(IF(AC14>4.5,1,2),0) -> 2 | AH14: =IFERROR(LEFT(AR14,SEARCH(".",AR14)-1),AR14) | AI14: =IFERROR(LEFT(A14,SEARCH(".",A14)-1),A14) -> ЩС-Б | AJ14: =IFERROR(LEFT(AQ14,SEARCH(".",AQ14)-1),AQ14) -> #VALUE! | AK14: =IF(C14=0,B14,C14) -> Щит бассейна ЩС-Б Подвальный этаж этаж Пом. №00.002Тб | AL14: =ROUNDUP(U14,2) -> 37.97 | AM14: =E14 -> 24.99 | AN14: =D14 -> ЩС-Б | AP14: =IF(W14=0,AE14,AF14&" L="&M14&"-"&AC14&"%") -> ВВГнг(А)-LS (5х10) L=53-1,57% | AQ14: =RIGHT(A14,LEN(A14)-SEARCH(".",A14)) -> #VALUE! | AR14: =IFERROR(RIGHT(AQ14,LEN(AQ14)-SEARCH(".",AQ14)),"") | AS14: =IFERROR(IF(VLOOKUP(AI14,Потребители_обозначение,5,FALSE)=2,_xlfn.IFS(H14=3,VLOOKUP(E14,Справочная_двигатели,3,FALSE),H14=1,VLOOKUP(E14,Справочная_двигатели,5,TRUE)),0),0) -> 0 | AT14: =IFERROR(IF(VLOOKUP(AI14,Потребители_обозначение,5,FALSE)=3,VLOOKUP(E14,Справочная_ЛЭД,2,TRUE),0),0) -> 0 | AU14: =IF(AS14=0,AT14,AS14) -> 0
A15: =D15 -> ЩС-ВК.001 | B15: =IFERROR(IF(VLOOKUP(AI15,Потребители_обозначение,4,FALSE)=1,VLOOKUP(AI15,Потребители_обозначение,2,FALSE)&" "&VLOOKUP(AJ15,Этаж_обозначение,2,FALSE)&" Пом. №"&AH15,VLOOKUP(AI15,Потребители_обозначение,2,FALSE)&" Шлейф №"&AJ15),VLOOKUP(D15,Потребители_обозначение,2,FALSE)) -> #N/A | C15: Щит дренажных насосов ЩС-ВК.001 Подвальный этаж этаж Пом. 00.002Т | D15: ЩС-ВК.001 | E15: 3.8 | F15: 230 | G15: 1 | H15: 1 | I15: 52 | J15: 35 | K15: =M15-5-J15 -> 12 | L15: 0 | M15: =IFERROR(IF(VLOOKUP(AI15,Потребители_обозначение,4,FALSE)=1,VLOOKUP(AI15,Потребители_обозначение,3,FALSE)*(G15*2-1)+I15+VLOOKUP(AJ15,Этаж_обозначение,3,FALSE)+VLOOKUP(AJ15,Этаж_обозначение,4,FALSE),VLOOKUP(AI15,Потребители_обозначение,3,FALSE)*(G15*2-1)+I15),I15) -> 52 | N15: мс | O15: 3 | P15: 0.95 | Q15: 0.5 | R15: 4 | S15: 20 | U15: =_xlfn.IFS(H15=1,E15*1000/220,H15=3,E15/0.38/1.732) -> 17.272727 | V15: =IF(S15=0,VLOOKUP(U15,Автомат_номиналы,2,TRUE),S15) -> 20 | W15: =IF(VLOOKUP(N15,Кабель_обозначение,3,FALSE)=1,IF(R15=0,VLOOKUP(V15,Кабель_номиналы,2,TRUE),R15),0) -> 4 | X15: =VLOOKUP(W15,Кабель_сопротивление,3,FALSE) -> 0.0175 | Y15: =VLOOKUP(W15,Кабель_сопротивление,2,FALSE) -> 0.095 | Z15: {=_xlfn.IFS(H15=1,2,H15=3,1)} -> 2 | AA15: =ROUND(SIN(ACOS(P15)),2) -> 0.31 | AB15: =Z15*(X15*I15/W15+Y15*I15*AA15/1000)*U15 -> 7.9119938 | AC15: =ROUNDUP(AB15/220*100,2) -> 3.6 | AD15: =_xlfn.IFS(H15=3,380,H15=1,220) -> 220 | AE15: =VLOOKUP(N15,Кабель_обозначение,2,FALSE) -> ВВГнг(А)-LS | AF15: =IF(VLOOKUP(N15,Кабель_обозначение,3,FALSE)=1,AE15&" ("&O15&"х"&W15&")",AE15) -> ВВГнг(А)-LS (3х4) | AG15: =IFERROR(IF(AC15>4.5,1,2),0) -> 2 | AH15: =IFERROR(LEFT(AR15,SEARCH(".",AR15)-1),AR15) | AI15: =IFERROR(LEFT(A15,SEARCH(".",A15)-1),A15) -> ЩС-ВК | AJ15: =IFERROR(LEFT(AQ15,SEARCH(".",AQ15)-1),AQ15) -> 001 | AK15: =IF(C15=0,B15,C15) -> Щит дренажных насосов ЩС-ВК.001 Подвальный этаж этаж Пом. 00.002Т | AL15: =ROUNDUP(U15,2) -> 17.28 | AM15: =E15 -> 3.8 | AN15: =D15 -> ЩС-ВК.001 | AP15: =IF(W15=0,AE15,AF15&" L="&M15&"-"&AC15&"%") -> ВВГнг(А)-LS (3х4) L=52-3,6% | AQ15: =RIGHT(A15,LEN(A15)-SEARCH(".",A15)) -> 001 | AR15: =IFERROR(RIGHT(AQ15,LEN(AQ15)-SEARCH(".",AQ15)),"") | AS15: =IFERROR(IF(VLOOKUP(AI15,Потребители_обозначение,5,FALSE)=2,_xlfn.IFS(H15=3,VLOOKUP(E15,Справочная_двигатели,3,FALSE),H15=1,VLOOKUP(E15,Справочная_двигатели,5,TRUE)),0),0) -> 0 | AT15: =IFERROR(IF(VLOOKUP(AI15,Потребители_обозначение,5,FALSE)=3,VLOOKUP(E15,Справочная_ЛЭД,2,TRUE),0),0) -> 0 | AU15: =IF(AS15=0,AT15,AS15) -> 0
A16: =D16 -> ЩС-ВК.002 | B16: =IFERROR(IF(VLOOKUP(AI16,Потребители_обозначение,4,FALSE)=1,VLOOKUP(AI16,Потребители_обозначение,2,FALSE)&" "&VLOOKUP(AJ16,Этаж_обозначение,2,FALSE)&" Пом. №"&AH16,VLOOKUP(AI16,Потребители_обозначение,2,FALSE)&" Шлейф №"&AJ16),VLOOKUP(D16,Потребители_обозначение,2,FALSE)) -> #N/A | C16: Щит насосов ЩС-ВК.002 Подвальный этаж этаж Пом. №00.002Тб | D16: ЩС-ВК.002 | E16: 2.4 | F16: 230 | G16: 1 | H16: 1 | I16: 51 | J16: 34 | K16: 12 | L16: 0 | M16: =IFERROR(IF(VLOOKUP(AI16,Потребители_обозначение,4,FALSE)=1,VLOOKUP(AI16,Потребители_обозначение,3,FALSE)*(G16*2-1)+I16+VLOOKUP(AJ16,Этаж_обозначение,3,FALSE)+VLOOKUP(AJ16,Этаж_обозначение,4,FALSE),VLOOKUP(AI16,Потребители_обозначение,3,FALSE)*(G16*2-1)+I16),I16) -> 51 | N16: мс | O16: 3 | P16: 0.95 | Q16: 0.7 | R16: 4 | S16: 16 | U16: =_xlfn.IFS(H16=1,E16*1000/220,H16=3,E16/0.38/1.732) -> 10.909091 | V16: =IF(S16=0,VLOOKUP(U16,Автомат_номиналы,2,TRUE),S16) -> 16 | W16: =IF(R16=0,VLOOKUP(V16,Кабель_номиналы,2,TRUE),R16) -> 4 | X16: =VLOOKUP(W16,Кабель_сопротивление,3,FALSE) -> 0.0175 | Y16: =VLOOKUP(W16,Кабель_сопротивление,2,FALSE) -> 0.095 | Z16: {=_xlfn.IFS(H16=1,2,H16=3,1)} -> 2 | AA16: =ROUND(SIN(ACOS(P16)),2) -> 0.31 | AB16: =Z16*(X16*I16/W16+Y16*I16*AA16/1000)*U16 -> 4.9009516 | AC16: =ROUNDUP(AB16/220*100,2) -> 2.23 | AD16: =_xlfn.IFS(H16=3,380,H16=1,220) -> 220 | AE16: =VLOOKUP(N16,Кабель_обозначение,2,FALSE) -> ВВГнг(А)-LS | AF16: =IF(VLOOKUP(N16,Кабель_обозначение,3,FALSE)=1,AE16&" ("&O16&"х"&W16&")",AE16) -> ВВГнг(А)-LS (3х4) | AG16: =IFERROR(IF(AC16>4.5,1,2),0) -> 2 | AH16: =IFERROR(LEFT(AR16,SEARCH(".",AR16)-1),AR16) | AI16: =IFERROR(LEFT(A16,SEARCH(".",A16)-1),A16) -> ЩС-ВК | AJ16: =IFERROR(LEFT(AQ16,SEARCH(".",AQ16)-1),AQ16) -> 002 | AK16: =IF(C16=0,B16,C16) -> Щит насосов ЩС-ВК.002 Подвальный этаж этаж Пом. №00.002Тб | AL16: =ROUNDUP(U16,2) -> 10.91 | AM16: =E16 -> 2.4 | AN16: =D16 -> ЩС-ВК.002 | AP16: =IF(W16=0,AE16,AF16&" L="&M16&"-"&AC16&"%") -> ВВГнг(А)-LS (3х4) L=51-2,23% | AQ16: =RIGHT(A16,LEN(A16)-SEARCH(".",A16)) -> 002 | AR16: =IFERROR(RIGHT(AQ16,LEN(AQ16)-SEARCH(".",AQ16)),"") | AS16: =IFERROR(IF(VLOOKUP(AI16,Потребители_обозначение,5,FALSE)=2,_xlfn.IFS(H16=3,VLOOKUP(E16,Справочная_двигатели,3,FALSE),H16=1,VLOOKUP(E16,Справочная_двигатели,5,TRUE)),0),0) -> 0 | AT16: =IFERROR(IF(VLOOKUP(AI16,Потребители_обозначение,5,FALSE)=3,VLOOKUP(E16,Справочная_ЛЭД,2,TRUE),0),0) -> 0 | AU16: =IF(AS16=0,AT16,AS16) -> 0
A17: =D17 -> ЩС-ВК.003 | B17: =IFERROR(IF(VLOOKUP(AI17,Потребители_обозначение,4,FALSE)=1,VLOOKUP(AI17,Потребители_обозначение,2,FALSE)&" "&VLOOKUP(AJ17,Этаж_обозначение,2,FALSE)&" Пом. №"&AH17,VLOOKUP(AI17,Потребители_обозначение,2,FALSE)&" Шлейф №"&AJ17),VLOOKUP(D17,Потребители_обозначение,2,FALSE)) -> #N/A | C17: Щит насосов ЩС-ВК.003 Подвальный этаж этаж Пом. №00.006Т | D17: ЩС-ВК.003 | E17: 4.34 | F17: 230 | G17: 1 | H17: 1 | I17: 53 | J17: 48 | K17: 5 | L17: 0 | M17: =IFERROR(IF(VLOOKUP(AI17,Потребители_обозначение,4,FALSE)=1,VLOOKUP(AI17,Потребители_обозначение,3,FALSE)*(G17*2-1)+I17+VLOOKUP(AJ17,Этаж_обозначение,3,FALSE)+VLOOKUP(AJ17,Этаж_обозначение,4,FALSE),VLOOKUP(AI17,Потребители_обозначение,3,FALSE)*(G17*2-1)+I17),I17) -> 53 | N17: мс | O17: 3 | P17: 0.95 | Q17: 0.7 | R17: 4 | S17: 20 | U17: =_xlfn.IFS(H17=1,E17*1000/220,H17=3,E17/0.38/1.732) -> 19.727273 | V17: =IF(S17=0,VLOOKUP(U17,Автомат_номиналы,2,TRUE),S17) -> 20 | W17: =IF(R17=0,VLOOKUP(V17,Кабель_номиналы,2,TRUE),R17) -> 4 | X17: =VLOOKUP(W17,Кабель_сопротивление,3,FALSE) -> 0.0175 | Y17: =VLOOKUP(W17,Кабель_сопротивление,2,FALSE) -> 0.095 | Z17: {=_xlfn.IFS(H17=1,2,H17=3,1)} -> 2 | AA17: =ROUND(SIN(ACOS(P17)),2) -> 0.31 | AB17: =Z17*(X17*I17/W17+Y17*I17*AA17/1000)*U17 -> 9.2101054 | AC17: =ROUNDUP(AB17/220*100,2) -> 4.19 | AD17: =_xlfn.IFS(H17=3,380,H17=1,220) -> 220 | AE17: =VLOOKUP(N17,Кабель_обозначение,2,FALSE) -> ВВГнг(А)-LS | AF17: =IF(VLOOKUP(N17,Кабель_обозначение,3,FALSE)=1,AE17&" ("&O17&"х"&W17&")",AE17) -> ВВГнг(А)-LS (3х4) | AG17: =IFERROR(IF(AC17>4.5,1,2),0) -> 2 | AH17: =IFERROR(LEFT(AR17,SEARCH(".",AR17)-1),AR17) | AI17: =IFERROR(LEFT(A17,SEARCH(".",A17)-1),A17) -> ЩС-ВК | AJ17: =IFERROR(LEFT(AQ17,SEARCH(".",AQ17)-1),AQ17) -> 003 | AK17: =IF(C17=0,B17,C17) -> Щит насосов ЩС-ВК.003 Подвальный этаж этаж Пом. №00.006Т | AL17: =ROUNDUP(U17,2) -> 19.73 | AM17: =E17 -> 4.34 | AN17: =D17 -> ЩС-ВК.003 | AP17: =IF(W17=0,AE17,AF17&" L="&M17&"-"&AC17&"%") -> ВВГнг(А)-LS (3х4) L=53-4,19% | AQ17: =RIGHT(A17,LEN(A17)-SEARCH(".",A17)) -> 003 | AR17: =IFERROR(RIGHT(AQ17,LEN(AQ17)-SEARCH(".",AQ17)),"") | AS17: =IFERROR(IF(VLOOKUP(AI17,Потребители_обозначение,5,FALSE)=2,_xlfn.IFS(H17=3,VLOOKUP(E17,Справочная_двигатели,3,FALSE),H17=1,VLOOKUP(E17,Справочная_двигатели,5,TRUE)),0),0) -> 0 | AT17: =IFERROR(IF(VLOOKUP(AI17,Потребители_обозначение,5,FALSE)=3,VLOOKUP(E17,Справочная_ЛЭД,2,TRUE),0),0) -> 0 | AU17: =IF(AS17=0,AT17,AS17) -> 0
A18: =D18 -> ЩУОВ | B18: =IFERROR(IF(VLOOKUP(AI18,Потребители_обозначение,4,FALSE)=1,VLOOKUP(AI18,Потребители_обозначение,2,FALSE)&" "&VLOOKUP(AJ18,Этаж_обозначение,2,FALSE)&" Пом. №"&AH18,VLOOKUP(AI18,Потребители_обозначение,2,FALSE)&" Шлейф №"&AJ18),VLOOKUP(D18,Потребители_обозначение,2,FALSE)) -> #N/A | C18: Щит управления обогрева воронок ЩУОВ Тех. этаж этаж Пом. №3.001 | D18: ЩУОВ | E18: 16.44 | F18: 400 | G18: 1 | H18: 3 | I18: 52 | J18: 39 | K18: =M18-5-J18 -> 8 | L18: 0 | M18: =IFERROR(IF(VLOOKUP(AI18,Потребители_обозначение,4,FALSE)=1,VLOOKUP(AI18,Потребители_обозначение,3,FALSE)*(G18*2-1)+I18+VLOOKUP(AJ18,Этаж_обозначение,3,FALSE)+VLOOKUP(AJ18,Этаж_обозначение,4,FALSE),VLOOKUP(AI18,Потребители_обозначение,3,FALSE)*(G18*2-1)+I18),I18) -> 52 | N18: мс | O18: 5 | P18: 0.95 | Q18: 0.7 | R18: 6 | S18: 32 | U18: =_xlfn.IFS(H18=1,E18*1000/220,H18=3,E18/0.38/1.732) -> 24.978729 | V18: =IF(S18=0,VLOOKUP(U18,Автомат_номиналы,2,TRUE),S18) -> 32 | W18: =IF(R18=0,VLOOKUP(V18,Кабель_номиналы,2,TRUE),R18) -> 6 | X18: =VLOOKUP(W18,Кабель_сопротивление,3,FALSE) -> 0.0175 | Y18: =VLOOKUP(W18,Кабель_сопротивление,2,FALSE) -> 0.09 | Z18: {=_xlfn.IFS(H18=1,2,H18=3,1)} -> 1 | AA18: =ROUND(SIN(ACOS(P18)),2) -> 0.31 | AB18: =Z18*(X18*I18/W18+Y18*I18*AA18/1000)*U18 -> 3.8246796 | AC18: =ROUNDUP(AB18/220*100,2) -> 1.74 | AD18: =_xlfn.IFS(H18=3,380,H18=1,220) -> 380 | AE18: =VLOOKUP(N18,Кабель_обозначение,2,FALSE) -> ВВГнг(А)-LS | AF18: =IF(VLOOKUP(N18,Кабель_обозначение,3,FALSE)=1,AE18&" ("&O18&"х"&W18&")",AE18) -> ВВГнг(А)-LS (5х6) | AG18: =IFERROR(IF(AC18>4.5,1,2),0) -> 2 | AH18: =IFERROR(LEFT(AR18,SEARCH(".",AR18)-1),AR18) | AI18: =IFERROR(LEFT(A18,SEARCH(".",A18)-1),A18) -> ЩУОВ | AJ18: =IFERROR(LEFT(AQ18,SEARCH(".",AQ18)-1),AQ18) -> #VALUE! | AK18: =IF(C18=0,B18,C18) -> Щит управления обогрева воронок ЩУОВ Тех. этаж этаж Пом. №3.001 | AL18: =ROUNDUP(U18,2) -> 24.98 | AM18: =E18 -> 16.44 | AN18: =D18 -> ЩУОВ | AP18: =IF(W18=0,AE18,AF18&" L="&M18&"-"&AC18&"%") -> ВВГнг(А)-LS (5х6) L=52-1,74% | AQ18: =RIGHT(A18,LEN(A18)-SEARCH(".",A18)) -> #VALUE! | AR18: =IFERROR(RIGHT(AQ18,LEN(AQ18)-SEARCH(".",AQ18)),"") | AS18: =IFERROR(IF(VLOOKUP(AI18,Потребители_обозначение,5,FALSE)=2,_xlfn.IFS(H18=3,VLOOKUP(E18,Справочная_двигатели,3,FALSE),H18=1,VLOOKUP(E18,Справочная_двигатели,5,TRUE)),0),0) -> 0 | AT18: =IFERROR(IF(VLOOKUP(AI18,Потребители_обозначение,5,FALSE)=3,VLOOKUP(E18,Справочная_ЛЭД,2,TRUE),0),0) -> 0 | AU18: =IF(AS18=0,AT18,AS18) -> 0
A19: =D19 -> ЩР-ПК | B19: =IFERROR(IF(VLOOKUP(AI19,Потребители_обозначение,4,FALSE)=1,VLOOKUP(AI19,Потребители_обозначение,2,FALSE)&" "&VLOOKUP(AJ19,Этаж_обозначение,2,FALSE)&" Пом. №"&AH19,VLOOKUP(AI19,Потребители_обозначение,2,FALSE)&" Шлейф №"&AJ19),VLOOKUP(D19,Потребители_обозначение,2,FALSE)) -> #N/A | C19: Щит профкухни ЩС-ПК Цокольный этаж этаж Пом. №0.0014Б | D19: ЩР-ПК | E19: 103.95 | F19: 400 | G19: 1 | H19: 3 | I19: 53 | J19: 38 | K19: 10 | L19: 0 | M19: =IFERROR(IF(VLOOKUP(AI19,Потребители_обозначение,4,FALSE)=1,VLOOKUP(AI19,Потребители_обозначение,3,FALSE)*(G19*2-1)+I19+VLOOKUP(AJ19,Этаж_обозначение,3,FALSE)+VLOOKUP(AJ19,Этаж_обозначение,4,FALSE),VLOOKUP(AI19,Потребители_обозначение,3,FALSE)*(G19*2-1)+I19),I19) -> 53 | N19: 5мс2 | O19: 1 | P19: 0.95 | Q19: 0.7 | R19: 95 | S19: 200 | U19: =_xlfn.IFS(H19=1,E19*1000/220,H19=3,E19/0.38/1.732) -> 157.94032 | V19: =IF(S19=0,VLOOKUP(U19,Автомат_номиналы,2,TRUE),S19) -> 200 | W19: =IF(R19=0,VLOOKUP(V19,Кабель_номиналы,2,TRUE),R19) -> 95 | X19: =VLOOKUP(W19,Кабель_сопротивление,3,FALSE) -> 0.0175 | Y19: =VLOOKUP(W19,Кабель_сопротивление,2,FALSE) -> 0.0602 | Z19: {=_xlfn.IFS(H19=1,2,H19=3,1)} -> 1 | AA19: =ROUND(SIN(ACOS(P19)),2) -> 0.31 | AB19: =Z19*(X19*I19/W19+Y19*I19*AA19/1000)*U19 -> 1.6982128 | AC19: =ROUNDUP(AB19/220*100,2) -> 0.78 | AD19: =_xlfn.IFS(H19=3,380,H19=1,220) -> 380 | AE19: =VLOOKUP(N19,Кабель_обозначение,2,FALSE) -> 5хВВГнг(А)-LS | AF19: =IF(VLOOKUP(N19,Кабель_обозначение,3,FALSE)=1,AE19&" ("&O19&"х"&W19&")",AE19) -> 5хВВГнг(А)-LS (1х95) | AG19: =IFERROR(IF(AC19>4.5,1,2),0) -> 2 | AH19: =IFERROR(LEFT(AR19,SEARCH(".",AR19)-1),AR19) | AI19: =IFERROR(LEFT(A19,SEARCH(".",A19)-1),A19) -> ЩР-ПК | AJ19: =IFERROR(LEFT(AQ19,SEARCH(".",AQ19)-1),AQ19) -> #VALUE! | AK19: =IF(C19=0,B19,C19) -> Щит профкухни ЩС-ПК Цокольный этаж этаж Пом. №0.0014Б | AL19: =ROUNDUP(U19,2) -> 157.95 | AM19: =E19 -> 103.95 | AN19: =D19 -> ЩР-ПК | AP19: =IF(W19=0,AE19,AF19&" L="&M19&"-"&AC19&"%") -> 5хВВГнг(А)-LS (1х95) L=53-0,78% | AQ19: =RIGHT(A19,LEN(A19)-SEARCH(".",A19)) -> #VALUE! | AR19: =IFERROR(RIGHT(AQ19,LEN(AQ19)-SEARCH(".",AQ19)),"") | AS19: =IFERROR(IF(VLOOKUP(AI19,Потребители_обозначение,5,FALSE)=2,_xlfn.IFS(H19=3,VLOOKUP(E19,Справочная_двигатели,3,FALSE),H19=1,VLOOKUP(E19,Справочная_двигатели,5,TRUE)),0),0) -> 0 | AT19: =IFERROR(IF(VLOOKUP(AI19,Потребители_обозначение,5,FALSE)=3,VLOOKUP(E19,Справочная_ЛЭД,2,TRUE),0),0) -> 0 | AU19: =IF(AS19=0,AT19,AS19) -> 0
A20: =D20 -> 0 | B20: =IFERROR(IF(VLOOKUP(AI20,Потребители_обозначение,4,FALSE)=1,VLOOKUP(AI20,Потребители_обозначение,2,FALSE)&" "&VLOOKUP(AJ20,Этаж_обозначение,2,FALSE)&" Пом. №"&AH20,VLOOKUP(AI20,Потребители_обозначение,2,FALSE)&" Шлейф №"&AJ20),VLOOKUP(D20,Потребители_обозначение,2,FALSE)) -> #N/A | M20: =IFERROR(IF(VLOOKUP(AI20,Потребители_обозначение,4,FALSE)=1,VLOOKUP(AI20,Потребители_обозначение,3,FALSE)*(G20*2-1)+I20+VLOOKUP(AJ20,Этаж_обозначение,3,FALSE)+VLOOKUP(AJ20,Этаж_обозначение,4,FALSE),VLOOKUP(AI20,Потребители_обозначение,3,FALSE)*(G20*2-1)+I20),I20) -> 0 | P20: =IF(VLOOKUP(AI20,Потребители_обозначение,5,FALSE)=2,_xlfn.IFS(H20=3,VLOOKUP(E20,Справочная_двигатели,8,FALSE),H20=1,VLOOKUP(E20,Справочная_двигатели,10,TRUE)),0.95) -> #N/A | Q20: 0.7 | U20: =_xlfn.IFS(H20=1,E20*1000/220,H20=3,E20/0.38/1.732) -> #N/A | V20: =IF(S20=0,VLOOKUP(U20,Автомат_номиналы,2,TRUE),S20) -> #N/A | W20: =IF(VLOOKUP(N20,Кабель_обозначение,3,FALSE)=1,IF(R20=0,VLOOKUP(V20,Кабель_номиналы,2,TRUE),R20),0) -> #N/A | X20: =VLOOKUP(W20,Кабель_сопротивление,3,FALSE) -> #N/A | Y20: =VLOOKUP(W20,Кабель_сопротивление,2,FALSE) -> #N/A | Z20: {=_xlfn.IFS(H20=1,2,H20=3,1)} -> #N/A | AA20: =ROUND(SIN(ACOS(P20)),2) -> #N/A | AB20: =Z20*(X20*I20/W20+Y20*I20*AA20/1000)*U20 -> #N/A | AC20: =ROUNDUP(AB20/220*100,2) -> #N/A | AD20: =_xlfn.IFS(H20=3,380,H20=1,220) -> #N/A | AE20: =VLOOKUP(N20,Кабель_обозначение,2,FALSE) -> #N/A | AF20: =IF(VLOOKUP(N20,Кабель_обозначение,3,FALSE)=1,AE20&" ("&O20&"х"&W20&")",AE20) -> #N/A | AG20: =IFERROR(IF(AC20>4.5,1,2),0) -> 0 | AH20: =IFERROR(LEFT(AR20,SEARCH(".",AR20)-1),AR20) | AI20: =IFERROR(LEFT(A20,SEARCH(".",A20)-1),A20) -> 0 | AJ20: =IFERROR(LEFT(AQ20,SEARCH(".",AQ20)-1),AQ20) -> #VALUE! | AK20: =IF(C20=0,B20,C20) -> #N/A | AL20: =ROUNDUP(U20,2) -> #N/A | AM20: =E20 -> 0 | AN20: =D20 -> 0 | AP20: =IF(W20=0,AE20,AF20&" L="&M20&"-"&AC20&"%") -> #N/A | AQ20: =RIGHT(A20,LEN(A20)-SEARCH(".",A20)) -> #VALUE! | AR20: =IFERROR(RIGHT(AQ20,LEN(AQ20)-SEARCH(".",AQ20)),"") | AS20: =IFERROR(IF(VLOOKUP(AI20,Потребители_обозначение,5,FALSE)=2,_xlfn.IFS(H20=3,VLOOKUP(E20,Справочная_двигатели,3,FALSE),H20=1,VLOOKUP(E20,Справочная_двигатели,5,TRUE)),0),0) -> 0 | AT20: =IFERROR(IF(VLOOKUP(AI20,Потребители_обозначение,5,FALSE)=3,VLOOKUP(E20,Справочная_ЛЭД,2,TRUE),0),0) -> 0 | AU20: =IF(AS20=0,AT20,AS20) -> 0
