Workbook
Name Автомат_номиналы: Справочная!$F$4:$G$13
Name гофра_пвх: Справочная_потребители!$Z$4:$AB$9
Name гофра_пнд: Справочная_потребители!$AD$4:$AF$9
Name Для_диапазонов: 'В Акад'!$B$3:$M$4000
Name Для_расчета_кабелей: Кабельный_журнал!$I$5:$W$1000
Name Исходные_данные: 'Исходные данные'!$A$3:$AT$1000
Name Итог_щит_1: 'В Акад'!$P$2:$U$6
Name Итог_щит_2: 'В Акад'!$P$9:$U$13
Name Кабель_диаметр: Справочная_потребители!$T$4:$X$503
Name Кабель_номиналы: Справочная!$I$4:$J$19
Name Кабель_обозначение: Справочная!$L$4:$N$51
Name Кабель_сопротивление: Справочная!$B$4:$D$19
Name Кабельный_журнал: Кабельный_журнал!$P$5:$AB$1000
Name Мин_автомат_БП: Справочная!$BF$5
Name Модели_список: OFFSET(Каталог!$AB$3,0,0,1+MAX(Каталог!$AA$4:$AA$500),1)
Name Модули_спр: Каталог!$C$4:$F$500
Name Нагрузка_диапазон_1: Нагрузка_щитов!$D$2:$I$1000
Name Нумерация_щитов_1: Разбивка_по_щитам!$A$3:$A$1000
Name Нумерация_щитов_2: Разбивка_по_щитам!$B$3:$B$1000
Name Потребители_обозначение: Справочная!$P$4:$Y$51
Name Разбивка_нумерация_1: Разбивка_по_щитам!$A$3:$U$1000
Name Разбивка_нумерация_2: Разбивка_по_щитам!$B$3:$U$1000
Name Разбивка_нумерация_4: Разбивка_по_щитам!$D$2:$U$1000
Name Разбивка_нумерация_5: Разбивка_по_щитам!$E$2:$U$1000
Name Спецификация: Спецификация!$B$3:$J$60
Name Список_автоматов: OFFSET(Каталог!$X$3,0,0,1+MAX(Каталог!$W$4:$W$500),1)
Name Список_аппаратов: OFFSET(Каталог!$Z$4,0,0,MAX(1,MAX(Каталог!$Y$4:$Y$500)),1)
Name Список_модулей: OFFSET(Каталог!$AB$3,0,0,1+MAX(Каталог!$AA$4:$AA$500),1)
Name Список_произв: OFFSET(Каталог!$AD$3,0,0,1+MAX(Каталог!$AC$4:$AC$500),1)
Name Справочная_двигатели: Справочная_потребители!$B$4:$K$37
Name Справочная_ЛЭД: Справочная_потребители!$M$4:$O$19
Name Справочная_ПТО: Справочная!$AJ$4:$AK$200
Name Столбцов_на_лист: Справочная!$BF$4
Name УГО_блоки: Справочная!$BA$4:$BC$30
Name УГО_спр: Справочная!$AU$4:$AY$72
Name Управление_цвета: Справочная!$AQ$4:$AS$10
Name Щит_1: INDIRECT(Диапазоны!$C$4):INDIRECT(Диапазоны!$F$4)
Name Щит_2: INDIRECT(Диапазоны!$C$5):INDIRECT(Диапазоны!$F$5)
Name Этаж_обозначение: Справочная!$AD$4:$AG$19

Sheet Краткое руководство
C1: ШАБЛОН однолинейки v3.8 — копируйте на каждый объект/щит (имя файла без номера версии). Пример заполнения — «Однолинейка_пример_ЖК-Остров.xlsx». | E1: Ведомость изменений | H1: Ведомость неисправляемых ошибок
B2: 1 | C2: Нельзя добавлять строки | E2: 1.01 Демо | F2: Создание таблицы | H2: Все резервы идут под одинаковой фазой, нет возможности задать в ручную
B3: 2 | C3: НЕЛЬЗЯ трогать ячейки выделенные синим цветом!!! | E3: 1.02 Демо | F3: Исправлены некоторые ошибки в расчетах
B4: 3 | C4: НЕЛЬЗЯ вставлять столбцы | E4: 1.03 Демо | F4: Добавлено выделение ячеек красным при нарушении потерь напряжения, добавлено выделение ячейки с кол-вом электроприемников
B5: 4 | C5: Нельзя вырезать данные (ctrl+x) | E5: 1.04а Демо | F5: 1.Исправлена ошибка автоназвания потребителя, если нет порядкового номера. 2.Добавлена возможность корректировки Кс и косинуса на листе "Нагрузка_Щитов" (ошибка защиты листа). 3.Начато исправление ошибки ненахождение артикулов на ПК с разделительным знаком "," в таблице ПТО в справочной.
B6: 5 | C6: Листы: синие — справочники (Справочная, Каталог), зелёные — ввод (Исходные данные > Разбивка по щитам > Однолинейка), оранжевые — результаты, серые — служебные. «В Акад» и «Диапазоны» — для старого способа (Data Link в AutoCAD): НЕ удалять, НЕ скрывать и НЕ переименовывать. Скрыт только лист «Справочная_потребители» (правая кнопка по ярлыку → Показать). | E6: 1.04.2а Демо | F6: Исправлены некоторые ошибки в расчетах
B7: 6 | C7: На листе "Кабельный журнал" есть сводная таблица кабелей | E7: 1.04.2б Демо | F7: Добавлен лист токов КЗ для тестирования, добавлена справочная с Iп (не внедрен в расчеты)
B8: 7 | C8: На листе "Кабельный журнал" есть сводная таблица артикулов прокладки | E8: 1.04.2в Демо | F8: Исправлены некоторые ошибки в диапазонах
B9: 8 | C9: Номинал автомата нужен для расчета сечения кабеля, для других целей не используется | E9: 1.05 Демо | F9: Добавлен расчет пусковых токов, добавлен авто Cos(фи) (Нагрузка_щитов) Добавлен расчет КРМ + рекомндация по установке КРМ (Нагрузка_щитов)
B10: 9 | C10: Все ячейки, кроме нужных - заблокированы | E10: v3.5 (схема) | F10: Лист «Однолинейка» + программа AutoCAD SX_Schema (SXDRAW/SXUPDATE). Каталог оборудования с выпадающими списками, светофор (AE), защита паролем sx, лист «Бирки», подсчёт и артикулы в «Спецификации».
B11: 10 | C11: Если какая-то ячейка выделилась красным - значит есть нарушение (ГОСТа, расчета или иное), меняй значения во вводимых данных. Выделенная ячейка как-то связана с ошибкой | E11: v3.6 (схема) | F11: В «Спецификации» автоматы, аппараты, модули и клеммы 3L считаются по однолинейке (по артикулу), остальное вручную. Каталог показывает «в проекте, шт.». ТКЗ больше не пересчитывается при каждой правке. Коды → УГО перенесены в «Справочную» AU:AX. Служебные столбцы однолинейки свёрнуты.
B12: 11 | C12: ОДНОЛИНЕЙКА: вводить только в белые столбцы D, E, F, I–L, N, P, Y. Остальное считается само (лист защищён, пароль sx). | E12: v3.7 (схема) | F12: Спецификация собирается сама из «Каталога» (без пустых строк, по разделам). Понятный «Справочник_схемы». УГО по-русски + свои блоки. Клеммы 3L на линию по коду (шторы SH = 2). Старая ручная спецификация — скрытый лист «Спецификация_до_v3.7».
B13: 12 | C13: Столбец AE «Статус»: красный — ошибка (дубль клеммы, нет фазы, автомат/канал), жёлтый — проверить (нет мощности, 5 жил на 1 фазе, розетка без 30 мА, потери > 4%). | E13: v3.8 (схема) | F13: Лист «Справочник_схемы» убран: настройки, итоги и свободные каналы — «Справочная» BE:BN; сводка ошибок — «Однолинейка» AE1. Спецификация: «Спецификация» — ваша (значения, правьте как хотите), «Спецификация_авто» — черновик (формулы). Листы по цветам: синий — справочники, зелёный — ввод, оранжевый — результаты, серый — служебные (часть скрыта).
B14: 13 | C14: Канал (N): пусто — следующий по порядку, № — вручную, «=» — параллельно предыдущей, «+» — новый канал, «р» — резерв, «б»/«к» — без канала модуля.
B15: 14 | C15: СПЕЦИФИКАЦИЯ: «Спецификация_авто» считается сама (Каталог: N — по однолинейке, O — вручную/запас). Когда схема готова — выделить «Спецификация_авто» B4:J160 → Копировать → «Спецификация» B4 → Вставить → Значения. Дальше «Спецификацию» правьте как обычно.
B16: 15 | C16: AutoCAD: APPLOAD → SX_Schema.lsp. SXDRAW — построить (окно), SXUPDATE — перестроить без окна, SXCLEAR — удалить схему.
B17: 16 | C17: Новый код потребителя: строка в «Справочной» (P…Y) + в той же строке УГО (список), 30 мА, мин. автомат, клемм 3L на линию (AU:AY). Настройки однолинейки (мест на лист, мин. автомат перед БП) — «Справочная» BF4:BF5.
B18: 17 | C18: Свой значок УГО: «Справочная» BA:BB — название + имя блока из 02_Однолинейка.dwg. Лист «В Акад» — старый способ (Data Link), оставлен для коллег.

Sheet Справочная
L2: Заполнить!!! | AJ2: ПТО | AQ2: Способ управления | AU2: УГО на однолинейке (по коду) | BA2: ЗНАЧКИ УГО ДЛЯ ОДНОЛИНЕЙКИ | BE2: НАСТРОЙКИ ОДНОЛИНЕЙКИ И СВОДКА (перенесено с листа «Справочник_схемы»)
B3: Сечение | C3: Индуктивное, Ом/км | D3: Активное, Ом/км | F3: Ток | G3: Автомат | I3: Ток | J3: Кабель | L3: Обознач | M3: Кабель | N3: Сечение (1-да; 2 -нет) | P3: Обознач | Q3: Потребитель | R3: Опуск | S3: 1 - этаж/2 - шлейф | T3: Пусковой ток 1 - нет/2 - двигатель/3-свет | U3: Марка кабеля | V3: Кол-во жил | W3: Рабочее напряжение | X3: Кол-во фаз | Y3: Сечение | AA3: Обознач | AB3: Расшифровка | AD3: Обознач | AE3: Этаж | AF3: Подъем | AG3: По другим этажам | AJ3: Кабель | AK3: Артикул | AL3: Тип кабеля | AM3: Кол-во жил | AN3: Сечение | AO3: Пол/Потолок | AQ3: Ключ в выноске | AR3: Наименование | AS3: Цвет номера группы | AU3: Код (из P) | AV3: УГО | AW3: 30 мА | AX3: Мин. автомат, А | AY3: Трёхуровн. клемм на линию | BA3: УГО (выбирается в AV) | BB3: Блок AutoCAD (из 02_Однолинейка.dwg) | BC3: Код программы (не менять) | BE3: НАСТРОЙКИ (жёлтые — можно менять) | BH3: МОДУЛИ В ПРОЕКТЕ — СВОБОДНЫЕ КАНАЛЫ
B4: 0.75 | C4: 0.13 | D4: 0.0175 | F4: 0 | G4: 6 | I4: 0 | J4: 1.5 | L4: мс | M4: ВВГнг(А)-LS | N4: 1 | P4: Ввод | Q4: Ввод питающей линии | R4: 5 | S4: 1 | T4: 1 | AA4: тпв | AB4: Труба жесткая ПВХ | AD4: 0 | AE4: Цокольный этаж | AJ4: =AL4&" ("&AM4&"х"&AN4&") "&AO4 | AK4: МСК001 | AL4: ВВГнг(А)-LS | AM4: 2 | AN4: 1.5 | AO4: 1 | AQ4: Relay | AR4: Реле | AU4: =IF(P4="","",P4) | BA4: Розетка | BB4: Розетка1 | BC4: SOCKET | BE4: Мест (столбцов схемы) на лист A3 | BF4: 17 | BH4: Щит | BI4: Модуль | BJ4: Модель | BK4: Каналов | BL4: Занято (посл. №) | BM4: Резерв «р» | BN4: Свободно
B5: 1 | C5: 0.11 | D5: 0.0175 | F5: 5.4 | G5: 10 | I5: 19 | J5: 2.5 | L5: мфр | M5: ВВГнг(А)-FRLS | N5: 1 | P5: На ИБП | Q5: Питание на ИБП | R5: 5 | S5: 1 | T5: 1 | AA5: тпн | AB5: Труба жесткая ПНД | AD5: 1 | AJ5: =AL5&" ("&AM5&"х"&AN5&") "&AO5 | AK5: МСК002 | AL5: ВВГнг(А)-LS | AM5: 2 | AN5: 1.5 | AO5: 2 | AQ5: DALI | AR5: DALI | AU5: =IF(P5="","",P5) | BA5: Светильник | BB5: $RECOVER_230831092053-0 | BC5: LAMP | BE5: Мин. автомат перед БП / трансформатором, А | BF5: 10 | BH5: =IFERROR(INDEX(Однолинейка!$A$1:$A$1000,(MATCH(1,Однолинейка!$BS$1:$BS$1000,0))),"") | BI5: =IFERROR(INDEX(Однолинейка!$AW$1:$AW$1000,(MATCH(1,Однолинейка!$BS$1:$BS$1000,0))),"") | BJ5: =IF(BI5="","",INDEX(Однолинейка!$AI$1:$AI$1000,(MATCH(1,Однолинейка!$BS$1:$BS$1000,0)))) | BK5: =IF(BI5="","",IFERROR(VLOOKUP(BJ5,Модули_спр,3,FALSE),"")) | BL5: =IF(BI5="","",_xlfn.MAXIFS(Однолинейка!$O$3:$O$1000,Однолинейка!$AH$3:$AH$1000,BI5,Однолинейка!$A$3:$A$1000,BH5)) | BM5: =IF(BI5="","",COUNTIFS(Однолинейка!$AH$3:$AH$1000,BI5,Однолинейка!$A$3:$A$1000,BH5,Однолинейка!$N$3:$N$1000,"р")) | BN5: =IF(OR(BI5="",BK5=""),"",BK5-BL5)
B6: 1.5 | C6: 0.11 | D6: 0.0175 | F6: 9 | G6: 16 | I6: 25 | J6: 4 | L6: ютп | M6: FTP-Cat.6-4х2х0.52 | N6: 2 | P6: От ИБП | Q6: Питание от ИБП | R6: 5 | S6: 1 | T6: 1 | AA6: гпв | AB6: Труба гофрированная ПВХ | AD6: 2 | AJ6: =AL6&" ("&AM6&"х"&AN6&") "&AO6 | AK6: МСК003 | AL6: ВВГнг(А)-LS | AM6: 2 | AN6: 2.5 | AO6: 1 | AQ6: кнопк | AR6: С кнопки | AU6: =IF(P6="","",P6) | BA6: Сервопривод | BB6: Сервопривод-1 | BC6: SERVO | BH6: =IFERROR(INDEX(Однолинейка!$A$1:$A$1000,(MATCH(2,Однолинейка!$BS$1:$BS$1000,0))),"") | BI6: =IFERROR(INDEX(Однолинейка!$AW$1:$AW$1000,(MATCH(2,Однолинейка!$BS$1:$BS$1000,0))),"") | BJ6: =IF(BI6="","",INDEX(Однолинейка!$AI$1:$AI$1000,(MATCH(2,Однолинейка!$BS$1:$BS$1000,0)))) | BK6: =IF(BI6="","",IFERROR(VLOOKUP(BJ6,Модули_спр,3,FALSE),"")) | BL6: =IF(BI6="","",_xlfn.MAXIFS(Однолинейка!$O$3:$O$1000,Однолинейка!$AH$3:$AH$1000,BI6,Однолинейка!$A$3:$A$1000,BH6)) | BM6: =IF(BI6="","",COUNTIFS(Однолинейка!$AH$3:$AH$1000,BI6,Однолинейка!$A$3:$A$1000,BH6,Однолинейка!$N$3:$N$1000,"р")) | BN6: =IF(OR(BI6="",BK6=""),"",BK6-BL6)
B7: 2.5 | C7: 0.1 | D7: 0.0175 | F7: 14.4 | G7: 20 | I7: 33 | J7: 6 | L7: ре | M7: ПуГВ | N7: 1 | P7: R | Q7: Розеточная группа | R7: 2 | S7: 1 | T7: 1 | U7: мс | V7: 3 | W7: 230 | X7: 1 | Y7: 2.5 | AA7: гпн | AB7: Труба гофрированная ПНД | AD7: 3 | AE7: Третий этаж | AJ7: =AL7&" ("&AM7&"х"&AN7&") "&AO7 | AK7: МСК004 | AL7: ВВГнг(А)-LS | AM7: 2 | AN7: 2.5 | AO7: 2 | AQ7: Ключ из AQ ищется в AY. Цвет AS — образец для номера в D. | AU7: =IF(P7="","",P7) | AV7: Розетка | AW7: да | AX7: 16 | BA7: Клапан | BB7: EK.1 | BC7: VALVE | BE7: ИТОГИ ПО ОДНОЛИНЕЙКЕ | BH7: =IFERROR(INDEX(Однолинейка!$A$1:$A$1000,(MATCH(3,Однолинейка!$BS$1:$BS$1000,0))),"") | BI7: =IFERROR(INDEX(Однолинейка!$AW$1:$AW$1000,(MATCH(3,Однолинейка!$BS$1:$BS$1000,0))),"") | BJ7: =IF(BI7="","",INDEX(Однолинейка!$AI$1:$AI$1000,(MATCH(3,Однолинейка!$BS$1:$BS$1000,0)))) | BK7: =IF(BI7="","",IFERROR(VLOOKUP(BJ7,Модули_спр,3,FALSE),"")) | BL7: =IF(BI7="","",_xlfn.MAXIFS(Однолинейка!$O$3:$O$1000,Однолинейка!$AH$3:$AH$1000,BI7,Однолинейка!$A$3:$A$1000,BH7)) | BM7: =IF(BI7="","",COUNTIFS(Однолинейка!$AH$3:$AH$1000,BI7,Однолинейка!$A$3:$A$1000,BH7,Однолинейка!$N$3:$N$1000,"р")) | BN7: =IF(OR(BI7="",BK7=""),"",BK7-BL7)
B8: 4 | C8: 0.095 | D8: 0.0175 | F8: 18 | G8: 25 | I8: 42 | J8: 10 | L8: мб | M8: ВБШвнг(А)-LS | N8: 1 | P8: L | Q8: Группа освещения | R8: 1 | S8: 1 | T8: 1 | U8: мс | V8: 3 | W8: 230 | X8: 1 | Y8: 1.5 | AJ8: =AL8&" ("&AM8&"х"&AN8&") "&AO8 | AK8: МСК005 | AL8: ВВГнг(А)-LS | AM8: 3 | AN8: 1.5 | AO8: 1 | AU8: =IF(P8="","",P8) | AV8: Светильник | AW8: нет | AX8: 10 | BA8: Привод (двигатель) | BB8: Привод | BC8: MOTOR | BE8: Автоматов всего | BF8: =COUNTIF(Однолинейка!$E$3:$E$1000,"?*") | BH8: =IFERROR(INDEX(Однолинейка!$A$1:$A$1000,(MATCH(4,Однолинейка!$BS$1:$BS$1000,0))),"") | BI8: =IFERROR(INDEX(Однолинейка!$AW$1:$AW$1000,(MATCH(4,Однолинейка!$BS$1:$BS$1000,0))),"") | BJ8: =IF(BI8="","",INDEX(Однолинейка!$AI$1:$AI$1000,(MATCH(4,Однолинейка!$BS$1:$BS$1000,0)))) | BK8: =IF(BI8="","",IFERROR(VLOOKUP(BJ8,Модули_спр,3,FALSE),"")) | BL8: =IF(BI8="","",_xlfn.MAXIFS(Однолинейка!$O$3:$O$1000,Однолинейка!$AH$3:$AH$1000,BI8,Однолинейка!$A$3:$A$1000,BH8)) | BM8: =IF(BI8="","",COUNTIFS(Однолинейка!$AH$3:$AH$1000,BI8,Однолинейка!$A$3:$A$1000,BH8,Однолинейка!$N$3:$N$1000,"р")) | BN8: =IF(OR(BI8="",BK8=""),"",BK8-BL8)
B9: 6 | C9: 0.09 | D9: 0.0175 | F9: 22.5 | G9: 32 | I9: 58 | J9: 16 | L9: кмс | M9: КГВВнг(А)-LS | N9: 1 | P9: LED | Q9: Светодиодное освещение | R9: 1 | S9: 1 | T9: 1 | AJ9: =AL9&" ("&AM9&"х"&AN9&") "&AO9 | AK9: МСК006 | AL9: ВВГнг(А)-LS | AM9: 3 | AN9: 1.5 | AO9: 2 | AU9: =IF(P9="","",P9) | AV9: Светильник | AW9: нет | AX9: 10 | BA9: Нагреватель | BB9: (условный значок программы) | BC9: HEAT | BE9: из них с 30 мА (QFD) | BF9: =COUNTIF(Однолинейка!$AJ$3:$AJ$1000,"QFD*") | BH9: =IFERROR(INDEX(Однолинейка!$A$1:$A$1000,(MATCH(5,Однолинейка!$BS$1:$BS$1000,0))),"") | BI9: =IFERROR(INDEX(Однолинейка!$AW$1:$AW$1000,(MATCH(5,Однолинейка!$BS$1:$BS$1000,0))),"") | BJ9: =IF(BI9="","",INDEX(Однолинейка!$AI$1:$AI$1000,(MATCH(5,Однолинейка!$BS$1:$BS$1000,0)))) | BK9: =IF(BI9="","",IFERROR(VLOOKUP(BJ9,Модули_спр,3,FALSE),"")) | BL9: =IF(BI9="","",_xlfn.MAXIFS(Однолинейка!$O$3:$O$1000,Однолинейка!$AH$3:$AH$1000,BI9,Однолинейка!$A$3:$A$1000,BH9)) | BM9: =IF(BI9="","",COUNTIFS(Однолинейка!$AH$3:$AH$1000,BI9,Однолинейка!$A$3:$A$1000,BH9,Однолинейка!$N$3:$N$1000,"р")) | BN9: =IF(OR(BI9="",BK9=""),"",BK9-BL9)
B10: 10 | C10: 0.073 | D10: 0.0175 | F10: 28.8 | G10: 40 | I10: 78 | J10: 25 | L10: кмб | M10: КВБбШвнг(А)-LS 14x2.5 | N10: 2 | P10: R.ШТК | Q10: Шкаф слаботочных систем | R10: 2 | S10: 1 | T10: 1 | AJ10: =AL10&" ("&AM10&"х"&AN10&") "&AO10 | AK10: МСК007 | AL10: ВВГнг(А)-LS | AM10: 3 | AN10: 2.5 | AO10: 1 | AU10: =IF(P10="","",P10) | AV10: Розетка | AW10: нет | AX10: 16 | BA10: Прочее (прямоуг. с подписью) | BB10: (условный значок программы) | BC10: BOX | BE10: Клемм XT (номеров) | BF10: =COUNTIF(Однолинейка!$AY$3:$AY$1000,1) | BH10: =IFERROR(INDEX(Однолинейка!$A$1:$A$1000,(MATCH(6,Однолинейка!$BS$1:$BS$1000,0))),"") | BI10: =IFERROR(INDEX(Однолинейка!$AW$1:$AW$1000,(MATCH(6,Однолинейка!$BS$1:$BS$1000,0))),"") | BJ10: =IF(BI10="","",INDEX(Однолинейка!$AI$1:$AI$1000,(MATCH(6,Однолинейка!$BS$1:$BS$1000,0)))) | BK10: =IF(BI10="","",IFERROR(VLOOKUP(BJ10,Модули_спр,3,FALSE),"")) | BL10: =IF(BI10="","",_xlfn.MAXIFS(Однолинейка!$O$3:$O$1000,Однолинейка!$AH$3:$AH$1000,BI10,Однолинейка!$A$3:$A$1000,BH10)) | BM10: =IF(BI10="","",COUNTIFS(Однолинейка!$AH$3:$AH$1000,BI10,Однолинейка!$A$3:$A$1000,BH10,Однолинейка!$N$3:$N$1000,"р")) | BN10: =IF(OR(BI10="",BK10=""),"",BK10-BL10)
B11: 16 | C11: 0.0675 | D11: 0.0175 | F11: 36 | G11: 50 | I11: 104 | J11: 35 | L11: мфр | M11: ППГнг(А)-FRHF | N11: 1 | P11: R.ЩОПС | Q11: Щит охранно-пожарной сигнализации | R11: 2 | S11: 1 | T11: 1 | AJ11: =AL11&" ("&AM11&"х"&AN11&") "&AO11 | AK11: МСК008 | AL11: ВВГнг(А)-LS | AM11: 3 | AN11: 2.5 | AO11: 2 | AU11: =IF(P11="","",P11) | AV11: Розетка | AW11: нет | AX11: 16 | BE11: трёхуровневых блоков | BF11: =SUM(Однолинейка!$BW$3:$BW$1000) | BH11: =IFERROR(INDEX(Однолинейка!$A$1:$A$1000,(MATCH(7,Однолинейка!$BS$1:$BS$1000,0))),"") | BI11: =IFERROR(INDEX(Однолинейка!$AW$1:$AW$1000,(MATCH(7,Однолинейка!$BS$1:$BS$1000,0))),"") | BJ11: =IF(BI11="","",INDEX(Однолинейка!$AI$1:$AI$1000,(MATCH(7,Однолинейка!$BS$1:$BS$1000,0)))) | BK11: =IF(BI11="","",IFERROR(VLOOKUP(BJ11,Модули_спр,3,FALSE),"")) | BL11: =IF(BI11="","",_xlfn.MAXIFS(Однолинейка!$O$3:$O$1000,Однолинейка!$AH$3:$AH$1000,BI11,Однолинейка!$A$3:$A$1000,BH11)) | BM11: =IF(BI11="","",COUNTIFS(Однолинейка!$AH$3:$AH$1000,BI11,Однолинейка!$A$3:$A$1000,BH11,Однолинейка!$N$3:$N$1000,"р")) | BN11: =IF(OR(BI11="",BK11=""),"",BK11-BL11)
B12: 25 | C12: 0.0662 | D12: 0.0175 | F12: 45 | G12: 63 | I12: 127 | J12: 50 | L12: мшф | M12: ППГнг(А)-HF | N12: 1 | P12: АСУ | Q12: Питание системы автоматизации | R12: 1 | S12: 1 | T12: 1 | AJ12: =AL12&" ("&AM12&"х"&AN12&") "&AO12 | AK12: МСК009 | AL12: ВВГнг(А)-LS | AM12: 3 | AN12: 4 | AO12: 1 | AU12: =IF(P12="","",P12) | AV12: Прочее (прямоуг. с подписью) | AW12: нет | BE12: доп. проходных | BF12: =SUM(Однолинейка!$BX$3:$BX$1000) | BH12: =IFERROR(INDEX(Однолинейка!$A$1:$A$1000,(MATCH(8,Однолинейка!$BS$1:$BS$1000,0))),"") | BI12: =IFERROR(INDEX(Однолинейка!$AW$1:$AW$1000,(MATCH(8,Однолинейка!$BS$1:$BS$1000,0))),"") | BJ12: =IF(BI12="","",INDEX(Однолинейка!$AI$1:$AI$1000,(MATCH(8,Однолинейка!$BS$1:$BS$1000,0)))) | BK12: =IF(BI12="","",IFERROR(VLOOKUP(BJ12,Модули_спр,3,FALSE),"")) | BL12: =IF(BI12="","",_xlfn.MAXIFS(Однолинейка!$O$3:$O$1000,Однолинейка!$AH$3:$AH$1000,BI12,Однолинейка!$A$3:$A$1000,BH12)) | BM12: =IF(BI12="","",COUNTIFS(Однолинейка!$AH$3:$AH$1000,BI12,Однолинейка!$A$3:$A$1000,BH12,Однолинейка!$N$3:$N$1000,"р")) | BN12: =IF(OR(BI12="",BK12=""),"",BK12-BL12)
B13: 35 | C13: 0.0637 | D13: 0.0175 | F13: 56.7 | G13: Не исп | I13: 155 | J13: 70 | L13: кн | M13: J-Y(St)Y 2х2х0.8 | N13: 2 | P13: PS-KNX | Q13: Блок питания шины KNX | R13: 1 | S13: 1 | T13: 1 | AJ13: =AL13&" ("&AM13&"х"&AN13&") "&AO13 | AK13: МСК010 | AL13: ВВГнг(А)-LS | AM13: 3 | AN13: 4 | AO13: 2 | AU13: =IF(P13="","",P13) | BE13: Модулей всего | BF13: =COUNTIF(Однолинейка!$AW$3:$AW$1000,"?*") | BH13: =IFERROR(INDEX(Однолинейка!$A$1:$A$1000,(MATCH(9,Однолинейка!$BS$1:$BS$1000,0))),"") | BI13: =IFERROR(INDEX(Однолинейка!$AW$1:$AW$1000,(MATCH(9,Однолинейка!$BS$1:$BS$1000,0))),"") | BJ13: =IF(BI13="","",INDEX(Однолинейка!$AI$1:$AI$1000,(MATCH(9,Однолинейка!$BS$1:$BS$1000,0)))) | BK13: =IF(BI13="","",IFERROR(VLOOKUP(BJ13,Модули_спр,3,FALSE),"")) | BL13: =IF(BI13="","",_xlfn.MAXIFS(Однолинейка!$O$3:$O$1000,Однолинейка!$AH$3:$AH$1000,BI13,Однолинейка!$A$3:$A$1000,BH13)) | BM13: =IF(BI13="","",COUNTIFS(Однолинейка!$AH$3:$AH$1000,BI13,Однолинейка!$A$3:$A$1000,BH13,Однолинейка!$N$3:$N$1000,"р")) | BN13: =IF(OR(BI13="",BK13=""),"",BK13-BL13)
B14: 50 | C14: 0.0625 | D14: 0.0175 | I14: 196 | J14: 95 | L14: кф | M14: КИПЭВ 2х2х0.6 | N14: 2 | P14: В | Q14: Вытяжной вентилятор | R14: 1 | S14: 1 | T14: 1 | AJ14: =AL14&" ("&AM14&"х"&AN14&") "&AO14 | AK14: МСК011 | AL14: ВВГнг(А)-LS | AM14: 3 | AN14: 6 | AO14: 1 | AU14: =IF(P14="","",P14) | AV14: Привод (двигатель) | AW14: нет | BE14: Строк с ошибками (красные в AE) | BF14: =COUNTIF(Однолинейка!$BU$3:$BU$1000,2) | BH14: =IFERROR(INDEX(Однолинейка!$A$1:$A$1000,(MATCH(10,Однолинейка!$BS$1:$BS$1000,0))),"") | BI14: =IFERROR(INDEX(Однолинейка!$AW$1:$AW$1000,(MATCH(10,Однолинейка!$BS$1:$BS$1000,0))),"") | BJ14: =IF(BI14="","",INDEX(Однолинейка!$AI$1:$AI$1000,(MATCH(10,Однолинейка!$BS$1:$BS$1000,0)))) | BK14: =IF(BI14="","",IFERROR(VLOOKUP(BJ14,Модули_спр,3,FALSE),"")) | BL14: =IF(BI14="","",_xlfn.MAXIFS(Однолинейка!$O$3:$O$1000,Однолинейка!$AH$3:$AH$1000,BI14,Однолинейка!$A$3:$A$1000,BH14)) | BM14: =IF(BI14="","",COUNTIFS(Однолинейка!$AH$3:$AH$1000,BI14,Однолинейка!$A$3:$A$1000,BH14,Однолинейка!$N$3:$N$1000,"р")) | BN14: =IF(OR(BI14="",BK14=""),"",BK14-BL14)
B15: 70 | C15: 0.0612 | D15: 0.0175 | I15: 242 | J15: 120 | L15: кс | M15: КСПВГ 4х0.35 | N15: 2 | P15: ТП | Q15: Теплый пол | R15: 2 | S15: 1 | T15: 1 | AJ15: =AL15&" ("&AM15&"х"&AN15&") "&AO15 | AK15: МСК012 | AL15: ВВГнг(А)-LS | AM15: 3 | AN15: 6 | AO15: 2 | AU15: =IF(P15="","",P15) | AV15: Нагреватель | AW15: да | BE15: Строк с предупреждениями (жёлтые в AE) | BF15: =COUNTIF(Однолинейка!$BU$3:$BU$1000,1) | BH15: =IFERROR(INDEX(Однолинейка!$A$1:$A$1000,(MATCH(11,Однолинейка!$BS$1:$BS$1000,0))),"") | BI15: =IFERROR(INDEX(Однолинейка!$AW$1:$AW$1000,(MATCH(11,Однолинейка!$BS$1:$BS$1000,0))),"") | BJ15: =IF(BI15="","",INDEX(Однолинейка!$AI$1:$AI$1000,(MATCH(11,Однолинейка!$BS$1:$BS$1000,0)))) | BK15: =IF(BI15="","",IFERROR(VLOOKUP(BJ15,Модули_спр,3,FALSE),"")) | BL15: =IF(BI15="","",_xlfn.MAXIFS(Однолинейка!$O$3:$O$1000,Однолинейка!$AH$3:$AH$1000,BI15,Однолинейка!$A$3:$A$1000,BH15)) | BM15: =IF(BI15="","",COUNTIFS(Однолинейка!$AH$3:$AH$1000,BI15,Однолинейка!$A$3:$A$1000,BH15,Однолинейка!$N$3:$N$1000,"р")) | BN15: =IF(OR(BI15="",BK15=""),"",BK15-BL15)
B16: 95 | C16: 0.0602 | D16: 0.0175 | I16: 280 | J16: 150 | L16: кмс1 | M16: КГВВнг(А)-LS (5х1) | P16: ЭK | Q16: Шаровый электрокран | R16: 1 | S16: 1 | T16: 1 | AJ16: =AL16&" ("&AM16&"х"&AN16&") "&AO16 | AK16: МСК013 | AL16: ВВГнг(А)-LS | AM16: 5 | AN16: 1.5 | AO16: 1 | AU16: =IF(P16="","",P16) | AV16: Клапан | AW16: нет | BH16: =IFERROR(INDEX(Однолинейка!$A$1:$A$1000,(MATCH(12,Однолинейка!$BS$1:$BS$1000,0))),"") | BI16: =IFERROR(INDEX(Однолинейка!$AW$1:$AW$1000,(MATCH(12,Однолинейка!$BS$1:$BS$1000,0))),"") | BJ16: =IF(BI16="","",INDEX(Однолинейка!$AI$1:$AI$1000,(MATCH(12,Однолинейка!$BS$1:$BS$1000,0)))) | BK16: =IF(BI16="","",IFERROR(VLOOKUP(BJ16,Модули_спр,3,FALSE),"")) | BL16: =IF(BI16="","",_xlfn.MAXIFS(Однолинейка!$O$3:$O$1000,Однолинейка!$AH$3:$AH$1000,BI16,Однолинейка!$A$3:$A$1000,BH16)) | BM16: =IF(BI16="","",COUNTIFS(Однолинейка!$AH$3:$AH$1000,BI16,Однолинейка!$A$3:$A$1000,BH16,Однолинейка!$N$3:$N$1000,"р")) | BN16: =IF(OR(BI16="",BK16=""),"",BK16-BL16)
B17: 150 | C17: 0.0596 | D17: 0.0175 | I17: 321 | J17: 185 | P17: TE-O | Q17: Управление сервоприводом отопления | R17: 1 | S17: 1 | T17: 1 | AJ17: =AL17&" ("&AM17&"х"&AN17&") "&AO17 | AK17: МСК014 | AL17: ВВГнг(А)-LS | AM17: 5 | AN17: 1.5 | AO17: 2 | AU17: =IF(P17="","",P17) | BH17: =IFERROR(INDEX(Однолинейка!$A$1:$A$1000,(MATCH(13,Однолинейка!$BS$1:$BS$1000,0))),"") | BI17: =IFERROR(INDEX(Однолинейка!$AW$1:$AW$1000,(MATCH(13,Однолинейка!$BS$1:$BS$1000,0))),"") | BJ17: =IF(BI17="","",INDEX(Однолинейка!$AI$1:$AI$1000,(MATCH(13,Однолинейка!$BS$1:$BS$1000,0)))) | BK17: =IF(BI17="","",IFERROR(VLOOKUP(BJ17,Модули_спр,3,FALSE),"")) | BL17: =IF(BI17="","",_xlfn.MAXIFS(Однолинейка!$O$3:$O$1000,Однолинейка!$AH$3:$AH$1000,BI17,Однолинейка!$A$3:$A$1000,BH17)) | BM17: =IF(BI17="","",COUNTIFS(Однолинейка!$AH$3:$AH$1000,BI17,Однолинейка!$A$3:$A$1000,BH17,Однолинейка!$N$3:$N$1000,"р")) | BN17: =IF(OR(BI17="",BK17=""),"",BK17-BL17)
B18: 185 | C18: 0.0596 | D18: 0.0175 | I18: 369 | J18: 240 | P18: SH | Q18: Моторзированная нагрузка | R18: 1 | S18: 1 | T18: 1 | AJ18: =AL18&" ("&AM18&"х"&AN18&") "&AO18 | AK18: МСК015 | AL18: ВВГнг(А)-LS | AM18: 5 | AN18: 2.5 | AO18: 1 | AU18: =IF(P18="","",P18) | AV18: Привод (двигатель) | AW18: нет | AY18: 2 | BE18: КАК ПОДБИРАЕТСЯ АВТОМАТ («авто») | BH18: =IFERROR(INDEX(Однолинейка!$A$1:$A$1000,(MATCH(14,Однолинейка!$BS$1:$BS$1000,0))),"") | BI18: =IFERROR(INDEX(Однолинейка!$AW$1:$AW$1000,(MATCH(14,Однолинейка!$BS$1:$BS$1000,0))),"") | BJ18: =IF(BI18="","",INDEX(Однолинейка!$AI$1:$AI$1000,(MATCH(14,Однолинейка!$BS$1:$BS$1000,0)))) | BK18: =IF(BI18="","",IFERROR(VLOOKUP(BJ18,Модули_спр,3,FALSE),"")) | BL18: =IF(BI18="","",_xlfn.MAXIFS(Однолинейка!$O$3:$O$1000,Однолинейка!$AH$3:$AH$1000,BI18,Однолинейка!$A$3:$A$1000,BH18)) | BM18: =IF(BI18="","",COUNTIFS(Однолинейка!$AH$3:$AH$1000,BI18,Однолинейка!$A$3:$A$1000,BH18,Однолинейка!$N$3:$N$1000,"р")) | BN18: =IF(OR(BI18="",BK18=""),"",BK18-BL18)
B19: 240 | C19: 0.0587 | D19: 0.0175 | I19: 438 | J19: Не исп | P19: DALI | Q19: Контролер DALI | R19: 1 | S19: 2 | T19: 1 | AJ19: =AL19&" ("&AM19&"х"&AN19&") "&AO19 | AK19: МСК016 | AL19: ВВГнг(А)-LS | AM19: 5 | AN19: 2.5 | AO19: 2 | AU19: =IF(P19="","",P19) | AV19: Светильник | AW19: нет | AX19: 10 | BE19: 1. Ток группы = сумма токов линий группы (линия в нескольких строках считается один раз). | BH19: =IFERROR(INDEX(Однолинейка!$A$1:$A$1000,(MATCH(15,Однолинейка!$BS$1:$BS$1000,0))),"") | BI19: =IFERROR(INDEX(Однолинейка!$AW$1:$AW$1000,(MATCH(15,Однолинейка!$BS$1:$BS$1000,0))),"") | BJ19: =IF(BI19="","",INDEX(Однолинейка!$AI$1:$AI$1000,(MATCH(15,Однолинейка!$BS$1:$BS$1000,0)))) | BK19: =IF(BI19="","",IFERROR(VLOOKUP(BJ19,Модули_спр,3,FALSE),"")) | BL19: =IF(BI19="","",_xlfn.MAXIFS(Однолинейка!$O$3:$O$1000,Однолинейка!$AH$3:$AH$1000,BI19,Однолинейка!$A$3:$A$1000,BH19)) | BM19: =IF(BI19="","",COUNTIFS(Однолинейка!$AH$3:$AH$1000,BI19,Однолинейка!$A$3:$A$1000,BH19,Однолинейка!$N$3:$N$1000,"р")) | BN19: =IF(OR(BI19="",BK19=""),"",BK19-BL19)
P20: LED | Q20: Группа светодиодного освещения | R20: 1 | S20: 1 | T20: 3 | AJ20: =AL20&" ("&AM20&"х"&AN20&") "&AO20 | AK20: МСК017 | AL20: ВВГнг(А)-LS | AM20: 5 | AN20: 4 | AO20: 1 | AU20: =IF(P20="","",P20) | AV20: Светильник | AW20: нет | AX20: 10 | BE20: 2. Номинал по току — по таблице «Автомат_номиналы» (эта страница, F:G). | BH20: =IFERROR(INDEX(Однолинейка!$A$1:$A$1000,(MATCH(16,Однолинейка!$BS$1:$BS$1000,0))),"") | BI20: =IFERROR(INDEX(Однолинейка!$AW$1:$AW$1000,(MATCH(16,Однолинейка!$BS$1:$BS$1000,0))),"") | BJ20: =IF(BI20="","",INDEX(Однолинейка!$AI$1:$AI$1000,(MATCH(16,Однолинейка!$BS$1:$BS$1000,0)))) | BK20: =IF(BI20="","",IFERROR(VLOOKUP(BJ20,Модули_спр,3,FALSE),"")) | BL20: =IF(BI20="","",_xlfn.MAXIFS(Однолинейка!$O$3:$O$1000,Однолинейка!$AH$3:$AH$1000,BI20,Однолинейка!$A$3:$A$1000,BH20)) | BM20: =IF(BI20="","",COUNTIFS(Однолинейка!$AH$3:$AH$1000,BI20,Однолинейка!$A$3:$A$1000,BH20,Однолинейка!$N$3:$N$1000,"р")) | BN20: =IF(OR(BI20="",BK20=""),"",BK20-BL20)
P21: АПС | Q21: Реле АПС | R21: 1 | S21: 1 | T21: 1 | AJ21: =AL21&" ("&AM21&"х"&AN21&") "&AO21 | AK21: МСК018 | AL21: ВВГнг(А)-LS | AM21: 5 | AN21: 4 | AO21: 2 | AU21: =IF(P21="","",P21) | BE21: 3. Итог = наибольший из: по току, «Мин. автомат» по коду (AX: розетки 16 А, свет 10 А) и ручного автомата из «Исходных данных». | BH21: =IFERROR(INDEX(Однолинейка!$A$1:$A$1000,(MATCH(17,Однолинейка!$BS$1:$BS$1000,0))),"") | BI21: =IFERROR(INDEX(Однолинейка!$AW$1:$AW$1000,(MATCH(17,Однолинейка!$BS$1:$BS$1000,0))),"") | BJ21: =IF(BI21="","",INDEX(Однолинейка!$AI$1:$AI$1000,(MATCH(17,Однолинейка!$BS$1:$BS$1000,0)))) | BK21: =IF(BI21="","",IFERROR(VLOOKUP(BJ21,Модули_спр,3,FALSE),"")) | BL21: =IF(BI21="","",_xlfn.MAXIFS(Однолинейка!$O$3:$O$1000,Однолинейка!$AH$3:$AH$1000,BI21,Однолинейка!$A$3:$A$1000,BH21)) | BM21: =IF(BI21="","",COUNTIFS(Однолинейка!$AH$3:$AH$1000,BI21,Однолинейка!$A$3:$A$1000,BH21,Однолинейка!$N$3:$N$1000,"р")) | BN21: =IF(OR(BI21="",BK21=""),"",BK21-BL21)
P22: K | Q22: Внутренний блок кондиционера | R22: 1 | S22: 1 | T22: 1 | AJ22: =AL22&" ("&AM22&"х"&AN22&") "&AO22 | AK22: МСК019 | AL22: ВВГнг(А)-LS | AM22: 5 | AN22: 6 | AO22: 1 | AU22: =IF(P22="","",P22) | AV22: Привод (двигатель) | AW22: нет | BE22: 4. «Макс. автомат по кабелю» — по сечению (I:J). Если итог больше — «КАБЕЛЬ НЕ ЗАЩИЩЁН». | BH22: =IFERROR(INDEX(Однолинейка!$A$1:$A$1000,(MATCH(18,Однолинейка!$BS$1:$BS$1000,0))),"") | BI22: =IFERROR(INDEX(Однолинейка!$AW$1:$AW$1000,(MATCH(18,Однолинейка!$BS$1:$BS$1000,0))),"") | BJ22: =IF(BI22="","",INDEX(Однолинейка!$AI$1:$AI$1000,(MATCH(18,Однолинейка!$BS$1:$BS$1000,0)))) | BK22: =IF(BI22="","",IFERROR(VLOOKUP(BJ22,Модули_спр,3,FALSE),"")) | BL22: =IF(BI22="","",_xlfn.MAXIFS(Однолинейка!$O$3:$O$1000,Однолинейка!$AH$3:$AH$1000,BI22,Однолинейка!$A$3:$A$1000,BH22)) | BM22: =IF(BI22="","",COUNTIFS(Однолинейка!$AH$3:$AH$1000,BI22,Однолинейка!$A$3:$A$1000,BH22,Однолинейка!$N$3:$N$1000,"р")) | BN22: =IF(OR(BI22="",BK22=""),"",BK22-BL22)
P23: ПВ | Q23: Приточно-вытяжная установка | R23: 1 | S23: 1 | T23: 1 | AJ23: =AL23&" ("&AM23&"х"&AN23&") "&AO23 | AK23: МСК020 | AL23: ВВГнг(А)-LS | AM23: 5 | AN23: 6 | AO23: 2 | AU23: =IF(P23="","",P23) | BE23: 5. Если после автомата БП/трансформатор — берётся ток и мин. номинал BF5. | BH23: =IFERROR(INDEX(Однолинейка!$A$1:$A$1000,(MATCH(19,Однолинейка!$BS$1:$BS$1000,0))),"") | BI23: =IFERROR(INDEX(Однолинейка!$AW$1:$AW$1000,(MATCH(19,Однолинейка!$BS$1:$BS$1000,0))),"") | BJ23: =IF(BI23="","",INDEX(Однолинейка!$AI$1:$AI$1000,(MATCH(19,Однолинейка!$BS$1:$BS$1000,0)))) | BK23: =IF(BI23="","",IFERROR(VLOOKUP(BJ23,Модули_спр,3,FALSE),"")) | BL23: =IF(BI23="","",_xlfn.MAXIFS(Однолинейка!$O$3:$O$1000,Однолинейка!$AH$3:$AH$1000,BI23,Однолинейка!$A$3:$A$1000,BH23)) | BM23: =IF(BI23="","",COUNTIFS(Однолинейка!$AH$3:$AH$1000,BI23,Однолинейка!$A$3:$A$1000,BH23,Однолинейка!$N$3:$N$1000,"р")) | BN23: =IF(OR(BI23="",BK23=""),"",BK23-BL23)
P24: УВ | Q24: Увлажнитель | R24: 1 | S24: 1 | T24: 1 | AJ24: =AL24&" ("&AM24&"х"&AN24&") "&AO24 | AK24: МСК021 | AL24: ВВГнг(А)-LS | AM24: 5 | AN24: 10 | AO24: 1 | AU24: =IF(P24="","",P24) | AV24: Привод (двигатель) | AW24: нет | BE24: 6. Полюса: 3 фазы → 3P (4P с 30 мА), 1 фаза → 1P (2P с 30 мА). | BH24: =IFERROR(INDEX(Однолинейка!$A$1:$A$1000,(MATCH(20,Однолинейка!$BS$1:$BS$1000,0))),"") | BI24: =IFERROR(INDEX(Однолинейка!$AW$1:$AW$1000,(MATCH(20,Однолинейка!$BS$1:$BS$1000,0))),"") | BJ24: =IF(BI24="","",INDEX(Однолинейка!$AI$1:$AI$1000,(MATCH(20,Однолинейка!$BS$1:$BS$1000,0)))) | BK24: =IF(BI24="","",IFERROR(VLOOKUP(BJ24,Модули_спр,3,FALSE),"")) | BL24: =IF(BI24="","",_xlfn.MAXIFS(Однолинейка!$O$3:$O$1000,Однолинейка!$AH$3:$AH$1000,BI24,Однолинейка!$A$3:$A$1000,BH24)) | BM24: =IF(BI24="","",COUNTIFS(Однолинейка!$AH$3:$AH$1000,BI24,Однолинейка!$A$3:$A$1000,BH24,Однолинейка!$N$3:$N$1000,"р")) | BN24: =IF(OR(BI24="",BK24=""),"",BK24-BL24)
P25: ПН | Q25: Проточный водонагреватель | R25: 1 | S25: 1 | T25: 1 | AJ25: =AL25&" ("&AM25&"х"&AN25&") "&AO25 | AK25: МСК022 | AL25: ВВГнг(А)-LS | AM25: 5 | AN25: 10 | AO25: 2 | AU25: =IF(P25="","",P25) | AV25: Нагреватель | AW25: да | BE25: 7. 30 мА: столбец F «Однолинейки» или по коду (AW). | BH25: =IFERROR(INDEX(Однолинейка!$A$1:$A$1000,(MATCH(21,Однолинейка!$BS$1:$BS$1000,0))),"") | BI25: =IFERROR(INDEX(Однолинейка!$AW$1:$AW$1000,(MATCH(21,Однолинейка!$BS$1:$BS$1000,0))),"") | BJ25: =IF(BI25="","",INDEX(Однолинейка!$AI$1:$AI$1000,(MATCH(21,Однолинейка!$BS$1:$BS$1000,0)))) | BK25: =IF(BI25="","",IFERROR(VLOOKUP(BJ25,Модули_спр,3,FALSE),"")) | BL25: =IF(BI25="","",_xlfn.MAXIFS(Однолинейка!$O$3:$O$1000,Однолинейка!$AH$3:$AH$1000,BI25,Однолинейка!$A$3:$A$1000,BH25)) | BM25: =IF(BI25="","",COUNTIFS(Однолинейка!$AH$3:$AH$1000,BI25,Однолинейка!$A$3:$A$1000,BH25,Однолинейка!$N$3:$N$1000,"р")) | BN25: =IF(OR(BI25="",BK25=""),"",BK25-BL25)
P26: WD | Q26: Датчик протечки | R26: 0 | S26: 1 | T26: 1 | AJ26: =AL26&" ("&AM26&"х"&AN26&") "&AO26 | AK26: МСК023 | AL26: ВВГнг(А)-LS | AM26: 5 | AN26: 16 | AO26: 1 | AU26: =IF(P26="","",P26) | BE26: 8. Свой текст в «Автомат» (например «2P С20А 30мА») — используется как есть и проверяется. | BH26: =IFERROR(INDEX(Однолинейка!$A$1:$A$1000,(MATCH(22,Однолинейка!$BS$1:$BS$1000,0))),"") | BI26: =IFERROR(INDEX(Однолинейка!$AW$1:$AW$1000,(MATCH(22,Однолинейка!$BS$1:$BS$1000,0))),"") | BJ26: =IF(BI26="","",INDEX(Однолинейка!$AI$1:$AI$1000,(MATCH(22,Однолинейка!$BS$1:$BS$1000,0)))) | BK26: =IF(BI26="","",IFERROR(VLOOKUP(BJ26,Модули_спр,3,FALSE),"")) | BL26: =IF(BI26="","",_xlfn.MAXIFS(Однолинейка!$O$3:$O$1000,Однолинейка!$AH$3:$AH$1000,BI26,Однолинейка!$A$3:$A$1000,BH26)) | BM26: =IF(BI26="","",COUNTIFS(Однолинейка!$AH$3:$AH$1000,BI26,Однолинейка!$A$3:$A$1000,BH26,Однолинейка!$N$3:$N$1000,"р")) | BN26: =IF(OR(BI26="",BK26=""),"",BK26-BL26)
P27: VK | Q27: Выключатель нажимной | R27: 0 | S27: 1 | T27: 1 | AJ27: =AL27&" ("&AM27&"х"&AN27&") "&AO27 | AK27: МСК024 | AL27: ВВГнг(А)-LS | AM27: 5 | AN27: 16 | AO27: 2 | AU27: =IF(P27="","",P27) | BH27: =IFERROR(INDEX(Однолинейка!$A$1:$A$1000,(MATCH(23,Однолинейка!$BS$1:$BS$1000,0))),"") | BI27: =IFERROR(INDEX(Однолинейка!$AW$1:$AW$1000,(MATCH(23,Однолинейка!$BS$1:$BS$1000,0))),"") | BJ27: =IF(BI27="","",INDEX(Однолинейка!$AI$1:$AI$1000,(MATCH(23,Однолинейка!$BS$1:$BS$1000,0)))) | BK27: =IF(BI27="","",IFERROR(VLOOKUP(BJ27,Модули_спр,3,FALSE),"")) | BL27: =IF(BI27="","",_xlfn.MAXIFS(Однолинейка!$O$3:$O$1000,Однолинейка!$AH$3:$AH$1000,BI27,Однолинейка!$A$3:$A$1000,BH27)) | BM27: =IF(BI27="","",COUNTIFS(Однолинейка!$AH$3:$AH$1000,BI27,Однолинейка!$A$3:$A$1000,BH27,Однолинейка!$N$3:$N$1000,"р")) | BN27: =IF(OR(BI27="",BK27=""),"",BK27-BL27)
P28: КУП | Q28: Коробка уравнивания потенциалов | R28: 1 | S28: 1 | T28: 1 | AJ28: =AL28&" ("&AM28&"х"&AN28&") "&AO28 | AK28: МСК025 | AL28: ВВГнг(А)-LS | AM28: 5 | AN28: 25 | AO28: 1 | AU28: =IF(P28="","",P28) | BH28: =IFERROR(INDEX(Однолинейка!$A$1:$A$1000,(MATCH(24,Однолинейка!$BS$1:$BS$1000,0))),"") | BI28: =IFERROR(INDEX(Однолинейка!$AW$1:$AW$1000,(MATCH(24,Однолинейка!$BS$1:$BS$1000,0))),"") | BJ28: =IF(BI28="","",INDEX(Однолинейка!$AI$1:$AI$1000,(MATCH(24,Однолинейка!$BS$1:$BS$1000,0)))) | BK28: =IF(BI28="","",IFERROR(VLOOKUP(BJ28,Модули_спр,3,FALSE),"")) | BL28: =IF(BI28="","",_xlfn.MAXIFS(Однолинейка!$O$3:$O$1000,Однолинейка!$AH$3:$AH$1000,BI28,Однолинейка!$A$3:$A$1000,BH28)) | BM28: =IF(BI28="","",COUNTIFS(Однолинейка!$AH$3:$AH$1000,BI28,Однолинейка!$A$3:$A$1000,BH28,Однолинейка!$N$3:$N$1000,"р")) | BN28: =IF(OR(BI28="",BK28=""),"",BK28-BL28)
P29: PE | Q29: Заземляющая шина | R29: 1 | S29: 1 | T29: 1 | AJ29: =AL29&" ("&AM29&"х"&AN29&") "&AO29 | AK29: МСК026 | AL29: ВВГнг(А)-LS | AM29: 5 | AN29: 25 | AO29: 2 | AU29: =IF(P29="","",P29) | BH29: =IFERROR(INDEX(Однолинейка!$A$1:$A$1000,(MATCH(25,Однолинейка!$BS$1:$BS$1000,0))),"") | BI29: =IFERROR(INDEX(Однолинейка!$AW$1:$AW$1000,(MATCH(25,Однолинейка!$BS$1:$BS$1000,0))),"") | BJ29: =IF(BI29="","",INDEX(Однолинейка!$AI$1:$AI$1000,(MATCH(25,Однолинейка!$BS$1:$BS$1000,0)))) | BK29: =IF(BI29="","",IFERROR(VLOOKUP(BJ29,Модули_спр,3,FALSE),"")) | BL29: =IF(BI29="","",_xlfn.MAXIFS(Однолинейка!$O$3:$O$1000,Однолинейка!$AH$3:$AH$1000,BI29,Однолинейка!$A$3:$A$1000,BH29)) | BM29: =IF(BI29="","",COUNTIFS(Однолинейка!$AH$3:$AH$1000,BI29,Однолинейка!$A$3:$A$1000,BH29,Однолинейка!$N$3:$N$1000,"р")) | BN29: =IF(OR(BI29="",BK29=""),"",BK29-BL29)
P30: R.GSM | Q30: Щит усиления соловой связи | R30: 1 | S30: 1 | T30: 1 | AJ30: =AL30&" ("&AM30&"х"&AN30&") "&AO30 | AK30: МСК027 | AL30: ВВГнг(А)-LS | AM30: 5 | AN30: 35 | AO30: 1 | AU30: =IF(P30="","",P30) | AV30: Розетка | AW30: нет | AX30: 16 | BH30: =IFERROR(INDEX(Однолинейка!$A$1:$A$1000,(MATCH(26,Однолинейка!$BS$1:$BS$1000,0))),"") | BI30: =IFERROR(INDEX(Однолинейка!$AW$1:$AW$1000,(MATCH(26,Однолинейка!$BS$1:$BS$1000,0))),"") | BJ30: =IF(BI30="","",INDEX(Однолинейка!$AI$1:$AI$1000,(MATCH(26,Однолинейка!$BS$1:$BS$1000,0)))) | BK30: =IF(BI30="","",IFERROR(VLOOKUP(BJ30,Модули_спр,3,FALSE),"")) | BL30: =IF(BI30="","",_xlfn.MAXIFS(Однолинейка!$O$3:$O$1000,Однолинейка!$AH$3:$AH$1000,BI30,Однолинейка!$A$3:$A$1000,BH30)) | BM30: =IF(BI30="","",COUNTIFS(Однолинейка!$AH$3:$AH$1000,BI30,Однолинейка!$A$3:$A$1000,BH30,Однолинейка!$N$3:$N$1000,"р")) | BN30: =IF(OR(BI30="",BK30=""),"",BK30-BL30)
P31: TE-ТП | Q31: Управление сервоприводом теплого пола | R31: 1 | S31: 1 | T31: 1 | AJ31: =AL31&" ("&AM31&"х"&AN31&") "&AO31 | AK31: МСК028 | AL31: ВВГнг(А)-LS | AM31: 5 | AN31: 35 | AO31: 2 | AU31: =IF(P31="","",P31) | BH31: =IFERROR(INDEX(Однолинейка!$A$1:$A$1000,(MATCH(27,Однолинейка!$BS$1:$BS$1000,0))),"") | BI31: =IFERROR(INDEX(Однолинейка!$AW$1:$AW$1000,(MATCH(27,Однолинейка!$BS$1:$BS$1000,0))),"") | BJ31: =IF(BI31="","",INDEX(Однолинейка!$AI$1:$AI$1000,(MATCH(27,Однолинейка!$BS$1:$BS$1000,0)))) | BK31: =IF(BI31="","",IFERROR(VLOOKUP(BJ31,Модули_спр,3,FALSE),"")) | BL31: =IF(BI31="","",_xlfn.MAXIFS(Однолинейка!$O$3:$O$1000,Однолинейка!$AH$3:$AH$1000,BI31,Однолинейка!$A$3:$A$1000,BH31)) | BM31: =IF(BI31="","",COUNTIFS(Однолинейка!$AH$3:$AH$1000,BI31,Однолинейка!$A$3:$A$1000,BH31,Однолинейка!$N$3:$N$1000,"р")) | BN31: =IF(OR(BI31="",BK31=""),"",BK31-BL31)
P32: ПУ | Q32: Приточная установка | R32: 1 | S32: 1 | T32: 1 | AJ32: =AL32&" ("&AM32&"х"&AN32&") "&AO32 | AK32: МСК029 | AL32: ВВГнг(А)-LS | AM32: 5 | AN32: 50 | AO32: 1 | AU32: =IF(P32="","",P32) | AV32: Привод (двигатель) | AW32: нет | BA32: Свой значок: впишите название в BA и точное имя блока в BB (код оставьте пустым) — блок возьмётся из библиотеки DWG. | BH32: =IFERROR(INDEX(Однолинейка!$A$1:$A$1000,(MATCH(28,Однолинейка!$BS$1:$BS$1000,0))),"") | BI32: =IFERROR(INDEX(Однолинейка!$AW$1:$AW$1000,(MATCH(28,Однолинейка!$BS$1:$BS$1000,0))),"") | BJ32: =IF(BI32="","",INDEX(Однолинейка!$AI$1:$AI$1000,(MATCH(28,Однолинейка!$BS$1:$BS$1000,0)))) | BK32: =IF(BI32="","",IFERROR(VLOOKUP(BJ32,Модули_спр,3,FALSE),"")) | BL32: =IF(BI32="","",_xlfn.MAXIFS(Однолинейка!$O$3:$O$1000,Однолинейка!$AH$3:$AH$1000,BI32,Однолинейка!$A$3:$A$1000,BH32)) | BM32: =IF(BI32="","",COUNTIFS(Однолинейка!$AH$3:$AH$1000,BI32,Однолинейка!$A$3:$A$1000,BH32,Однолинейка!$N$3:$N$1000,"р")) | BN32: =IF(OR(BI32="",BK32=""),"",BK32-BL32)
P33: LD | Q33: Питание подсветок | R33: 3 | S33: 1 | T33: 1 | AJ33: =AL33&" ("&AM33&"х"&AN33&") "&AO33 | AK33: МСК030 | AL33: ВВГнг(А)-LS | AM33: 5 | AN33: 50 | AO33: 2 | AU33: =IF(P33="","",P33) | AV33: Светильник | AW33: нет | AX33: 10 | BH33: =IFERROR(INDEX(Однолинейка!$A$1:$A$1000,(MATCH(29,Однолинейка!$BS$1:$BS$1000,0))),"") | BI33: =IFERROR(INDEX(Однолинейка!$AW$1:$AW$1000,(MATCH(29,Однолинейка!$BS$1:$BS$1000,0))),"") | BJ33: =IF(BI33="","",INDEX(Однолинейка!$AI$1:$AI$1000,(MATCH(29,Однолинейка!$BS$1:$BS$1000,0)))) | BK33: =IF(BI33="","",IFERROR(VLOOKUP(BJ33,Модули_спр,3,FALSE),"")) | BL33: =IF(BI33="","",_xlfn.MAXIFS(Однолинейка!$O$3:$O$1000,Однолинейка!$AH$3:$AH$1000,BI33,Однолинейка!$A$3:$A$1000,BH33)) | BM33: =IF(BI33="","",COUNTIFS(Однолинейка!$AH$3:$AH$1000,BI33,Однолинейка!$A$3:$A$1000,BH33,Однолинейка!$N$3:$N$1000,"р")) | BN33: =IF(OR(BI33="",BK33=""),"",BK33-BL33)
P34: КМН | Q34: Электрокамин | R34: 1 | S34: 1 | T34: 1 | AJ34: =AL34&" ("&AM34&"х"&AN34&") "&AO34 | AK34: МСК031 | AL34: ВВГнг(А)-LS | AM34: 5 | AN34: 95 | AO34: 1 | AU34: =IF(P34="","",P34) | AV34: Нагреватель | AW34: нет | BH34: =IFERROR(INDEX(Однолинейка!$A$1:$A$1000,(MATCH(30,Однолинейка!$BS$1:$BS$1000,0))),"") | BI34: =IFERROR(INDEX(Однолинейка!$AW$1:$AW$1000,(MATCH(30,Однолинейка!$BS$1:$BS$1000,0))),"") | BJ34: =IF(BI34="","",INDEX(Однолинейка!$AI$1:$AI$1000,(MATCH(30,Однолинейка!$BS$1:$BS$1000,0)))) | BK34: =IF(BI34="","",IFERROR(VLOOKUP(BJ34,Модули_спр,3,FALSE),"")) | BL34: =IF(BI34="","",_xlfn.MAXIFS(Однолинейка!$O$3:$O$1000,Однолинейка!$AH$3:$AH$1000,BI34,Однолинейка!$A$3:$A$1000,BH34)) | BM34: =IF(BI34="","",COUNTIFS(Однолинейка!$AH$3:$AH$1000,BI34,Однолинейка!$A$3:$A$1000,BH34,Однолинейка!$N$3:$N$1000,"р")) | BN34: =IF(OR(BI34="",BK34=""),"",BK34-BL34)
AJ35: =AL35&" ("&AM35&"х"&AN35&") "&AO35 | AK35: МСК032 | AL35: ВВГнг(А)-LS | AM35: 5 | AN35: 95 | AO35: 2 | AU35: =IF(P35="","",P35) | BH35: =IFERROR(INDEX(Однолинейка!$A$1:$A$1000,(MATCH(31,Однолинейка!$BS$1:$BS$1000,0))),"") | BI35: =IFERROR(INDEX(Однолинейка!$AW$1:$AW$1000,(MATCH(31,Однолинейка!$BS$1:$BS$1000,0))),"") | BJ35: =IF(BI35="","",INDEX(Однолинейка!$AI$1:$AI$1000,(MATCH(31,Однолинейка!$BS$1:$BS$1000,0)))) | BK35: =IF(BI35="","",IFERROR(VLOOKUP(BJ35,Модули_спр,3,FALSE),"")) | BL35: =IF(BI35="","",_xlfn.MAXIFS(Однолинейка!$O$3:$O$1000,Однолинейка!$AH$3:$AH$1000,BI35,Однолинейка!$A$3:$A$1000,BH35)) | BM35: =IF(BI35="","",COUNTIFS(Однолинейка!$AH$3:$AH$1000,BI35,Однолинейка!$A$3:$A$1000,BH35,Однолинейка!$N$3:$N$1000,"р")) | BN35: =IF(OR(BI35="",BK35=""),"",BK35-BL35)
AJ36: =AL36&" ("&AM36&"х"&AN36&") "&AO36 | AK36: МСК033 | AL36: ВВГнг(А)-LS | AM36: 5 | AN36: 120 | AO36: 1 | AU36: =IF(P36="","",P36) | BH36: =IFERROR(INDEX(Однолинейка!$A$1:$A$1000,(MATCH(32,Однолинейка!$BS$1:$BS$1000,0))),"") | BI36: =IFERROR(INDEX(Однолинейка!$AW$1:$AW$1000,(MATCH(32,Однолинейка!$BS$1:$BS$1000,0))),"") | BJ36: =IF(BI36="","",INDEX(Однолинейка!$AI$1:$AI$1000,(MATCH(32,Однолинейка!$BS$1:$BS$1000,0)))) | BK36: =IF(BI36="","",IFERROR(VLOOKUP(BJ36,Модули_спр,3,FALSE),"")) | BL36: =IF(BI36="","",_xlfn.MAXIFS(Однолинейка!$O$3:$O$1000,Однолинейка!$AH$3:$AH$1000,BI36,Однолинейка!$A$3:$A$1000,BH36)) | BM36: =IF(BI36="","",COUNTIFS(Однолинейка!$AH$3:$AH$1000,BI36,Однолинейка!$A$3:$A$1000,BH36,Однолинейка!$N$3:$N$1000,"р")) | BN36: =IF(OR(BI36="",BK36=""),"",BK36-BL36)
AJ37: =AL37&" ("&AM37&"х"&AN37&") "&AO37 | AK37: МСК034 | AL37: ВВГнг(А)-LS | AM37: 5 | AN37: 120 | AO37: 2 | AU37: =IF(P37="","",P37) | BH37: =IFERROR(INDEX(Однолинейка!$A$1:$A$1000,(MATCH(33,Однолинейка!$BS$1:$BS$1000,0))),"") | BI37: =IFERROR(INDEX(Однолинейка!$AW$1:$AW$1000,(MATCH(33,Однолинейка!$BS$1:$BS$1000,0))),"") | BJ37: =IF(BI37="","",INDEX(Однолинейка!$AI$1:$AI$1000,(MATCH(33,Однолинейка!$BS$1:$BS$1000,0)))) | BK37: =IF(BI37="","",IFERROR(VLOOKUP(BJ37,Модули_спр,3,FALSE),"")) | BL37: =IF(BI37="","",_xlfn.MAXIFS(Однолинейка!$O$3:$O$1000,Однолинейка!$AH$3:$AH$1000,BI37,Однолинейка!$A$3:$A$1000,BH37)) | BM37: =IF(BI37="","",COUNTIFS(Однолинейка!$AH$3:$AH$1000,BI37,Однолинейка!$A$3:$A$1000,BH37,Однолинейка!$N$3:$N$1000,"р")) | BN37: =IF(OR(BI37="",BK37=""),"",BK37-BL37)
AJ38: =AL38&" ("&AM38&"х"&AN38&") "&AO38 | AK38: МСК035 | AL38: ВВГнг(А)-LS | AM38: 5 | AN38: 95 | AO38: 1 | AU38: =IF(P38="","",P38) | BH38: =IFERROR(INDEX(Однолинейка!$A$1:$A$1000,(MATCH(34,Однолинейка!$BS$1:$BS$1000,0))),"") | BI38: =IFERROR(INDEX(Однолинейка!$AW$1:$AW$1000,(MATCH(34,Однолинейка!$BS$1:$BS$1000,0))),"") | BJ38: =IF(BI38="","",INDEX(Однолинейка!$AI$1:$AI$1000,(MATCH(34,Однолинейка!$BS$1:$BS$1000,0)))) | BK38: =IF(BI38="","",IFERROR(VLOOKUP(BJ38,Модули_спр,3,FALSE),"")) | BL38: =IF(BI38="","",_xlfn.MAXIFS(Однолинейка!$O$3:$O$1000,Однолинейка!$AH$3:$AH$1000,BI38,Однолинейка!$A$3:$A$1000,BH38)) | BM38: =IF(BI38="","",COUNTIFS(Однолинейка!$AH$3:$AH$1000,BI38,Однолинейка!$A$3:$A$1000,BH38,Однолинейка!$N$3:$N$1000,"р")) | BN38: =IF(OR(BI38="",BK38=""),"",BK38-BL38)
AJ39: =AL39&" ("&AM39&"х"&AN39&") "&AO39 | AK39: МСК036 | AL39: ВВГнг(А)-LS | AM39: 5 | AN39: 95 | AO39: 2 | AU39: =IF(P39="","",P39) | BH39: =IFERROR(INDEX(Однолинейка!$A$1:$A$1000,(MATCH(35,Однолинейка!$BS$1:$BS$1000,0))),"") | BI39: =IFERROR(INDEX(Однолинейка!$AW$1:$AW$1000,(MATCH(35,Однолинейка!$BS$1:$BS$1000,0))),"") | BJ39: =IF(BI39="","",INDEX(Однолинейка!$AI$1:$AI$1000,(MATCH(35,Однолинейка!$BS$1:$BS$1000,0)))) | BK39: =IF(BI39="","",IFERROR(VLOOKUP(BJ39,Модули_спр,3,FALSE),"")) | BL39: =IF(BI39="","",_xlfn.MAXIFS(Однолинейка!$O$3:$O$1000,Однолинейка!$AH$3:$AH$1000,BI39,Однолинейка!$A$3:$A$1000,BH39)) | BM39: =IF(BI39="","",COUNTIFS(Однолинейка!$AH$3:$AH$1000,BI39,Однолинейка!$A$3:$A$1000,BH39,Однолинейка!$N$3:$N$1000,"р")) | BN39: =IF(OR(BI39="",BK39=""),"",BK39-BL39)
AJ40: =AL40&" ("&AM40&"х"&AN40&") "&AO40 | AK40: МСК037 | AL40: ВВГнг(А)-LS | AM40: 5 | AN40: 120 | AO40: 1 | AU40: =IF(P40="","",P40)
AJ41: =AL41&" ("&AM41&"х"&AN41&") "&AO41 | AK41: МСК038 | AL41: ВВГнг(А)-LS | AM41: 5 | AN41: 120 | AO41: 2 | AU41: =IF(P41="","",P41) | BH41: Свободных каналов всего | BN41: =SUM(BN5:BN39)
...

Sheet Каталог
A1: КАТАЛОГ ОБОРУДОВАНИЯ. Спецификация собирается отсюда: N — посчитано по однолинейке, O — впишите вручную (корпус, провод, запас). Добавляйте строки вниз.
X2: список автоматов | Z2: список аппаратов | AB2: список модулей | AD2: список произв.
A3: Категория (раздел) | B3: Производитель | C3: Модель (как в таблице) | D3: Префикс модуля | E3: Каналов | F3: Тип каналов | G3: Наименование для спецификации | H3: Артикул | I3: Полюса | J3: Номинал, А | K3: 30 мА | L3: Ширина, мод. DIN | M3: Ед. | N3: По однолинейке (авто) | O3: Вручную / запас (+) | P3: ИТОГО в спецификацию | R3: НАСТРОЙКИ | S3: Значение | U3: обозначение | V3: ключ | W3: № авт. | X3: авто | Y3: № апп. | Z3: список аппаратов | AA3: № мод. | AB3: - | AC3: № произв. | AD3: (все) | AE3: ключ сортировки | AF3: № в спецификации | AG3: нет в каталоге | AH3: №
A4: Автомат | B4: Chint | C4: NB1-63 1P C10 | G4: Автоматический выключатель NB1-63 1P 10А 6кА х-ка C (DB) | H4: 179614 | I4: 1P | J4: 10 | K4: нет | L4: 1 | M4: шт. | N4: =IF(OR(A4="Автомат",A4="Дифавтомат"),IF(W4="","",COUNTIF(Однолинейка!$H$3:$H$1000,U4)),IF(A4="Аппарат",IF(C4="","",COUNTIF(Однолинейка!$I$3:$I$1000,C4)+COUNTIF(Однолинейка!$J$3:$J$1000,C4)+COUNTIF(Однолинейка!$K$3:$K$1000,C4)),IF(A4="Модуль",IF(C4="","",COUNTIFS(Однолинейка!$AW$3:$AW$1000,"?*",Однолинейка!$AI$3:$AI$1000,C4)),IF(A4="Клемма",IF(C4="","",IF(C4=$S$7,SUM(Однолинейка!$BW$3:$BW$1000),IF(C4=$S$8,SUM(Однолинейка!$BX$3:$BX$1000),""))),"")))) | P4: =IF(COUNT(N4,O4)=0,"",SUM(N4,O4)) | R4: Производитель автоматов | S4: Chint | U4: =IF(OR(A4="Автомат",A4="Дифавтомат"),I4&" С"&J4&"А"&IF(K4="да"," 30мА",""),"") | V4: =IF(U4="","",B4&"|"&U4) | W4: =IF(AND(U4<>"",OR($S$4="(все)",B4=$S$4),IF($S$4="(все)",COUNTIF($U$4:U4,U4),COUNTIFS($U$4:U4,U4,$B$4:B4,B4))=1),MAX($W$3:W3)+1,"") | X4: =IFERROR(INDEX($U$4:$U$500,MATCH(ROW()-3,$W$4:$W$500,0)),"") | Y4: =IF(AND(A4="Аппарат",C4<>"",OR($S$5="(все)",B4=$S$5)),MAX($Y$3:Y3)+1,"") | Z4: =IFERROR(INDEX($C$4:$C$500,MATCH(ROW()-3,$Y$4:$Y$500,0)),"") | AA4: =IF(AND(A4="Модуль",C4<>"",OR($S$6="(все)",B4=$S$6)),MAX($AA$3:AA3)+1,"") | AB4: =IFERROR(INDEX($C$4:$C$500,MATCH(ROW()-3,$AA$4:$AA$500,0)),"") | AC4: =IF(OR(B4="",COUNTIF($B$4:B4,B4)>1),"",MAX($AC$3:AC3)+1) | AD4: =IFERROR(INDEX($B$4:$B$500,MATCH(ROW()-3,$AC$4:$AC$500,0)),"") | AE4: =IF(AND(A4<>"",N(P4)>0),IFERROR(MATCH(A4,$R$12:$R$25,0),99)*1000+ROW(),"") | AF4: =IF(AE4="","",COUNTIF($AE$4:$AE$500,"<="&AE4)) | AG4: =IF(Спецификация_авто!$L$4="","",IF(IF($S$4="(все)",COUNTIF($U$4:$U$500,Спецификация_авто!$L$4),COUNTIF($V$4:$V$500,$S$4&"|"&Спецификация_авто!$L$4))=0,Спецификация_авто!$L$4,"")) | AH4: =IF(AG4="","",COUNTIF($AG$4:AG4,"?*"))
A5: Автомат | B5: Chint | C5: NB1-63 1P C16 | G5: Автоматический выключатель NB1-63 1P 16А 6кА х-ка C (DB) | H5: 179616 | I5: 1P | J5: 16 | K5: нет | L5: 1 | M5: шт. | N5: =IF(OR(A5="Автомат",A5="Дифавтомат"),IF(W5="","",COUNTIF(Однолинейка!$H$3:$H$1000,U5)),IF(A5="Аппарат",IF(C5="","",COUNTIF(Однолинейка!$I$3:$I$1000,C5)+COUNTIF(Однолинейка!$J$3:$J$1000,C5)+COUNTIF(Однолинейка!$K$3:$K$1000,C5)),IF(A5="Модуль",IF(C5="","",COUNTIFS(Однолинейка!$AW$3:$AW$1000,"?*",Однолинейка!$AI$3:$AI$1000,C5)),IF(A5="Клемма",IF(C5="","",IF(C5=$S$7,SUM(Однолинейка!$BW$3:$BW$1000),IF(C5=$S$8,SUM(Однолинейка!$BX$3:$BX$1000),""))),"")))) | P5: =IF(COUNT(N5,O5)=0,"",SUM(N5,O5)) | R5: Производитель аппаратов | S5: (все) | U5: =IF(OR(A5="Автомат",A5="Дифавтомат"),I5&" С"&J5&"А"&IF(K5="да"," 30мА",""),"") | V5: =IF(U5="","",B5&"|"&U5) | W5: =IF(AND(U5<>"",OR($S$4="(все)",B5=$S$4),IF($S$4="(все)",COUNTIF($U$4:U5,U5),COUNTIFS($U$4:U5,U5,$B$4:B5,B5))=1),MAX($W$3:W4)+1,"") | X5: =IFERROR(INDEX($U$4:$U$500,MATCH(ROW()-3,$W$4:$W$500,0)),"") | Y5: =IF(AND(A5="Аппарат",C5<>"",OR($S$5="(все)",B5=$S$5)),MAX($Y$3:Y4)+1,"") | Z5: =IFERROR(INDEX($C$4:$C$500,MATCH(ROW()-3,$Y$4:$Y$500,0)),"") | AA5: =IF(AND(A5="Модуль",C5<>"",OR($S$6="(все)",B5=$S$6)),MAX($AA$3:AA4)+1,"") | AB5: =IFERROR(INDEX($C$4:$C$500,MATCH(ROW()-3,$AA$4:$AA$500,0)),"") | AC5: =IF(OR(B5="",COUNTIF($B$4:B5,B5)>1),"",MAX($AC$3:AC4)+1) | AD5: =IFERROR(INDEX($B$4:$B$500,MATCH(ROW()-3,$AC$4:$AC$500,0)),"") | AE5: =IF(AND(A5<>"",N(P5)>0),IFERROR(MATCH(A5,$R$12:$R$25,0),99)*1000+ROW(),"") | AF5: =IF(AE5="","",COUNTIF($AE$4:$AE$500,"<="&AE5)) | AG5: =IF(Спецификация_авто!$L$5="","",IF(IF($S$4="(все)",COUNTIF($U$4:$U$500,Спецификация_авто!$L$5),COUNTIF($V$4:$V$500,$S$4&"|"&Спецификация_авто!$L$5))=0,Спецификация_авто!$L$5,"")) | AH5: =IF(AG5="","",COUNTIF($AG$4:AG5,"?*"))
A6: Автомат | B6: Chint | C6: NB1-63 3P C20 | G6: Автоматический выключатель NB1-63 3P 20А 6кА х-ка C (DB) | H6: 179702 | I6: 3P | J6: 20 | K6: нет | L6: 3 | M6: шт. | N6: =IF(OR(A6="Автомат",A6="Дифавтомат"),IF(W6="","",COUNTIF(Однолинейка!$H$3:$H$1000,U6)),IF(A6="Аппарат",IF(C6="","",COUNTIF(Однолинейка!$I$3:$I$1000,C6)+COUNTIF(Однолинейка!$J$3:$J$1000,C6)+COUNTIF(Однолинейка!$K$3:$K$1000,C6)),IF(A6="Модуль",IF(C6="","",COUNTIFS(Однолинейка!$AW$3:$AW$1000,"?*",Однолинейка!$AI$3:$AI$1000,C6)),IF(A6="Клемма",IF(C6="","",IF(C6=$S$7,SUM(Однолинейка!$BW$3:$BW$1000),IF(C6=$S$8,SUM(Однолинейка!$BX$3:$BX$1000),""))),"")))) | P6: =IF(COUNT(N6,O6)=0,"",SUM(N6,O6)) | R6: Производитель модулей | S6: (все) | U6: =IF(OR(A6="Автомат",A6="Дифавтомат"),I6&" С"&J6&"А"&IF(K6="да"," 30мА",""),"") | V6: =IF(U6="","",B6&"|"&U6) | W6: =IF(AND(U6<>"",OR($S$4="(все)",B6=$S$4),IF($S$4="(все)",COUNTIF($U$4:U6,U6),COUNTIFS($U$4:U6,U6,$B$4:B6,B6))=1),MAX($W$3:W5)+1,"") | X6: =IFERROR(INDEX($U$4:$U$500,MATCH(ROW()-3,$W$4:$W$500,0)),"") | Y6: =IF(AND(A6="Аппарат",C6<>"",OR($S$5="(все)",B6=$S$5)),MAX($Y$3:Y5)+1,"") | Z6: =IFERROR(INDEX($C$4:$C$500,MATCH(ROW()-3,$Y$4:$Y$500,0)),"") | AA6: =IF(AND(A6="Модуль",C6<>"",OR($S$6="(все)",B6=$S$6)),MAX($AA$3:AA5)+1,"") | AB6: =IFERROR(INDEX($C$4:$C$500,MATCH(ROW()-3,$AA$4:$AA$500,0)),"") | AC6: =IF(OR(B6="",COUNTIF($B$4:B6,B6)>1),"",MAX($AC$3:AC5)+1) | AD6: =IFERROR(INDEX($B$4:$B$500,MATCH(ROW()-3,$AC$4:$AC$500,0)),"") | AE6: =IF(AND(A6<>"",N(P6)>0),IFERROR(MATCH(A6,$R$12:$R$25,0),99)*1000+ROW(),"") | AF6: =IF(AE6="","",COUNTIF($AE$4:$AE$500,"<="&AE6)) | AG6: =IF(Спецификация_авто!$L$6="","",IF(IF($S$4="(все)",COUNTIF($U$4:$U$500,Спецификация_авто!$L$6),COUNTIF($V$4:$V$500,$S$4&"|"&Спецификация_авто!$L$6))=0,Спецификация_авто!$L$6,"")) | AH6: =IF(AG6="","",COUNTIF($AG$4:AG6,"?*"))
A7: Автомат | B7: Chint | C7: NB1-63 4P C50 | G7: Автоматический выключатель NB1-63 4P 50А 6кА х-ка C (DB) | H7: 179750 | I7: 4P | J7: 50 | K7: нет | L7: 4 | M7: шт. | N7: =IF(OR(A7="Автомат",A7="Дифавтомат"),IF(W7="","",COUNTIF(Однолинейка!$H$3:$H$1000,U7)),IF(A7="Аппарат",IF(C7="","",COUNTIF(Однолинейка!$I$3:$I$1000,C7)+COUNTIF(Однолинейка!$J$3:$J$1000,C7)+COUNTIF(Однолинейка!$K$3:$K$1000,C7)),IF(A7="Модуль",IF(C7="","",COUNTIFS(Однолинейка!$AW$3:$AW$1000,"?*",Однолинейка!$AI$3:$AI$1000,C7)),IF(A7="Клемма",IF(C7="","",IF(C7=$S$7,SUM(Однолинейка!$BW$3:$BW$1000),IF(C7=$S$8,SUM(Однолинейка!$BX$3:$BX$1000),""))),"")))) | P7: =IF(COUNT(N7,O7)=0,"",SUM(N7,O7)) | R7: Клемма трёхуровневая (модель) | S7: VPR-2.5-3L-GY | U7: =IF(OR(A7="Автомат",A7="Дифавтомат"),I7&" С"&J7&"А"&IF(K7="да"," 30мА",""),"") | V7: =IF(U7="","",B7&"|"&U7) | W7: =IF(AND(U7<>"",OR($S$4="(все)",B7=$S$4),IF($S$4="(все)",COUNTIF($U$4:U7,U7),COUNTIFS($U$4:U7,U7,$B$4:B7,B7))=1),MAX($W$3:W6)+1,"") | X7: =IFERROR(INDEX($U$4:$U$500,MATCH(ROW()-3,$W$4:$W$500,0)),"") | Y7: =IF(AND(A7="Аппарат",C7<>"",OR($S$5="(все)",B7=$S$5)),MAX($Y$3:Y6)+1,"") | Z7: =IFERROR(INDEX($C$4:$C$500,MATCH(ROW()-3,$Y$4:$Y$500,0)),"") | AA7: =IF(AND(A7="Модуль",C7<>"",OR($S$6="(все)",B7=$S$6)),MAX($AA$3:AA6)+1,"") | AB7: =IFERROR(INDEX($C$4:$C$500,MATCH(ROW()-3,$AA$4:$AA$500,0)),"") | AC7: =IF(OR(B7="",COUNTIF($B$4:B7,B7)>1),"",MAX($AC$3:AC6)+1) | AD7: =IFERROR(INDEX($B$4:$B$500,MATCH(ROW()-3,$AC$4:$AC$500,0)),"") | AE7: =IF(AND(A7<>"",N(P7)>0),IFERROR(MATCH(A7,$R$12:$R$25,0),99)*1000+ROW(),"") | AF7: =IF(AE7="","",COUNTIF($AE$4:$AE$500,"<="&AE7)) | AG7: =IF(Спецификация_авто!$L$7="","",IF(IF($S$4="(все)",COUNTIF($U$4:$U$500,Спецификация_авто!$L$7),COUNTIF($V$4:$V$500,$S$4&"|"&Спецификация_авто!$L$7))=0,Спецификация_авто!$L$7,"")) | AH7: =IF(AG7="","",COUNTIF($AG$4:AG7,"?*"))
A8: Автомат | B8: Chint | C8: NXB-125 3P C80 | G8: Автоматический выключатель NXB-125 3P C80 10кА х-ка C | H8: 816139 | I8: 3P | J8: 80 | K8: нет | L8: 4.5 | M8: шт. | N8: =IF(OR(A8="Автомат",A8="Дифавтомат"),IF(W8="","",COUNTIF(Однолинейка!$H$3:$H$1000,U8)),IF(A8="Аппарат",IF(C8="","",COUNTIF(Однолинейка!$I$3:$I$1000,C8)+COUNTIF(Однолинейка!$J$3:$J$1000,C8)+COUNTIF(Однолинейка!$K$3:$K$1000,C8)),IF(A8="Модуль",IF(C8="","",COUNTIFS(Однолинейка!$AW$3:$AW$1000,"?*",Однолинейка!$AI$3:$AI$1000,C8)),IF(A8="Клемма",IF(C8="","",IF(C8=$S$7,SUM(Однолинейка!$BW$3:$BW$1000),IF(C8=$S$8,SUM(Однолинейка!$BX$3:$BX$1000),""))),"")))) | P8: =IF(COUNT(N8,O8)=0,"",SUM(N8,O8)) | R8: Клемма проходная доп. (модель) | S8: VPR-2.5-QUATTRO-GY | U8: =IF(OR(A8="Автомат",A8="Дифавтомат"),I8&" С"&J8&"А"&IF(K8="да"," 30мА",""),"") | V8: =IF(U8="","",B8&"|"&U8) | W8: =IF(AND(U8<>"",OR($S$4="(все)",B8=$S$4),IF($S$4="(все)",COUNTIF($U$4:U8,U8),COUNTIFS($U$4:U8,U8,$B$4:B8,B8))=1),MAX($W$3:W7)+1,"") | X8: =IFERROR(INDEX($U$4:$U$500,MATCH(ROW()-3,$W$4:$W$500,0)),"") | Y8: =IF(AND(A8="Аппарат",C8<>"",OR($S$5="(все)",B8=$S$5)),MAX($Y$3:Y7)+1,"") | Z8: =IFERROR(INDEX($C$4:$C$500,MATCH(ROW()-3,$Y$4:$Y$500,0)),"") | AA8: =IF(AND(A8="Модуль",C8<>"",OR($S$6="(все)",B8=$S$6)),MAX($AA$3:AA7)+1,"") | AB8: =IFERROR(INDEX($C$4:$C$500,MATCH(ROW()-3,$AA$4:$AA$500,0)),"") | AC8: =IF(OR(B8="",COUNTIF($B$4:B8,B8)>1),"",MAX($AC$3:AC7)+1) | AD8: =IFERROR(INDEX($B$4:$B$500,MATCH(ROW()-3,$AC$4:$AC$500,0)),"") | AE8: =IF(AND(A8<>"",N(P8)>0),IFERROR(MATCH(A8,$R$12:$R$25,0),99)*1000+ROW(),"") | AF8: =IF(AE8="","",COUNTIF($AE$4:$AE$500,"<="&AE8)) | AG8: =IF(Спецификация_авто!$L$8="","",IF(IF($S$4="(все)",COUNTIF($U$4:$U$500,Спецификация_авто!$L$8),COUNTIF($V$4:$V$500,$S$4&"|"&Спецификация_авто!$L$8))=0,Спецификация_авто!$L$8,"")) | AH8: =IF(AG8="","",COUNTIF($AG$4:AG8,"?*"))
A9: Дифавтомат | B9: Chint | C9: NB1L 1P+N C16 30мА | G9: Дифавтомат (АВДТ) NB1L 1P+N C16 30мА тип A 6кА | H9: 203019 | I9: 2P | J9: 16 | K9: да | L9: 2 | M9: шт. | N9: =IF(OR(A9="Автомат",A9="Дифавтомат"),IF(W9="","",COUNTIF(Однолинейка!$H$3:$H$1000,U9)),IF(A9="Аппарат",IF(C9="","",COUNTIF(Однолинейка!$I$3:$I$1000,C9)+COUNTIF(Однолинейка!$J$3:$J$1000,C9)+COUNTIF(Однолинейка!$K$3:$K$1000,C9)),IF(A9="Модуль",IF(C9="","",COUNTIFS(Однолинейка!$AW$3:$AW$1000,"?*",Однолинейка!$AI$3:$AI$1000,C9)),IF(A9="Клемма",IF(C9="","",IF(C9=$S$7,SUM(Однолинейка!$BW$3:$BW$1000),IF(C9=$S$8,SUM(Однолинейка!$BX$3:$BX$1000),""))),"")))) | P9: =IF(COUNT(N9,O9)=0,"",SUM(N9,O9)) | R9: Трёхуровневых на 4–5-жильную линию, если по коду не задано | S9: 1 | U9: =IF(OR(A9="Автомат",A9="Дифавтомат"),I9&" С"&J9&"А"&IF(K9="да"," 30мА",""),"") | V9: =IF(U9="","",B9&"|"&U9) | W9: =IF(AND(U9<>"",OR($S$4="(все)",B9=$S$4),IF($S$4="(все)",COUNTIF($U$4:U9,U9),COUNTIFS($U$4:U9,U9,$B$4:B9,B9))=1),MAX($W$3:W8)+1,"") | X9: =IFERROR(INDEX($U$4:$U$500,MATCH(ROW()-3,$W$4:$W$500,0)),"") | Y9: =IF(AND(A9="Аппарат",C9<>"",OR($S$5="(все)",B9=$S$5)),MAX($Y$3:Y8)+1,"") | Z9: =IFERROR(INDEX($C$4:$C$500,MATCH(ROW()-3,$Y$4:$Y$500,0)),"") | AA9: =IF(AND(A9="Модуль",C9<>"",OR($S$6="(все)",B9=$S$6)),MAX($AA$3:AA8)+1,"") | AB9: =IFERROR(INDEX($C$4:$C$500,MATCH(ROW()-3,$AA$4:$AA$500,0)),"") | AC9: =IF(OR(B9="",COUNTIF($B$4:B9,B9)>1),"",MAX($AC$3:AC8)+1) | AD9: =IFERROR(INDEX($B$4:$B$500,MATCH(ROW()-3,$AC$4:$AC$500,0)),"") | AE9: =IF(AND(A9<>"",N(P9)>0),IFERROR(MATCH(A9,$R$12:$R$25,0),99)*1000+ROW(),"") | AF9: =IF(AE9="","",COUNTIF($AE$4:$AE$500,"<="&AE9)) | AG9: =IF(Спецификация_авто!$L$9="","",IF(IF($S$4="(все)",COUNTIF($U$4:$U$500,Спецификация_авто!$L$9),COUNTIF($V$4:$V$500,$S$4&"|"&Спецификация_авто!$L$9))=0,Спецификация_авто!$L$9,"")) | AH9: =IF(AG9="","",COUNTIF($AG$4:AG9,"?*"))
A10: Дифавтомат | B10: Chint | C10: NB1L 1P+N C20 30мА | G10: Дифавтомат (АВДТ) NB1L 1P+N C20 30мА тип A 6кА | H10: 203296 | I10: 2P | J10: 20 | K10: да | L10: 2 | M10: шт. | N10: =IF(OR(A10="Автомат",A10="Дифавтомат"),IF(W10="","",COUNTIF(Однолинейка!$H$3:$H$1000,U10)),IF(A10="Аппарат",IF(C10="","",COUNTIF(Однолинейка!$I$3:$I$1000,C10)+COUNTIF(Однолинейка!$J$3:$J$1000,C10)+COUNTIF(Однолинейка!$K$3:$K$1000,C10)),IF(A10="Модуль",IF(C10="","",COUNTIFS(Однолинейка!$AW$3:$AW$1000,"?*",Однолинейка!$AI$3:$AI$1000,C10)),IF(A10="Клемма",IF(C10="","",IF(C10=$S$7,SUM(Однолинейка!$BW$3:$BW$1000),IF(C10=$S$8,SUM(Однолинейка!$BX$3:$BX$1000),""))),"")))) | P10: =IF(COUNT(N10,O10)=0,"",SUM(N10,O10)) | U10: =IF(OR(A10="Автомат",A10="Дифавтомат"),I10&" С"&J10&"А"&IF(K10="да"," 30мА",""),"") | V10: =IF(U10="","",B10&"|"&U10) | W10: =IF(AND(U10<>"",OR($S$4="(все)",B10=$S$4),IF($S$4="(все)",COUNTIF($U$4:U10,U10),COUNTIFS($U$4:U10,U10,$B$4:B10,B10))=1),MAX($W$3:W9)+1,"") | X10: =IFERROR(INDEX($U$4:$U$500,MATCH(ROW()-3,$W$4:$W$500,0)),"") | Y10: =IF(AND(A10="Аппарат",C10<>"",OR($S$5="(все)",B10=$S$5)),MAX($Y$3:Y9)+1,"") | Z10: =IFERROR(INDEX($C$4:$C$500,MATCH(ROW()-3,$Y$4:$Y$500,0)),"") | AA10: =IF(AND(A10="Модуль",C10<>"",OR($S$6="(все)",B10=$S$6)),MAX($AA$3:AA9)+1,"") | AB10: =IFERROR(INDEX($C$4:$C$500,MATCH(ROW()-3,$AA$4:$AA$500,0)),"") | AC10: =IF(OR(B10="",COUNTIF($B$4:B10,B10)>1),"",MAX($AC$3:AC9)+1) | AD10: =IFERROR(INDEX($B$4:$B$500,MATCH(ROW()-3,$AC$4:$AC$500,0)),"") | AE10: =IF(AND(A10<>"",N(P10)>0),IFERROR(MATCH(A10,$R$12:$R$25,0),99)*1000+ROW(),"") | AF10: =IF(AE10="","",COUNTIF($AE$4:$AE$500,"<="&AE10)) | AG10: =IF(Спецификация_авто!$L$10="","",IF(IF($S$4="(все)",COUNTIF($U$4:$U$500,Спецификация_авто!$L$10),COUNTIF($V$4:$V$500,$S$4&"|"&Спецификация_авто!$L$10))=0,Спецификация_авто!$L$10,"")) | AH10: =IF(AG10="","",COUNTIF($AG$4:AG10,"?*"))
A11: Дифавтомат | B11: Chint | C11: NB1L 1P+N C32 30мА | G11: Дифавтомат (АВДТ) NB1L 1P+N C32 30мА тип A 6кА | H11: 982114 | I11: 2P | J11: 32 | K11: да | L11: 2 | M11: шт. | N11: =IF(OR(A11="Автомат",A11="Дифавтомат"),IF(W11="","",COUNTIF(Однолинейка!$H$3:$H$1000,U11)),IF(A11="Аппарат",IF(C11="","",COUNTIF(Однолинейка!$I$3:$I$1000,C11)+COUNTIF(Однолинейка!$J$3:$J$1000,C11)+COUNTIF(Однолинейка!$K$3:$K$1000,C11)),IF(A11="Модуль",IF(C11="","",COUNTIFS(Однолинейка!$AW$3:$AW$1000,"?*",Однолинейка!$AI$3:$AI$1000,C11)),IF(A11="Клемма",IF(C11="","",IF(C11=$S$7,SUM(Однолинейка!$BW$3:$BW$1000),IF(C11=$S$8,SUM(Однолинейка!$BX$3:$BX$1000),""))),"")))) | P11: =IF(COUNT(N11,O11)=0,"",SUM(N11,O11)) | R11: ПОРЯДОК РАЗДЕЛОВ СПЕЦИФИКАЦИИ (можно менять и дописывать) | U11: =IF(OR(A11="Автомат",A11="Дифавтомат"),I11&" С"&J11&"А"&IF(K11="да"," 30мА",""),"") | V11: =IF(U11="","",B11&"|"&U11) | W11: =IF(AND(U11<>"",OR($S$4="(все)",B11=$S$4),IF($S$4="(все)",COUNTIF($U$4:U11,U11),COUNTIFS($U$4:U11,U11,$B$4:B11,B11))=1),MAX($W$3:W10)+1,"") | X11: =IFERROR(INDEX($U$4:$U$500,MATCH(ROW()-3,$W$4:$W$500,0)),"") | Y11: =IF(AND(A11="Аппарат",C11<>"",OR($S$5="(все)",B11=$S$5)),MAX($Y$3:Y10)+1,"") | Z11: =IFERROR(INDEX($C$4:$C$500,MATCH(ROW()-3,$Y$4:$Y$500,0)),"") | AA11: =IF(AND(A11="Модуль",C11<>"",OR($S$6="(все)",B11=$S$6)),MAX($AA$3:AA10)+1,"") | AB11: =IFERROR(INDEX($C$4:$C$500,MATCH(ROW()-3,$AA$4:$AA$500,0)),"") | AC11: =IF(OR(B11="",COUNTIF($B$4:B11,B11)>1),"",MAX($AC$3:AC10)+1) | AD11: =IFERROR(INDEX($B$4:$B$500,MATCH(ROW()-3,$AC$4:$AC$500,0)),"") | AE11: =IF(AND(A11<>"",N(P11)>0),IFERROR(MATCH(A11,$R$12:$R$25,0),99)*1000+ROW(),"") | AF11: =IF(AE11="","",COUNTIF($AE$4:$AE$500,"<="&AE11)) | AG11: =IF(Спецификация_авто!$L$11="","",IF(IF($S$4="(все)",COUNTIF($U$4:$U$500,Спецификация_авто!$L$11),COUNTIF($V$4:$V$500,$S$4&"|"&Спецификация_авто!$L$11))=0,Спецификация_авто!$L$11,"")) | AH11: =IF(AG11="","",COUNTIF($AG$4:AG11,"?*"))
