Workbook
Name Автомат_номиналы: Справочная!$F$4:$G$13
Name гофра_пвх: Справочная_потребители!$Z$4:$AB$9
Name гофра_пнд: Справочная_потребители!$AD$4:$AF$9
Name Для_диапазонов: 'В Акад'!$B$3:$M$4000
Name Для_расчета_кабелей: Кабельный_журнал!$I$5:$W$1000
Name Исходные_данные: 'Исходные данные'!$A$3:$AT$1000
Name Итог_щит_1: 'В Акад'!$P$2:$U$6
Name Итог_щит_2: 'В Акад'!$P$9:$U$13
Name Кабель_диаметр: Справочная_потребители!$T$4:$X$503
Name Кабель_номиналы: Справочная!$I$4:$J$19
Name Кабель_обозначение: Справочная!$L$4:$N$51
Name Кабель_сопротивление: Справочная!$B$4:$D$19
Name Кабельный_журнал: INDIRECT(Диапазоны!$C$34):INDIRECT(Диапазоны!$F$34)
Name Нагрузка_диапазон_1: Нагрузка_щитов!$D$2:$I$1000
Name Нумерация_щитов_1: Разбивка_по_щитам!$A$3:$A$1000
Name Нумерация_щитов_2: Разбивка_по_щитам!$B$3:$B$1000
Name Потребители_обозначение: Справочная!$P$4:$T$51
Name Разбивка_нумерация_1: Разбивка_по_щитам!$A$3:$U$1000
Name Разбивка_нумерация_2: Разбивка_по_щитам!$B$3:$U$1000
Name Разбивка_нумерация_4: Разбивка_по_щитам!$D$2:$U$1000
Name Разбивка_нумерация_5: Разбивка_по_щитам!$E$2:$U$1000
Name Спецификация: Спецификация!$B$3:$J$60
Name Справочная_двигатели: Справочная_потребители!$B$4:$K$37
Name Справочная_ЛЭД: Справочная_потребители!$M$4:$O$19
Name Справочная_ПТО: Справочная!$AE$4:$AF$200
Name Щит_1: INDIRECT(Диапазоны!$C$4):INDIRECT(Диапазоны!$F$4)
Name Щит_2: INDIRECT(Диапазоны!$C$5):INDIRECT(Диапазоны!$F$5)
Name Этаж_обозначение: Справочная!$Y$4:$AB$19

Sheet Краткое руководство
C1: Версия таблицы 1.05 Демо | E1: Ведомость изменений | H1: Ведомость неисправляемых ошибок
B2: 1 | C2: Нельзя добавлять строки | E2: 1.01 Демо | F2: Создание таблицы | H2: Все резервы идут под одинаковой фазой, нет возможности задать в ручную
B3: 2 | C3: НЕЛЬЗЯ трогать ячейки выделенные синим цветом!!! | E3: 1.02 Демо | F3: Исправлены некоторые ошибки в расчетах
B4: 3 | C4: НЕЛЬЗЯ вставлять столбцы | E4: 1.03 Демо | F4: Добавлено выделение ячеек красным при нарушении потерь напряжения, добавлено выделение ячейки с кол-вом электроприемников
B5: 4 | C5: Нельзя вырезать данные (ctrl+x) | E5: 1.04а Демо | F5: 1.Исправлена ошибка автоназвания потребителя, если нет порядкового номера. 2.Добавлена возможность корректировки Кс и косинуса на листе "Нагрузка_Щитов" (ошибка защиты листа). 3.Начато исправление ошибки ненахождение артикулов на ПК с разделительным знаком "," в таблице ПТО в справочной.
B6: 5 | C6: Листы расставлены в порядке заполнения (Справочная>Исходные данные>Разбивка по щитам>ТКЗ>Нагрузка щитов>Спецификация), прочие листы - системные | E6: 1.04.2а Демо | F6: Исправлены некоторые ошибки в расчетах
B7: 6 | C7: На листе "Кабельный журнал" есть сводная таблица кабелей | E7: 1.04.2б Демо | F7: Добавлен лист токов КЗ для тестирования, добавлена справочная с Iп (не внедрен в расчеты)
B8: 7 | C8: На листе "Кабельный журнал" есть сводная таблица артикулов прокладки | E8: 1.04.2в Демо | F8: Исправлены некоторые ошибки в диапазонах
B9: 8 | C9: Номинал автомата нужен для расчета сечения кабеля, для других целей не используется | E9: 1.05 Демо | F9: Добавлен расчет пусковых токов, добавлен авто Cos(фи) (Нагрузка_щитов) Добавлен расчет КРМ + рекомндация по установке КРМ (Нагрузка_щитов)
B10: 9 | C10: Все ячейки, кроме нужных - заблокированы
B11: 10 | C11: Если какая-то ячейка выделилась красным - значит есть нарушение (ГОСТа, расчета или иное), меняй значения во вводимых данных. Выделенная ячейка как-то связана с ошибкой

Sheet Справочная
L2: Заполнить!!! | AE2: ПТО
B3: Сечение | C3: Индуктивное, Ом/км | D3: Активное, Ом/км | F3: Ток | G3: Автомат | I3: Ток | J3: Кабель | L3: Обознач | M3: Кабель | N3: Сечение (1-да; 2 -нет) | P3: Обознач | Q3: Потребитель | R3: Опуск | S3: 1 - этаж/2 - шлейф | T3: Пусковой ток 1 - нет/2 - двигатель/3-свет | V3: Обознач | W3: Расшифровка | Y3: Обознач | Z3: Этаж | AA3: Подъем | AB3: По другим этажам | AE3: Кабель | AF3: Артикул | AG3: Тип кабеля | AH3: Кол-во жил | AI3: Сечение | AJ3: Пол/Потолок
B4: 0.75 | C4: 0.13 | D4: 0.0175 | F4: 0 | G4: 6 | I4: 0 | J4: 1.5 | L4: мс | M4: ВВГнг(А)-LS | N4: 1 | P4: Ввод | Q4: Ввод питающей линии | R4: 5 | S4: 1 | T4: 1 | V4: тпв | W4: Труба жесткая ПВХ | Y4: 0 | Z4: Цокольный этаж | AE4: =AG4&" ("&AH4&"х"&AI4&") "&AJ4 -> ВВГнг(А)-LS (2х1,5) 1 | AF4: МСК001 | AG4: ВВГнг(А)-LS | AH4: 2 | AI4: 1.5 | AJ4: 1
B5: 1 | C5: 0.11 | D5: 0.0175 | F5: 5.4 | G5: 10 | I5: 19 | J5: 2.5 | L5: мфр | M5: ВВГнг(А)-FRLS | N5: 1 | P5: На ИБП | Q5: Питание на ИБП | R5: 5 | S5: 1 | T5: 1 | V5: тпн | W5: Труба жесткая ПНД | Y5: 1 | AE5: =AG5&" ("&AH5&"х"&AI5&") "&AJ5 -> ВВГнг(А)-LS (2х1,5) 2 | AF5: МСК002 | AG5: ВВГнг(А)-LS | AH5: 2 | AI5: 1.5 | AJ5: 2
B6: 1.5 | C6: 0.11 | D6: 0.0175 | F6: 9 | G6: 16 | I6: 25 | J6: 4 | L6: ютп | M6: FTP-Cat.6-4х2х0.52 | N6: 2 | P6: От ИБП | Q6: Питание от ИБП | R6: 5 | S6: 1 | T6: 1 | V6: гпв | W6: Труба гофрированная ПВХ | Y6: 2 | Z6: Второй этаж | AE6: =AG6&" ("&AH6&"х"&AI6&") "&AJ6 -> ВВГнг(А)-LS (2х2,5) 1 | AF6: МСК003 | AG6: ВВГнг(А)-LS | AH6: 2 | AI6: 2.5 | AJ6: 1
B7: 2.5 | C7: 0.1 | D7: 0.0175 | F7: 14.4 | G7: 20 | I7: 33 | J7: 6 | L7: ре | M7: ПуГВ | N7: 1 | P7: R | Q7: Розеточная группа | R7: 2 | S7: 1 | T7: 1 | V7: гпн | W7: Труба гофрированная ПНД | Y7: 3 | Z7: Третий этаж | AE7: =AG7&" ("&AH7&"х"&AI7&") "&AJ7 -> ВВГнг(А)-LS (2х2,5) 2 | AF7: МСК004 | AG7: ВВГнг(А)-LS | AH7: 2 | AI7: 2.5 | AJ7: 2
B8: 4 | C8: 0.095 | D8: 0.0175 | F8: 18 | G8: 25 | I8: 42 | J8: 10 | L8: мб | M8: ВБШвнг(А)-LS | N8: 1 | P8: L | Q8: Группа освещения | R8: 1 | S8: 1 | T8: 1 | AE8: =AG8&" ("&AH8&"х"&AI8&") "&AJ8 -> ВВГнг(А)-LS (3х1,5) 1 | AF8: МСК005 | AG8: ВВГнг(А)-LS | AH8: 3 | AI8: 1.5 | AJ8: 1
B9: 6 | C9: 0.09 | D9: 0.0175 | F9: 22.5 | G9: 32 | I9: 58 | J9: 16 | L9: кмс | M9: КГВВнг(А)-LS | N9: 1 | P9: LED | Q9: Светодиодное освещение | R9: 1 | S9: 1 | T9: 1 | AE9: =AG9&" ("&AH9&"х"&AI9&") "&AJ9 -> ВВГнг(А)-LS (3х1,5) 2 | AF9: МСК006 | AG9: ВВГнг(А)-LS | AH9: 3 | AI9: 1.5 | AJ9: 2
B10: 10 | C10: 0.073 | D10: 0.0175 | F10: 28.8 | G10: 40 | I10: 78 | J10: 25 | L10: кмб | M10: КВБбШвнг(А)-LS 14x2.5 | N10: 2 | P10: R.ШТК | Q10: Шкаф слаботочных систем | R10: 2 | S10: 1 | T10: 1 | AE10: =AG10&" ("&AH10&"х"&AI10&") "&AJ10 -> ВВГнг(А)-LS (3х2,5) 1 | AF10: МСК007 | AG10: ВВГнг(А)-LS | AH10: 3 | AI10: 2.5 | AJ10: 1
B11: 16 | C11: 0.0675 | D11: 0.0175 | F11: 36 | G11: 50 | I11: 104 | J11: 35 | L11: мфр | M11: ППГнг(А)-FRHF | N11: 1 | P11: R.ЩОПС | Q11: Щит охранно-пожарной сигнализации | R11: 2 | S11: 1 | T11: 1 | AE11: =AG11&" ("&AH11&"х"&AI11&") "&AJ11 -> ВВГнг(А)-LS (3х2,5) 2 | AF11: МСК008 | AG11: ВВГнг(А)-LS | AH11: 3 | AI11: 2.5 | AJ11: 2
B12: 25 | C12: 0.0662 | D12: 0.0175 | F12: 45 | G12: 63 | I12: 127 | J12: 50 | L12: мшф | M12: ППГнг(А)-HF | N12: 1 | P12: АСУ | Q12: Питание системы автоматизации | R12: 1 | S12: 1 | T12: 1 | AE12: =AG12&" ("&AH12&"х"&AI12&") "&AJ12 -> ВВГнг(А)-LS (3х4) 1 | AF12: МСК009 | AG12: ВВГнг(А)-LS | AH12: 3 | AI12: 4 | AJ12: 1
B13: 35 | C13: 0.0637 | D13: 0.0175 | F13: 56.7 | G13: Не исп | I13: 155 | J13: 70 | L13: кн | M13: J-Y(St)Y 2х2х0.8 | N13: 2 | P13: PS-KNX | Q13: Блок питания шины KNX | R13: 1 | S13: 1 | T13: 1 | AE13: =AG13&" ("&AH13&"х"&AI13&") "&AJ13 -> ВВГнг(А)-LS (3х4) 2 | AF13: МСК010 | AG13: ВВГнг(А)-LS | AH13: 3 | AI13: 4 | AJ13: 2
B14: 50 | C14: 0.0625 | D14: 0.0175 | I14: 196 | J14: 95 | L14: кф | M14: КИПЭВ 2х2х0.6 | N14: 2 | P14: В | Q14: Вытяжной вентилятор | R14: 1 | S14: 1 | T14: 1 | AE14: =AG14&" ("&AH14&"х"&AI14&") "&AJ14 -> ВВГнг(А)-LS (3х6) 1 | AF14: МСК011 | AG14: ВВГнг(А)-LS | AH14: 3 | AI14: 6 | AJ14: 1
B15: 70 | C15: 0.0612 | D15: 0.0175 | I15: 242 | J15: 120 | L15: кс | M15: КСПВГ 4х0.35 | N15: 2 | P15: ТП | Q15: Теплый пол | R15: 2 | S15: 1 | T15: 1 | AE15: =AG15&" ("&AH15&"х"&AI15&") "&AJ15 -> ВВГнг(А)-LS (3х6) 2 | AF15: МСК012 | AG15: ВВГнг(А)-LS | AH15: 3 | AI15: 6 | AJ15: 2
B16: 95 | C16: 0.0602 | D16: 0.0175 | I16: 280 | J16: 150 | L16: кмс1 | M16: КГВВнг(А)-LS (5х1) | P16: ЭK | Q16: Шаровый электрокран | R16: 1 | S16: 1 | T16: 1 | AE16: =AG16&" ("&AH16&"х"&AI16&") "&AJ16 -> ВВГнг(А)-LS (5х1,5) 1 | AF16: МСК013 | AG16: ВВГнг(А)-LS | AH16: 5 | AI16: 1.5 | AJ16: 1
B17: 150 | C17: 0.0596 | D17: 0.0175 | I17: 321 | J17: 185 | P17: TE-O | Q17: Управление сервоприводом отопления | R17: 1 | S17: 1 | T17: 1 | AE17: =AG17&" ("&AH17&"х"&AI17&") "&AJ17 -> ВВГнг(А)-LS (5х1,5) 2 | AF17: МСК014 | AG17: ВВГнг(А)-LS | AH17: 5 | AI17: 1.5 | AJ17: 2
B18: 185 | C18: 0.0596 | D18: 0.0175 | I18: 369 | J18: 240 | P18: SH | Q18: Моторзированная нагрузка | R18: 1 | S18: 1 | T18: 1 | AE18: =AG18&" ("&AH18&"х"&AI18&") "&AJ18 -> ВВГнг(А)-LS (5х2,5) 1 | AF18: МСК015 | AG18: ВВГнг(А)-LS | AH18: 5 | AI18: 2.5 | AJ18: 1
B19: 240 | C19: 0.0587 | D19: 0.0175 | I19: 438 | J19: Не исп | P19: DALI | Q19: Контролер DALI | R19: 1 | S19: 2 | T19: 1 | AE19: =AG19&" ("&AH19&"х"&AI19&") "&AJ19 -> ВВГнг(А)-LS (5х2,5) 2 | AF19: МСК016 | AG19: ВВГнг(А)-LS | AH19: 5 | AI19: 2.5 | AJ19: 2
P20: LED | Q20: Группа светодиодного освещения | R20: 1 | S20: 1 | T20: 3 | AE20: =AG20&" ("&AH20&"х"&AI20&") "&AJ20 -> ВВГнг(А)-LS (5х4) 1 | AF20: МСК017 | AG20: ВВГнг(А)-LS | AH20: 5 | AI20: 4 | AJ20: 1
P21: АПС | Q21: Реле АПС | R21: 1 | S21: 1 | T21: 1 | AE21: =AG21&" ("&AH21&"х"&AI21&") "&AJ21 -> ВВГнг(А)-LS (5х4) 2 | AF21: МСК018 | AG21: ВВГнг(А)-LS | AH21: 5 | AI21: 4 | AJ21: 2
P22: K | Q22: Внутренний блок кондиционера | R22: 1 | S22: 1 | T22: 1 | AE22: =AG22&" ("&AH22&"х"&AI22&") "&AJ22 -> ВВГнг(А)-LS (5х6) 1 | AF22: МСК019 | AG22: ВВГнг(А)-LS | AH22: 5 | AI22: 6 | AJ22: 1
P23: ПВ | Q23: Приточно-вытяжная установка | R23: 1 | S23: 1 | T23: 1 | AE23: =AG23&" ("&AH23&"х"&AI23&") "&AJ23 -> ВВГнг(А)-LS (5х6) 2 | AF23: МСК020 | AG23: ВВГнг(А)-LS | AH23: 5 | AI23: 6 | AJ23: 2
P24: УВ | Q24: Увлажнитель | R24: 1 | S24: 1 | T24: 1 | AE24: =AG24&" ("&AH24&"х"&AI24&") "&AJ24 -> ВВГнг(А)-LS (5х10) 1 | AF24: МСК021 | AG24: ВВГнг(А)-LS | AH24: 5 | AI24: 10 | AJ24: 1
P25: ПН | Q25: Проточный водонагреватель | R25: 1 | S25: 1 | T25: 1 | AE25: =AG25&" ("&AH25&"х"&AI25&") "&AJ25 -> ВВГнг(А)-LS (5х10) 2 | AF25: МСК022 | AG25: ВВГнг(А)-LS | AH25: 5 | AI25: 10 | AJ25: 2
P26: WD | Q26: Датчик протечки | R26: 0 | S26: 1 | T26: 1 | AE26: =AG26&" ("&AH26&"х"&AI26&") "&AJ26 -> ВВГнг(А)-LS (5х16) 1 | AF26: МСК023 | AG26: ВВГнг(А)-LS | AH26: 5 | AI26: 16 | AJ26: 1
P27: VK | Q27: Выключатель нажимной | R27: 0 | S27: 1 | T27: 1 | AE27: =AG27&" ("&AH27&"х"&AI27&") "&AJ27 -> ВВГнг(А)-LS (5х16) 2 | AF27: МСК024 | AG27: ВВГнг(А)-LS | AH27: 5 | AI27: 16 | AJ27: 2
P28: КУП | Q28: Коробка уравнивания потенциалов | R28: 1 | S28: 1 | T28: 1 | AE28: =AG28&" ("&AH28&"х"&AI28&") "&AJ28 -> ВВГнг(А)-LS (5х25) 1 | AF28: МСК025 | AG28: ВВГнг(А)-LS | AH28: 5 | AI28: 25 | AJ28: 1
P29: PE | Q29: Заземляющая шина | R29: 1 | S29: 1 | T29: 1 | AE29: =AG29&" ("&AH29&"х"&AI29&") "&AJ29 -> ВВГнг(А)-LS (5х25) 2 | AF29: МСК026 | AG29: ВВГнг(А)-LS | AH29: 5 | AI29: 25 | AJ29: 2
P30: R.GSM | Q30: Щит усиления соловой связи | R30: 1 | S30: 1 | T30: 1 | AE30: =AG30&" ("&AH30&"х"&AI30&") "&AJ30 -> ВВГнг(А)-LS (5х35) 1 | AF30: МСК027 | AG30: ВВГнг(А)-LS | AH30: 5 | AI30: 35 | AJ30: 1
P31: TE-ТП | Q31: Управление сервоприводом теплого пола | R31: 1 | S31: 1 | T31: 1 | AE31: =AG31&" ("&AH31&"х"&AI31&") "&AJ31 -> ВВГнг(А)-LS (5х35) 2 | AF31: МСК028 | AG31: ВВГнг(А)-LS | AH31: 5 | AI31: 35 | AJ31: 2
... P34: КМН | Q34: Электрокамин | R34: 1 | S34: 1 | T34: 1 | AE34: =AG34&" ("&AH34&"х"&AI34&") "&AJ34 -> ВВГнг(А)-LS (5х95) 1 | AF34: МСК031 | AG34: ВВГнг(А)-LS | AH34: 5 | AI34: 95 | AJ34: 1
AE35: =AG35&" ("&AH35&"х"&AI35&") "&AJ35 -> ВВГнг(А)-LS (5х95) 2 | AF35: МСК032 | AG35: ВВГнг(А)-LS | AH35: 5 | AI35: 95 | AJ35: 2
AE36: =AG36&" ("&AH36&"х"&AI36&") "&AJ36 -> ВВГнг(А)-LS (5х120) 1 | AF36: МСК033 | AG36: ВВГнг(А)-LS | AH36: 5 | AI36: 120 | AJ36: 1
AE37: =AG37&" ("&AH37&"х"&AI37&") "&AJ37 -> ВВГнг(А)-LS (5х120) 2 | AF37: МСК034 | AG37: ВВГнг(А)-LS | AH37: 5 | AI37: 120 | AJ37: 2
AE38: =AG38&" ("&AH38&"х"&AI38&") "&AJ38 -> ВВГнг(А)-LS (5х95) 1 | AF38: МСК035 | AG38: ВВГнг(А)-LS | AH38: 5 | AI38: 95 | AJ38: 1
AE39: =AG39&" ("&AH39&"х"&AI39&") "&AJ39 -> ВВГнг(А)-LS (5х95) 2 | AF39: МСК036 | AG39: ВВГнг(А)-LS | AH39: 5 | AI39: 95 | AJ39: 2
AE40: =AG40&" ("&AH40&"х"&AI40&") "&AJ40 -> ВВГнг(А)-LS (5х120) 1 | AF40: МСК037 | AG40: ВВГнг(А)-LS | AH40: 5 | AI40: 120 | AJ40: 1
AE41: =AG41&" ("&AH41&"х"&AI41&") "&AJ41 -> ВВГнг(А)-LS (5х120) 2 | AF41: МСК038 | AG41: ВВГнг(А)-LS | AH41: 5 | AI41: 120 | AJ41: 2
AE42: =AG42&" ("&AH42&"х"&AI42&") "&AJ42 -> ВБШВнг(А)-LS (5х10) 1 | AF42: МСК040 | AG42: ВБШВнг(А)-LS | AH42: 5 | AI42: 10 | AJ42: 1
AE43: =AG43&" ("&AH43&"х"&AI43&") "&AJ43 -> ВБШВнг(А)-LS (5х10) 2 | AF43: МСК041 | AG43: ВБШВнг(А)-LS | AH43: 5 | AI43: 10 | AJ43: 2
...

Sheet Исходные данные
A1: 1 | B1: 2 | C1: 3 | D1: 4 | E1: 5 | F1: 6 | G1: 7 | H1: 8 | I1: 9 | J1: 10 | K1: 11 | L1: 12 | M1: 13 | N1: 14 | O1: 15 | P1: 16 | Q1: 17 | R1: 18 | S1: 19 | T1: 20 | U1: 21 | V1: 22 | W1: 23 | X1: 24 | Y1: 25 | Z1: 26 | AA1: 27 | AB1: 28 | AC1: 29 | AD1: 30 | AE1: 31 | AF1: 32 | AG1: 33 | AH1: 34 | AI1: 35 | AJ1: 36 | AK1: 37 | AL1: 38 | AM1: 39 | AN1: 40 | AO1: 41 | AP1: 42 | AQ1: 43 | AR1: 44 | AS1: 45 | AT1: 46
B2: Наименование | C2: Наименование (ручное) | D2: Номер линии | E2: Мощность, кВт | F2: Напряжение | G2: Кол-во потребителей (для длины) | H2: Кол-во фаз | I2: Длина линии (по плану) | J2: Лоток | K2: Гофра ПВХ | L2: Гофра ПНД | M2: Длина линии (Итог) | N2: Марку кабеля | O2: Кол-во жил | P2: Косинус | Q2: Сечение (ручное) | R2: автомат (ручное) | S2: Потолок - 1/Пол - 2 | T2: Ток | U2: Автомат | V2: Сечение | W2: Активное сопротивление | X2: Индуктивное сопротивление | Y2: Коэффициент фазности | Z2: Синус | AA2: Потери, В | AB2: Потери, % | AC2: Уровень напряжения | AD2: Кабель | AE2: Кабель проиежуточный | AF2: Для потерь | AG2: Помещение | AH2: Потребитель | AI2: Этаж/Шлейф | AJ2: Наименование | AK2: ток | AL2: мощность | AM2: номер линии | AN2: УГО (заполняется в двг!) | AO2: Кабель | AP2: Для наименования | AQ2: Для наименования | AR2: Iпуск 1 | AS2: Iпуск 2 | AT2: Iпуск | AU2: DWG: гофра ПВХ по плану, м | AV2: DWG: гофра ПНД по плану, м | AW2: DWG: хэндлы полилиний | AX2: DWG: примечание
A3: =D3 -> 0 | B3: =IFERROR(IF(VLOOKUP(AH3,Потребители_обозначение,4,FALSE)=1,VLOOKUP(AH3,Потребители_обозначение,2,FALSE)&" "&VLOOKUP(AI3,Этаж_обозначение,2,FALSE)&" Пом. №"&AG3,VLOOKUP(AH3,Потребители_обозначение,2,FALSE)&" Шлейф №"&AI3),VLOOKUP(D3,Потребители_обозначение,2,FALSE)) -> #N/A | D3: R.1.01.1 | G3: 1 | I3: =IF(COUNT(AU3:AV3)=0,"",ROUNDUP(SUM(AU3:AV3),0)) | K3: =IF(OR(I3="",S3=""),"",IF(S3=1,MAX(0,M3-ROUNDUP(N(AV3),0)-4),ROUNDUP(N(AU3),0))) | L3: =IF(OR(I3="",S3=""),"",IF(S3=2,MAX(0,M3-ROUNDUP(N(AU3),0)-4),ROUNDUP(N(AV3),0))) | M3: =IFERROR(IF(VLOOKUP(AH3,Потребители_обозначение,4,FALSE)=1,VLOOKUP(AH3,Потребители_обозначение,3,FALSE)*(G3*2-1)+I3+VLOOKUP(AI3,Этаж_обозначение,3,FALSE)+VLOOKUP(AI3,Этаж_обозначение,4,FALSE),VLOOKUP(AH3,Потребители_обозначение,3,FALSE)*(G3*2-1)+I3),I3) -> 0 | P3: =IF(VLOOKUP(AH3,Потребители_обозначение,5,FALSE)=2,_xlfn.IFS(H3=3,VLOOKUP(E3,Справочная_двигатели,8,FALSE),H3=1,VLOOKUP(E3,Справочная_двигатели,10,TRUE)),0.95) -> #N/A | S3: 2 | T3: =_xlfn.IFS(H3=1,E3*1000/220,H3=3,E3/0.38/1.732) -> #N/A | U3: =IF(R3=0,VLOOKUP(T3,Автомат_номиналы,2,TRUE),R3) -> #N/A | V3: =IF(VLOOKUP(N3,Кабель_обозначение,3,FALSE)=1,IF(Q3=0,VLOOKUP(U3,Кабель_номиналы,2,TRUE),Q3),0) -> #N/A | W3: =VLOOKUP(V3,Кабель_сопротивление,3,FALSE) -> #N/A | X3: =VLOOKUP(V3,Кабель_сопротивление,2,FALSE) -> #N/A | Y3: {=_xlfn.IFS(H3=1,2,H3=3,1)} -> #N/A | Z3: =ROUND(SIN(ACOS(P3)),2) -> #N/A | AA3: =Y3*(W3*I3/V3+X3*I3*Z3/1000)*T3 -> #N/A | AB3: =ROUNDUP(AA3/220*100,2) -> #N/A | AC3: =_xlfn.IFS(H3=3,380,H3=1,220) -> #N/A | AD3: =VLOOKUP(N3,Кабель_обозначение,2,FALSE) -> #N/A | AE3: =IF(VLOOKUP(N3,Кабель_обозначение,3,FALSE)=1,AD3&" ("&O3&"х"&V3&")",AD3) -> #N/A | AF3: =IFERROR(IF(AB3>4.5,1,2),0) -> 0 | AG3: =IFERROR(LEFT(AQ3,SEARCH(".",AQ3)-1),AQ3) | AH3: =IFERROR(LEFT(A3,SEARCH(".",A3)-1),A3) -> 0 | AI3: =IFERROR(LEFT(AP3,SEARCH(".",AP3)-1),AP3) -> #VALUE! | AJ3: =IF(C3=0,B3,C3) -> #N/A | AK3: =ROUNDUP(T3,2) -> #N/A | AL3: =E3 -> 0 | AM3: =D3 -> 0 | AO3: =IF(V3=0,AD3,AE3&" L="&M3&"-"&AB3&"%") -> #N/A | AP3: =RIGHT(A3,LEN(A3)-SEARCH(".",A3)) -> #VALUE! | AQ3: =IFERROR(RIGHT(AP3,LEN(AP3)-SEARCH(".",AP3)),"") | AR3: =IFERROR(IF(VLOOKUP(AH3,Потребители_обозначение,5,FALSE)=2,_xlfn.IFS(H3=3,VLOOKUP(E3,Справочная_двигатели,3,FALSE),H3=1,VLOOKUP(E3,Справочная_двигатели,5,TRUE)),0),0) -> 0 | AS3: =IFERROR(IF(VLOOKUP(AH3,Потребители_обозначение,5,FALSE)=3,VLOOKUP(E3,Справочная_ЛЭД,2,TRUE),0),0) -> 0 | AT3: =IF(AR3=0,AS3,AR3) -> 0 | AV3: 7.29 | AW3: 830AB6
A4: =D4 -> Ввод.1 | B4: =IFERROR(IF(VLOOKUP(AH4,Потребители_обозначение,4,FALSE)=1,VLOOKUP(AH4,Потребители_обозначение,2,FALSE)&" "&VLOOKUP(AI4,Этаж_обозначение,2,FALSE)&" Пом. №"&AG4,VLOOKUP(AH4,Потребители_обозначение,2,FALSE)&" Шлейф №"&AI4),VLOOKUP(D4,Потребители_обозначение,2,FALSE)) -> Ввод питающей линии Пом. № | D4: R.1.02.1 | G4: 1 | I4: =IF(COUNT(AU4:AV4)=0,"",ROUNDUP(SUM(AU4:AV4),0)) | K4: =IF(OR(I4="",S4=""),"",IF(S4=1,MAX(0,M4-ROUNDUP(N(AV4),0)-4),ROUNDUP(N(AU4),0))) | L4: =IF(OR(I4="",S4=""),"",IF(S4=2,MAX(0,M4-ROUNDUP(N(AU4),0)-4),ROUNDUP(N(AV4),0))) | M4: =IFERROR(IF(VLOOKUP(AH4,Потребители_обозначение,4,FALSE)=1,VLOOKUP(AH4,Потребители_обозначение,3,FALSE)*(G4*2-1)+I4+VLOOKUP(AI4,Этаж_обозначение,3,FALSE)+VLOOKUP(AI4,Этаж_обозначение,4,FALSE),VLOOKUP(AH4,Потребители_обозначение,3,FALSE)*(G4*2-1)+I4),I4) -> 19 | P4: =IF(VLOOKUP(AH4,Потребители_обозначение,5,FALSE)=2,_xlfn.IFS(H4=3,VLOOKUP(E4,Справочная_двигатели,8,FALSE),H4=1,VLOOKUP(E4,Справочная_двигатели,10,TRUE)),0.95) -> 0.95 | S4: 2 | T4: =_xlfn.IFS(H4=1,E4*1000/220,H4=3,E4/0.38/1.732) -> 128.25605 | U4: =IF(R4=0,VLOOKUP(T4,Автомат_номиналы,2,TRUE),R4) -> 63 | V4: =IF(VLOOKUP(N4,Кабель_обозначение,3,FALSE)=1,IF(Q4=0,VLOOKUP(U4,Кабель_номиналы,2,TRUE),Q4),0) -> 16 | W4: =VLOOKUP(V4,Кабель_сопротивление,3,FALSE) -> 0.0175 | X4: =VLOOKUP(V4,Кабель_сопротивление,2,FALSE) -> 0.0675 | Y4: {=_xlfn.IFS(H4=1,2,H4=3,1)} -> 1 | Z4: =ROUND(SIN(ACOS(P4)),2) -> 0.31 | AA4: =Y4*(W4*I4/V4+X4*I4*Z4/1000)*T4 -> 2.0014933 | AB4: =ROUNDUP(AA4/220*100,2) -> 0.91 | AC4: =_xlfn.IFS(H4=3,380,H4=1,220) -> 380 | AD4: =VLOOKUP(N4,Кабель_обозначение,2,FALSE) -> ВВГнг(А)-LS | AE4: =IF(VLOOKUP(N4,Кабель_обозначение,3,FALSE)=1,AD4&" ("&O4&"х"&V4&")",AD4) -> ВВГнг(А)-LS (5х16) | AF4: =IFERROR(IF(AB4>4.5,1,2),0) -> 2 | AG4: =IFERROR(LEFT(AQ4,SEARCH(".",AQ4)-1),AQ4) | AH4: =IFERROR(LEFT(A4,SEARCH(".",A4)-1),A4) -> Ввод | AI4: =IFERROR(LEFT(AP4,SEARCH(".",AP4)-1),AP4) -> 1 | AJ4: =IF(C4=0,B4,C4) -> Основной ввод | AK4: =ROUNDUP(T4,2) -> 128.26 | AL4: =E4 -> 84.413 | AM4: =D4 -> Ввод.1 | AO4: =IF(V4=0,AD4,AE4&" L="&M4&"-"&AB4&"%") -> ВВГнг(А)-LS (5х16) L=19-0,91% | AP4: =RIGHT(A4,LEN(A4)-SEARCH(".",A4)) -> 1 | AQ4: =IFERROR(RIGHT(AP4,LEN(AP4)-SEARCH(".",AP4)),"") | AR4: =IFERROR(IF(VLOOKUP(AH4,Потребители_обозначение,5,FALSE)=2,_xlfn.IFS(H4=3,VLOOKUP(E4,Справочная_двигатели,3,FALSE),H4=1,VLOOKUP(E4,Справочная_двигатели,5,TRUE)),0),0) -> 0 | AS4: =IFERROR(IF(VLOOKUP(AH4,Потребители_обозначение,5,FALSE)=3,VLOOKUP(E4,Справочная_ЛЭД,2,TRUE),0),0) -> 0 | AT4: =IF(AR4=0,AS4,AR4) -> 0 | AV4: 4.86 | AW4: 83114A
A5: =D5 -> 0 | B5: =IFERROR(IF(VLOOKUP(AH5,Потребители_обозначение,4,FALSE)=1,VLOOKUP(AH5,Потребители_обозначение,2,FALSE)&" "&VLOOKUP(AI5,Этаж_обозначение,2,FALSE)&" Пом. №"&AG5,VLOOKUP(AH5,Потребители_обозначение,2,FALSE)&" Шлейф №"&AI5),VLOOKUP(D5,Потребители_обозначение,2,FALSE)) -> #N/A | D5: R.1.03.1 | G5: 1 | I5: =IF(COUNT(AU5:AV5)=0,"",ROUNDUP(SUM(AU5:AV5),0)) | K5: =IF(OR(I5="",S5=""),"",IF(S5=1,MAX(0,M5-ROUNDUP(N(AV5),0)-4),ROUNDUP(N(AU5),0))) | L5: =IF(OR(I5="",S5=""),"",IF(S5=2,MAX(0,M5-ROUNDUP(N(AU5),0)-4),ROUNDUP(N(AV5),0))) | M5: =IFERROR(IF(VLOOKUP(AH5,Потребители_обозначение,4,FALSE)=1,VLOOKUP(AH5,Потребители_обозначение,3,FALSE)*(G5*2-1)+I5+VLOOKUP(AI5,Этаж_обозначение,3,FALSE)+VLOOKUP(AI5,Этаж_обозначение,4,FALSE),VLOOKUP(AH5,Потребители_обозначение,3,FALSE)*(G5*2-1)+I5),I5) -> 0 | P5: =IF(VLOOKUP(AH5,Потребители_обозначение,5,FALSE)=2,_xlfn.IFS(H5=3,VLOOKUP(E5,Справочная_двигатели,8,FALSE),H5=1,VLOOKUP(E5,Справочная_двигатели,10,TRUE)),0.95) -> #N/A | S5: 2 | T5: =_xlfn.IFS(H5=1,E5*1000/220,H5=3,E5/0.38/1.732) -> #N/A | U5: =IF(R5=0,VLOOKUP(T5,Автомат_номиналы,2,TRUE),R5) -> #N/A | V5: =IF(VLOOKUP(N5,Кабель_обозначение,3,FALSE)=1,IF(Q5=0,VLOOKUP(U5,Кабель_номиналы,2,TRUE),Q5),0) -> #N/A | W5: =VLOOKUP(V5,Кабель_сопротивление,3,FALSE) -> #N/A | X5: =VLOOKUP(V5,Кабель_сопротивление,2,FALSE) -> #N/A | Y5: {=_xlfn.IFS(H5=1,2,H5=3,1)} -> #N/A | Z5: =ROUND(SIN(ACOS(P5)),2) -> #N/A | AA5: =Y5*(W5*I5/V5+X5*I5*Z5/1000)*T5 -> #N/A | AB5: =ROUNDUP(AA5/220*100,2) -> #N/A | AC5: =_xlfn.IFS(H5=3,380,H5=1,220) -> #N/A | AD5: =VLOOKUP(N5,Кабель_обозначение,2,FALSE) -> #N/A | AE5: =IF(VLOOKUP(N5,Кабель_обозначение,3,FALSE)=1,AD5&" ("&O5&"х"&V5&")",AD5) -> #N/A | AF5: =IFERROR(IF(AB5>4.5,1,2),0) -> 0 | AG5: =IFERROR(LEFT(AQ5,SEARCH(".",AQ5)-1),AQ5) | AH5: =IFERROR(LEFT(A5,SEARCH(".",A5)-1),A5) -> 0 | AI5: =IFERROR(LEFT(AP5,SEARCH(".",AP5)-1),AP5) -> #VALUE! | AJ5: =IF(C5=0,B5,C5) -> #N/A | AK5: =ROUNDUP(T5,2) -> #N/A | AL5: =E5 -> 0 | AM5: =D5 -> 0 | AO5: =IF(V5=0,AD5,AE5&" L="&M5&"-"&AB5&"%") -> #N/A | AP5: =RIGHT(A5,LEN(A5)-SEARCH(".",A5)) -> #VALUE! | AQ5: =IFERROR(RIGHT(AP5,LEN(AP5)-SEARCH(".",AP5)),"") | AR5: =IFERROR(IF(VLOOKUP(AH5,Потребители_обозначение,5,FALSE)=2,_xlfn.IFS(H5=3,VLOOKUP(E5,Справочная_двигатели,3,FALSE),H5=1,VLOOKUP(E5,Справочная_двигатели,5,TRUE)),0),0) -> 0 | AS5: =IFERROR(IF(VLOOKUP(AH5,Потребители_обозначение,5,FALSE)=3,VLOOKUP(E5,Справочная_ЛЭД,2,TRUE),0),0) -> 0 | AT5: =IF(AR5=0,AS5,AR5) -> 0 | AV5: 9.34 | AW5: 830D8A
A6: =D6 -> Ввод.2 | B6: =IFERROR(IF(VLOOKUP(AH6,Потребители_обозначение,4,FALSE)=1,VLOOKUP(AH6,Потребители_обозначение,2,FALSE)&" "&VLOOKUP(AI6,Этаж_обозначение,2,FALSE)&" Пом. №"&AG6,VLOOKUP(AH6,Потребители_обозначение,2,FALSE)&" Шлейф №"&AI6),VLOOKUP(D6,Потребители_обозначение,2,FALSE)) -> Ввод питающей линии Второй этаж Пом. № | D6: R.1.03.2 | G6: 1 | I6: =IF(COUNT(AU6:AV6)=0,"",ROUNDUP(SUM(AU6:AV6),0)) | K6: =IF(OR(I6="",S6=""),"",IF(S6=1,MAX(0,M6-ROUNDUP(N(AV6),0)-4),ROUNDUP(N(AU6),0))) | L6: =IF(OR(I6="",S6=""),"",IF(S6=2,MAX(0,M6-ROUNDUP(N(AU6),0)-4),ROUNDUP(N(AV6),0))) | M6: =IFERROR(IF(VLOOKUP(AH6,Потребители_обозначение,4,FALSE)=1,VLOOKUP(AH6,Потребители_обозначение,3,FALSE)*(G6*2-1)+I6+VLOOKUP(AI6,Этаж_обозначение,3,FALSE)+VLOOKUP(AI6,Этаж_обозначение,4,FALSE),VLOOKUP(AH6,Потребители_обозначение,3,FALSE)*(G6*2-1)+I6),I6) -> 18 | P6: =IF(VLOOKUP(AH6,Потребители_обозначение,5,FALSE)=2,_xlfn.IFS(H6=3,VLOOKUP(E6,Справочная_двигатели,8,FALSE),H6=1,VLOOKUP(E6,Справочная_двигатели,10,TRUE)),0.95) -> 0.95 | S6: 2 | T6: =_xlfn.IFS(H6=1,E6*1000/220,H6=3,E6/0.38/1.732) -> 0.015193874 | U6: =IF(R6=0,VLOOKUP(T6,Автомат_номиналы,2,TRUE),R6) -> 63 | V6: =IF(VLOOKUP(N6,Кабель_обозначение,3,FALSE)=1,IF(Q6=0,VLOOKUP(U6,Кабель_номиналы,2,TRUE),Q6),0) -> 10 | W6: =VLOOKUP(V6,Кабель_сопротивление,3,FALSE) -> 0.0175 | X6: =VLOOKUP(V6,Кабель_сопротивление,2,FALSE) -> 0.073 | Y6: {=_xlfn.IFS(H6=1,2,H6=3,1)} -> 1 | Z6: =ROUND(SIN(ACOS(P6)),2) -> 0.31 | AA6: =Y6*(W6*I6/V6+X6*I6*Z6/1000)*T6 -> 0.00035013052 | AB6: =ROUNDUP(AA6/220*100,2) -> 0.01 | AC6: =_xlfn.IFS(H6=3,380,H6=1,220) -> 380 | AD6: =VLOOKUP(N6,Кабель_обозначение,2,FALSE) -> ВВГнг(А)-LS | AE6: =IF(VLOOKUP(N6,Кабель_обозначение,3,FALSE)=1,AD6&" ("&O6&"х"&V6&")",AD6) -> ВВГнг(А)-LS (5х10) | AF6: =IFERROR(IF(AB6>4.5,1,2),0) -> 2 | AG6: =IFERROR(LEFT(AQ6,SEARCH(".",AQ6)-1),AQ6) | AH6: =IFERROR(LEFT(A6,SEARCH(".",A6)-1),A6) -> Ввод | AI6: =IFERROR(LEFT(AP6,SEARCH(".",AP6)-1),AP6) -> 2 | AJ6: =IF(C6=0,B6,C6) -> Дополнительный ввод | AK6: =ROUNDUP(T6,2) -> 0.02 | AL6: =E6 -> 0.01 | AM6: =D6 -> Ввод.2 | AO6: =IF(V6=0,AD6,AE6&" L="&M6&"-"&AB6&"%") -> ВВГнг(А)-LS (5х10) L=18-0,01% | AP6: =RIGHT(A6,LEN(A6)-SEARCH(".",A6)) -> 2 | AQ6: =IFERROR(RIGHT(AP6,LEN(AP6)-SEARCH(".",AP6)),"") | AR6: =IFERROR(IF(VLOOKUP(AH6,Потребители_обозначение,5,FALSE)=2,_xlfn.IFS(H6=3,VLOOKUP(E6,Справочная_двигатели,3,FALSE),H6=1,VLOOKUP(E6,Справочная_двигатели,5,TRUE)),0),0) -> 0 | AS6: =IFERROR(IF(VLOOKUP(AH6,Потребители_обозначение,5,FALSE)=3,VLOOKUP(E6,Справочная_ЛЭД,2,TRUE),0),0) -> 0 | AT6: =IF(AR6=0,AS6,AR6) -> 0 | AV6: 11.89 | AW6: 830D89
A7: =D7 -> 0 | B7: =IFERROR(IF(VLOOKUP(AH7,Потребители_обозначение,4,FALSE)=1,VLOOKUP(AH7,Потребители_обозначение,2,FALSE)&" "&VLOOKUP(AI7,Этаж_обозначение,2,FALSE)&" Пом. №"&AG7,VLOOKUP(AH7,Потребители_обозначение,2,FALSE)&" Шлейф №"&AI7),VLOOKUP(D7,Потребители_обозначение,2,FALSE)) -> #N/A | D7: R.1.03.3 | G7: 1 | I7: =IF(COUNT(AU7:AV7)=0,"",ROUNDUP(SUM(AU7:AV7),0)) | K7: =IF(OR(I7="",S7=""),"",IF(S7=1,MAX(0,M7-ROUNDUP(N(AV7),0)-4),ROUNDUP(N(AU7),0))) | L7: =IF(OR(I7="",S7=""),"",IF(S7=2,MAX(0,M7-ROUNDUP(N(AU7),0)-4),ROUNDUP(N(AV7),0))) | M7: =IFERROR(IF(VLOOKUP(AH7,Потребители_обозначение,4,FALSE)=1,VLOOKUP(AH7,Потребители_обозначение,3,FALSE)*(G7*2-1)+I7+VLOOKUP(AI7,Этаж_обозначение,3,FALSE)+VLOOKUP(AI7,Этаж_обозначение,4,FALSE),VLOOKUP(AH7,Потребители_обозначение,3,FALSE)*(G7*2-1)+I7),I7) -> 0 | P7: =IF(VLOOKUP(AH7,Потребители_обозначение,5,FALSE)=2,_xlfn.IFS(H7=3,VLOOKUP(E7,Справочная_двигатели,8,FALSE),H7=1,VLOOKUP(E7,Справочная_двигатели,10,TRUE)),0.95) -> #N/A | S7: 2 | T7: =_xlfn.IFS(H7=1,E7*1000/220,H7=3,E7/0.38/1.732) -> #N/A | U7: =IF(R7=0,VLOOKUP(T7,Автомат_номиналы,2,TRUE),R7) -> #N/A | V7: =IF(Q7=0,VLOOKUP(U7,Кабель_номиналы,2,TRUE),Q7) -> #N/A | W7: =VLOOKUP(V7,Кабель_сопротивление,3,FALSE) -> #N/A | X7: =VLOOKUP(V7,Кабель_сопротивление,2,FALSE) -> #N/A | Y7: {=_xlfn.IFS(H7=1,2,H7=3,1)} -> #N/A | Z7: =ROUND(SIN(ACOS(P7)),2) -> #N/A | AA7: =Y7*(W7*I7/V7+X7*I7*Z7/1000)*T7 -> #N/A | AB7: =ROUNDUP(AA7/220*100,2) -> #N/A | AC7: =_xlfn.IFS(H7=3,380,H7=1,220) -> #N/A | AD7: =VLOOKUP(N7,Кабель_обозначение,2,FALSE) -> #N/A | AE7: =IF(VLOOKUP(N7,Кабель_обозначение,3,FALSE)=1,AD7&" ("&O7&"х"&V7&")",AD7) -> #N/A | AF7: =IFERROR(IF(AB7>4.5,1,2),0) -> 0 | AG7: =IFERROR(LEFT(AQ7,SEARCH(".",AQ7)-1),AQ7) | AH7: =IFERROR(LEFT(A7,SEARCH(".",A7)-1),A7) -> 0 | AI7: =IFERROR(LEFT(AP7,SEARCH(".",AP7)-1),AP7) -> #VALUE! | AJ7: =IF(C7=0,B7,C7) -> #N/A | AK7: =ROUNDUP(T7,2) -> #N/A | AL7: =E7 -> 0 | AM7: =D7 -> 0 | AO7: =IF(V7=0,AD7,AE7&" L="&M7&"-"&AB7&"%") -> #N/A | AP7: =RIGHT(A7,LEN(A7)-SEARCH(".",A7)) -> #VALUE! | AQ7: =IFERROR(RIGHT(AP7,LEN(AP7)-SEARCH(".",AP7)),"") | AR7: =IFERROR(IF(VLOOKUP(AH7,Потребители_обозначение,5,FALSE)=2,_xlfn.IFS(H7=3,VLOOKUP(E7,Справочная_двигатели,3,FALSE),H7=1,VLOOKUP(E7,Справочная_двигатели,5,TRUE)),0),0) -> 0 | AS7: =IFERROR(IF(VLOOKUP(AH7,Потребители_обозначение,5,FALSE)=3,VLOOKUP(E7,Справочная_ЛЭД,2,TRUE),0),0) -> 0 | AT7: =IF(AR7=0,AS7,AR7) -> 0 | AV7: 12.11 | AW7: 830D86
A8: =D8 -> Ввод.3 | B8: =IFERROR(IF(VLOOKUP(AH8,Потребители_обозначение,4,FALSE)=1,VLOOKUP(AH8,Потребители_обозначение,2,FALSE)&" "&VLOOKUP(AI8,Этаж_обозначение,2,FALSE)&" Пом. №"&AG8,VLOOKUP(AH8,Потребители_обозначение,2,FALSE)&" Шлейф №"&AI8),VLOOKUP(D8,Потребители_обозначение,2,FALSE)) -> Ввод питающей линии Третий этаж Пом. № | D8: R.1.03.4 | G8: 1 | I8: =IF(COUNT(AU8:AV8)=0,"",ROUNDUP(SUM(AU8:AV8),0)) | K8: =IF(OR(I8="",S8=""),"",IF(S8=1,MAX(0,M8-ROUNDUP(N(AV8),0)-4),ROUNDUP(N(AU8),0))) | L8: =IF(OR(I8="",S8=""),"",IF(S8=2,MAX(0,M8-ROUNDUP(N(AU8),0)-4),ROUNDUP(N(AV8),0))) | M8: =IFERROR(IF(VLOOKUP(AH8,Потребители_обозначение,4,FALSE)=1,VLOOKUP(AH8,Потребители_обозначение,3,FALSE)*(G8*2-1)+I8+VLOOKUP(AI8,Этаж_обозначение,3,FALSE)+VLOOKUP(AI8,Этаж_обозначение,4,FALSE),VLOOKUP(AH8,Потребители_обозначение,3,FALSE)*(G8*2-1)+I8),I8) -> 29 | P8: =IF(VLOOKUP(AH8,Потребители_обозначение,5,FALSE)=2,_xlfn.IFS(H8=3,VLOOKUP(E8,Справочная_двигатели,8,FALSE),H8=1,VLOOKUP(E8,Справочная_двигатели,10,TRUE)),0.95) -> 0.95 | S8: 2 | T8: =_xlfn.IFS(H8=1,E8*1000/220,H8=3,E8/0.38/1.732) -> 0.015193874 | U8: =IF(R8=0,VLOOKUP(T8,Автомат_номиналы,2,TRUE),R8) -> 63 | V8: =IF(Q8=0,VLOOKUP(U8,Кабель_номиналы,2,TRUE),Q8) -> 10 | W8: =VLOOKUP(V8,Кабель_сопротивление,3,FALSE) -> 0.0175 | X8: =VLOOKUP(V8,Кабель_сопротивление,2,FALSE) -> 0.073 | Y8: {=_xlfn.IFS(H8=1,2,H8=3,1)} -> 1 | Z8: =ROUND(SIN(ACOS(P8)),2) -> 0.31 | AA8: =Y8*(W8*I8/V8+X8*I8*Z8/1000)*T8 -> 0.0006463948 | AB8: =ROUNDUP(AA8/220*100,2) -> 0.01 | AC8: =_xlfn.IFS(H8=3,380,H8=1,220) -> 380 | AD8: =VLOOKUP(N8,Кабель_обозначение,2,FALSE) -> ВВГнг(А)-LS | AE8: =IF(VLOOKUP(N8,Кабель_обозначение,3,FALSE)=1,AD8&" ("&O8&"х"&V8&")",AD8) -> ВВГнг(А)-LS (5х10) | AF8: =IFERROR(IF(AB8>4.5,1,2),0) -> 2 | AG8: =IFERROR(LEFT(AQ8,SEARCH(".",AQ8)-1),AQ8) | AH8: =IFERROR(LEFT(A8,SEARCH(".",A8)-1),A8) -> Ввод | AI8: =IFERROR(LEFT(AP8,SEARCH(".",AP8)-1),AP8) -> 3 | AJ8: =IF(C8=0,B8,C8) -> Дополнительный ввод | AK8: =ROUNDUP(T8,2) -> 0.02 | AL8: =E8 -> 0.01 | AM8: =D8 -> Ввод.3 | AO8: =IF(V8=0,AD8,AE8&" L="&M8&"-"&AB8&"%") -> ВВГнг(А)-LS (5х10) L=29-0,01% | AP8: =RIGHT(A8,LEN(A8)-SEARCH(".",A8)) -> 3 | AQ8: =IFERROR(RIGHT(AP8,LEN(AP8)-SEARCH(".",AP8)),"") | AR8: =IFERROR(IF(VLOOKUP(AH8,Потребители_обозначение,5,FALSE)=2,_xlfn.IFS(H8=3,VLOOKUP(E8,Справочная_двигатели,3,FALSE),H8=1,VLOOKUP(E8,Справочная_двигатели,5,TRUE)),0),0) -> 0 | AS8: =IFERROR(IF(VLOOKUP(AH8,Потребители_обозначение,5,FALSE)=3,VLOOKUP(E8,Справочная_ЛЭД,2,TRUE),0),0) -> 0 | AT8: =IF(AR8=0,AS8,AR8) -> 0 | AV8: 11.73 | AW8: 830D88
A9: =D9 -> 0 | B9: =IFERROR(IF(VLOOKUP(AH9,Потребители_обозначение,4,FALSE)=1,VLOOKUP(AH9,Потребители_обозначение,2,FALSE)&" "&VLOOKUP(AI9,Этаж_обозначение,2,FALSE)&" Пом. №"&AG9,VLOOKUP(AH9,Потребители_обозначение,2,FALSE)&" Шлейф №"&AI9),VLOOKUP(D9,Потребители_обозначение,2,FALSE)) -> #N/A | D9: R.1.05.1 | G9: 1 | I9: =IF(COUNT(AU9:AV9)=0,"",ROUNDUP(SUM(AU9:AV9),0)) | K9: =IF(OR(I9="",S9=""),"",IF(S9=1,MAX(0,M9-ROUNDUP(N(AV9),0)-4),ROUNDUP(N(AU9),0))) | L9: =IF(OR(I9="",S9=""),"",IF(S9=2,MAX(0,M9-ROUNDUP(N(AU9),0)-4),ROUNDUP(N(AV9),0))) | M9: =IFERROR(IF(VLOOKUP(AH9,Потребители_обозначение,4,FALSE)=1,VLOOKUP(AH9,Потребители_обозначение,3,FALSE)*(G9*2-1)+I9+VLOOKUP(AI9,Этаж_обозначение,3,FALSE)+VLOOKUP(AI9,Этаж_обозначение,4,FALSE),VLOOKUP(AH9,Потребители_обозначение,3,FALSE)*(G9*2-1)+I9),I9) -> 0 | P9: =IF(VLOOKUP(AH9,Потребители_обозначение,5,FALSE)=2,_xlfn.IFS(H9=3,VLOOKUP(E9,Справочная_двигатели,8,FALSE),H9=1,VLOOKUP(E9,Справочная_двигатели,10,TRUE)),0.95) -> #N/A | S9: 2 | T9: =_xlfn.IFS(H9=1,E9*1000/220,H9=3,E9/0.38/1.732) -> #N/A | U9: =IF(R9=0,VLOOKUP(T9,Автомат_номиналы,2,TRUE),R9) -> #N/A | V9: =IF(Q9=0,VLOOKUP(U9,Кабель_номиналы,2,TRUE),Q9) -> #N/A | W9: =VLOOKUP(V9,Кабель_сопротивление,3,FALSE) -> #N/A | X9: =VLOOKUP(V9,Кабель_сопротивление,2,FALSE) -> #N/A | Y9: {=_xlfn.IFS(H9=1,2,H9=3,1)} -> #N/A | Z9: =ROUND(SIN(ACOS(P9)),2) -> #N/A | AA9: =Y9*(W9*I9/V9+X9*I9*Z9/1000)*T9 -> #N/A | AB9: =ROUNDUP(AA9/220*100,2) -> #N/A | AC9: =_xlfn.IFS(H9=3,380,H9=1,220) -> #N/A | AD9: =VLOOKUP(N9,Кабель_обозначение,2,FALSE) -> #N/A | AE9: =IF(VLOOKUP(N9,Кабель_обозначение,3,FALSE)=1,AD9&" ("&O9&"х"&V9&")",AD9) -> #N/A | AF9: =IFERROR(IF(AB9>4.5,1,2),0) -> 0 | AG9: =IFERROR(LEFT(AQ9,SEARCH(".",AQ9)-1),AQ9) | AH9: =IFERROR(LEFT(A9,SEARCH(".",A9)-1),A9) -> 0 | AI9: =IFERROR(LEFT(AP9,SEARCH(".",AP9)-1),AP9) -> #VALUE! | AJ9: =IF(C9=0,B9,C9) -> #N/A | AK9: =ROUNDUP(T9,2) -> #N/A | AL9: =E9 -> 0 | AM9: =D9 -> 0 | AO9: =IF(V9=0,AD9,AE9&" L="&M9&"-"&AB9&"%") -> #N/A | AP9: =RIGHT(A9,LEN(A9)-SEARCH(".",A9)) -> #VALUE! | AQ9: =IFERROR(RIGHT(AP9,LEN(AP9)-SEARCH(".",AP9)),"") | AR9: =IFERROR(IF(VLOOKUP(AH9,Потребители_обозначение,5,FALSE)=2,_xlfn.IFS(H9=3,VLOOKUP(E9,Справочная_двигатели,3,FALSE),H9=1,VLOOKUP(E9,Справочная_двигатели,5,TRUE)),0),0) -> 0 | AS9: =IFERROR(IF(VLOOKUP(AH9,Потребители_обозначение,5,FALSE)=3,VLOOKUP(E9,Справочная_ЛЭД,2,TRUE),0),0) -> 0 | AT9: =IF(AR9=0,AS9,AR9) -> 0 | AV9: 20.49 | AW9: 830A6D
A10: =D10 -> KV-1 | B10: =IFERROR(IF(VLOOKUP(AH10,Потребители_обозначение,4,FALSE)=1,VLOOKUP(AH10,Потребители_обозначение,2,FALSE)&" "&VLOOKUP(AI10,Этаж_обозначение,2,FALSE)&" Пом. №"&AG10,VLOOKUP(AH10,Потребители_обозначение,2,FALSE)&" Шлейф №"&AI10),VLOOKUP(D10,Потребители_обозначение,2,FALSE)) -> #N/A | D10: R.1.05.2 | G10: 1 | I10: =IF(COUNT(AU10:AV10)=0,"",ROUNDUP(SUM(AU10:AV10),0)) | K10: =IF(OR(I10="",S10=""),"",IF(S10=1,MAX(0,M10-ROUNDUP(N(AV10),0)-4),ROUNDUP(N(AU10),0))) | L10: =IF(OR(I10="",S10=""),"",IF(S10=2,MAX(0,M10-ROUNDUP(N(AU10),0)-4),ROUNDUP(N(AV10),0))) | M10: =IFERROR(IF(VLOOKUP(AH10,Потребители_обозначение,4,FALSE)=1,VLOOKUP(AH10,Потребители_обозначение,3,FALSE)*(G10*2-1)+I10+VLOOKUP(AI10,Этаж_обозначение,3,FALSE)+VLOOKUP(AI10,Этаж_обозначение,4,FALSE),VLOOKUP(AH10,Потребители_обозначение,3,FALSE)*(G10*2-1)+I10),I10) -> 0 | P10: =IF(VLOOKUP(AH10,Потребители_обозначение,5,FALSE)=2,_xlfn.IFS(H10=3,VLOOKUP(E10,Справочная_двигатели,8,FALSE),H10=1,VLOOKUP(E10,Справочная_двигатели,10,TRUE)),0.95) -> #N/A | S10: 2 | T10: =_xlfn.IFS(H10=1,E10*1000/220,H10=3,E10/0.38/1.732) -> 0.015193874 | U10: =IF(R10=0,VLOOKUP(T10,Автомат_номиналы,2,TRUE),R10) -> 6 | V10: =IF(Q10=0,VLOOKUP(U10,Кабель_номиналы,2,TRUE),Q10) -> 2.5 | W10: =VLOOKUP(V10,Кабель_сопротивление,3,FALSE) -> 0.0175 | X10: =VLOOKUP(V10,Кабель_сопротивление,2,FALSE) -> 0.1 | Y10: {=_xlfn.IFS(H10=1,2,H10=3,1)} -> 1 | Z10: =ROUND(SIN(ACOS(P10)),2) -> #N/A | AA10: =Y10*(W10*I10/V10+X10*I10*Z10/1000)*T10 -> #N/A | AB10: =ROUNDUP(AA10/220*100,2) -> #N/A | AC10: =_xlfn.IFS(H10=3,380,H10=1,220) -> 380 | AD10: =VLOOKUP(N10,Кабель_обозначение,2,FALSE) -> #N/A | AE10: =IF(VLOOKUP(N10,Кабель_обозначение,3,FALSE)=1,AD10&" ("&O10&"х"&V10&")",AD10) -> #N/A | AF10: =IFERROR(IF(AB10>4.5,1,2),0) -> 0 | AG10: =IFERROR(LEFT(AQ10,SEARCH(".",AQ10)-1),AQ10) | AH10: =IFERROR(LEFT(A10,SEARCH(".",A10)-1),A10) -> KV-1 | AI10: =IFERROR(LEFT(AP10,SEARCH(".",AP10)-1),AP10) -> #VALUE! | AJ10: =IF(C10=0,B10,C10) -> Реле напряжения | AK10: =ROUNDUP(T10,2) -> 0.02 | AL10: =E10 -> 0.01 | AM10: =D10 -> KV-1 | AO10: =IF(V10=0,AD10,AE10&" L="&M10&"-"&AB10&"%") -> #N/A | AP10: =RIGHT(A10,LEN(A10)-SEARCH(".",A10)) -> #VALUE! | AQ10: =IFERROR(RIGHT(AP10,LEN(AP10)-SEARCH(".",AP10)),"") | AR10: =IFERROR(IF(VLOOKUP(AH10,Потребители_обозначение,5,FALSE)=2,_xlfn.IFS(H10=3,VLOOKUP(E10,Справочная_двигатели,3,FALSE),H10=1,VLOOKUP(E10,Справочная_двигатели,5,TRUE)),0),0) -> 0 | AS10: =IFERROR(IF(VLOOKUP(AH10,Потребители_обозначение,5,FALSE)=3,VLOOKUP(E10,Справочная_ЛЭД,2,TRUE),0),0) -> 0 | AT10: =IF(AR10=0,AS10,AR10) -> 0 | AV10: 19.45 | AW10: 830C24
A11: =D11 -> 0 | B11: =IFERROR(IF(VLOOKUP(AH11,Потребители_обозначение,4,FALSE)=1,VLOOKUP(AH11,Потребители_обозначение,2,FALSE)&" "&VLOOKUP(AI11,Этаж_обозначение,2,FALSE)&" Пом. №"&AG11,VLOOKUP(AH11,Потребители_обозначение,2,FALSE)&" Шлейф №"&AI11),VLOOKUP(D11,Потребители_обозначение,2,FALSE)) -> #N/A | D11: R.1.05.3 | G11: 1 | I11: =IF(COUNT(AU11:AV11)=0,"",ROUNDUP(SUM(AU11:AV11),0)) | K11: =IF(OR(I11="",S11=""),"",IF(S11=1,MAX(0,M11-ROUNDUP(N(AV11),0)-4),ROUNDUP(N(AU11),0))) | L11: =IF(OR(I11="",S11=""),"",IF(S11=2,MAX(0,M11-ROUNDUP(N(AU11),0)-4),ROUNDUP(N(AV11),0))) | M11: =IFERROR(IF(VLOOKUP(AH11,Потребители_обозначение,4,FALSE)=1,VLOOKUP(AH11,Потребители_обозначение,3,FALSE)*(G11*2-1)+I11+VLOOKUP(AI11,Этаж_обозначение,3,FALSE)+VLOOKUP(AI11,Этаж_обозначение,4,FALSE),VLOOKUP(AH11,Потребители_обозначение,3,FALSE)*(G11*2-1)+I11),I11) -> 0 | P11: =IF(VLOOKUP(AH11,Потребители_обозначение,5,FALSE)=2,_xlfn.IFS(H11=3,VLOOKUP(E11,Справочная_двигатели,8,FALSE),H11=1,VLOOKUP(E11,Справочная_двигатели,10,TRUE)),0.95) -> #N/A | S11: 2 | T11: =_xlfn.IFS(H11=1,E11*1000/220,H11=3,E11/0.38/1.732) -> #N/A | U11: =IF(R11=0,VLOOKUP(T11,Автомат_номиналы,2,TRUE),R11) -> #N/A | V11: =IF(Q11=0,VLOOKUP(U11,Кабель_номиналы,2,TRUE),Q11) -> #N/A | W11: =VLOOKUP(V11,Кабель_сопротивление,3,FALSE) -> #N/A | X11: =VLOOKUP(V11,Кабель_сопротивление,2,FALSE) -> #N/A | Y11: {=_xlfn.IFS(H11=1,2,H11=3,1)} -> #N/A | Z11: =ROUND(SIN(ACOS(P11)),2) -> #N/A | AA11: =Y11*(W11*I11/V11+X11*I11*Z11/1000)*T11 -> #N/A | AB11: =ROUNDUP(AA11/220*100,2) -> #N/A | AC11: =_xlfn.IFS(H11=3,380,H11=1,220) -> #N/A | AD11: =VLOOKUP(N11,Кабель_обозначение,2,FALSE) -> #N/A | AE11: =IF(VLOOKUP(N11,Кабель_обозначение,3,FALSE)=1,AD11&" ("&O11&"х"&V11&")",AD11) -> #N/A | AF11: =IFERROR(IF(AB11>4.5,1,2),0) -> 0 | AG11: =IFERROR(LEFT(AQ11,SEARCH(".",AQ11)-1),AQ11) | AH11: =IFERROR(LEFT(A11,SEARCH(".",A11)-1),A11) -> 0 | AI11: =IFERROR(LEFT(AP11,SEARCH(".",AP11)-1),AP11) -> #VALUE! | AJ11: =IF(C11=0,B11,C11) -> #N/A | AK11: =ROUNDUP(T11,2) -> #N/A | AL11: =E11 -> 0 | AM11: =D11 -> 0 | AO11: =IF(V11=0,AD11,AE11&" L="&M11&"-"&AB11&"%") -> #N/A | AP11: =RIGHT(A11,LEN(A11)-SEARCH(".",A11)) -> #VALUE! | AQ11: =IFERROR(RIGHT(AP11,LEN(AP11)-SEARCH(".",AP11)),"") | AR11: =IFERROR(IF(VLOOKUP(AH11,Потребители_обозначение,5,FALSE)=2,_xlfn.IFS(H11=3,VLOOKUP(E11,Справочная_двигатели,3,FALSE),H11=1,VLOOKUP(E11,Справочная_двигатели,5,TRUE)),0),0) -> 0 | AS11: =IFERROR(IF(VLOOKUP(AH11,Потребители_обозначение,5,FALSE)=3,VLOOKUP(E11,Справочная_ЛЭД,2,TRUE),0),0) -> 0 | AT11: =IF(AR11=0,AS11,AR11) -> 0 | AV11: 22.01 | AW11: 830C23
A12: =D12 -> 0 | B12: =IFERROR(IF(VLOOKUP(AH12,Потребители_обозначение,4,FALSE)=1,VLOOKUP(AH12,Потребители_обозначение,2,FALSE)&" "&VLOOKUP(AI12,Этаж_обозначение,2,FALSE)&" Пом. №"&AG12,VLOOKUP(AH12,Потребители_обозначение,2,FALSE)&" Шлейф №"&AI12),VLOOKUP(D12,Потребители_обозначение,2,FALSE)) -> #N/A | D12: R.1.05.4 | G12: 1 | I12: =IF(COUNT(AU12:AV12)=0,"",ROUNDUP(SUM(AU12:AV12),0)) | K12: =IF(OR(I12="",S12=""),"",IF(S12=1,MAX(0,M12-ROUNDUP(N(AV12),0)-4),ROUNDUP(N(AU12),0))) | L12: =IF(OR(I12="",S12=""),"",IF(S12=2,MAX(0,M12-ROUNDUP(N(AU12),0)-4),ROUNDUP(N(AV12),0))) | M12: =IFERROR(IF(VLOOKUP(AH12,Потребители_обозначение,4,FALSE)=1,VLOOKUP(AH12,Потребители_обозначение,3,FALSE)*(G12*2-1)+I12+VLOOKUP(AI12,Этаж_обозначение,3,FALSE)+VLOOKUP(AI12,Этаж_обозначение,4,FALSE),VLOOKUP(AH12,Потребители_обозначение,3,FALSE)*(G12*2-1)+I12),I12) -> 0 | P12: =IF(VLOOKUP(AH12,Потребители_обозначение,5,FALSE)=2,_xlfn.IFS(H12=3,VLOOKUP(E12,Справочная_двигатели,8,FALSE),H12=1,VLOOKUP(E12,Справочная_двигатели,10,TRUE)),0.95) -> #N/A | S12: 2 | T12: =_xlfn.IFS(H12=1,E12*1000/220,H12=3,E12/0.38/1.732) -> #N/A | U12: =IF(R12=0,VLOOKUP(T12,Автомат_номиналы,2,TRUE),R12) -> #N/A | V12: =IF(Q12=0,VLOOKUP(U12,Кабель_номиналы,2,TRUE),Q12) -> #N/A | W12: =VLOOKUP(V12,Кабель_сопротивление,3,FALSE) -> #N/A | X12: =VLOOKUP(V12,Кабель_сопротивление,2,FALSE) -> #N/A | Y12: {=_xlfn.IFS(H12=1,2,H12=3,1)} -> #N/A | Z12: =ROUND(SIN(ACOS(P12)),2) -> #N/A | AA12: =Y12*(W12*I12/V12+X12*I12*Z12/1000)*T12 -> #N/A | AB12: =ROUNDUP(AA12/220*100,2) -> #N/A | AC12: =_xlfn.IFS(H12=3,380,H12=1,220) -> #N/A | AD12: =VLOOKUP(N12,Кабель_обозначение,2,FALSE) -> #N/A | AE12: =IF(VLOOKUP(N12,Кабель_обозначение,3,FALSE)=1,AD12&" ("&O12&"х"&V12&")",AD12) -> #N/A | AF12: =IFERROR(IF(AB12>4.5,1,2),0) -> 0 | AG12: =IFERROR(LEFT(AQ12,SEARCH(".",AQ12)-1),AQ12) | AH12: =IFERROR(LEFT(A12,SEARCH(".",A12)-1),A12) -> 0 | AI12: =IFERROR(LEFT(AP12,SEARCH(".",AP12)-1),AP12) -> #VALUE! | AJ12: =IF(C12=0,B12,C12) -> #N/A | AK12: =ROUNDUP(T12,2) -> #N/A | AL12: =E12 -> 0 | AM12: =D12 -> 0 | AO12: =IF(V12=0,AD12,AE12&" L="&M12&"-"&AB12&"%") -> #N/A | AP12: =RIGHT(A12,LEN(A12)-SEARCH(".",A12)) -> #VALUE! | AQ12: =IFERROR(RIGHT(AP12,LEN(AP12)-SEARCH(".",AP12)),"") | AR12: =IFERROR(IF(VLOOKUP(AH12,Потребители_обозначение,5,FALSE)=2,_xlfn.IFS(H12=3,VLOOKUP(E12,Справочная_двигатели,3,FALSE),H12=1,VLOOKUP(E12,Справочная_двигатели,5,TRUE)),0),0) -> 0 | AS12: =IFERROR(IF(VLOOKUP(AH12,Потребители_обозначение,5,FALSE)=3,VLOOKUP(E12,Справочная_ЛЭД,2,TRUE),0),0) -> 0 | AT12: =IF(AR12=0,AS12,AR12) -> 0 | AV12: 15.22 | AW12: 830B49
A13: =D13 -> На ИБП | B13: =IFERROR(IF(VLOOKUP(AH13,Потребители_обозначение,4,FALSE)=1,VLOOKUP(AH13,Потребители_обозначение,2,FALSE)&" "&VLOOKUP(AI13,Этаж_обозначение,2,FALSE)&" Пом. №"&AG13,VLOOKUP(AH13,Потребители_обозначение,2,FALSE)&" Шлейф №"&AI13),VLOOKUP(D13,Потребители_обозначение,2,FALSE)) -> Питание на ИБП | D13: R.1.05.5 | G13: 1 | I13: =IF(COUNT(AU13:AV13)=0,"",ROUNDUP(SUM(AU13:AV13),0)) | K13: =IF(OR(I13="",S13=""),"",IF(S13=1,MAX(0,M13-ROUNDUP(N(AV13),0)-4),ROUNDUP(N(AU13),0))) | L13: =IF(OR(I13="",S13=""),"",IF(S13=2,MAX(0,M13-ROUNDUP(N(AU13),0)-4),ROUNDUP(N(AV13),0))) | M13: =IFERROR(IF(VLOOKUP(AH13,Потребители_обозначение,4,FALSE)=1,VLOOKUP(AH13,Потребители_обозначение,3,FALSE)*(G13*2-1)+I13+VLOOKUP(AI13,Этаж_обозначение,3,FALSE)+VLOOKUP(AI13,Этаж_обозначение,4,FALSE),VLOOKUP(AH13,Потребители_обозначение,3,FALSE)*(G13*2-1)+I13),I13) -> 22 | P13: =IF(VLOOKUP(AH13,Потребители_обозначение,5,FALSE)=2,_xlfn.IFS(H13=3,VLOOKUP(E13,Справочная_двигатели,8,FALSE),H13=1,VLOOKUP(E13,Справочная_двигатели,10,TRUE)),0.95) -> 0.95 | S13: 2 | T13: =_xlfn.IFS(H13=1,E13*1000/220,H13=3,E13/0.38/1.732) -> 9.0909091 | U13: =IF(R13=0,VLOOKUP(T13,Автомат_номиналы,2,TRUE),R13) -> 16 | V13: =IF(Q13=0,VLOOKUP(U13,Кабель_номиналы,2,TRUE),Q13) -> 2.5 | W13: =VLOOKUP(V13,Кабель_сопротивление,3,FALSE) -> 0.0175 | X13: =VLOOKUP(V13,Кабель_сопротивление,2,FALSE) -> 0.1 | Y13: {=_xlfn.IFS(H13=1,2,H13=3,1)} -> 2 | Z13: =ROUND(SIN(ACOS(P13)),2) -> 0.31 | AA13: =Y13*(W13*I13/V13+X13*I13*Z13/1000)*T13 -> 2.8124 | AB13: =ROUNDUP(AA13/220*100,2) -> 1.28 | AC13: =_xlfn.IFS(H13=3,380,H13=1,220) -> 220 | AD13: =VLOOKUP(N13,Кабель_обозначение,2,FALSE) -> ВВГнг(А)-LS | AE13: =IF(VLOOKUP(N13,Кабель_обозначение,3,FALSE)=1,AD13&" ("&O13&"х"&V13&")",AD13) -> ВВГнг(А)-LS (3х2,5) | AF13: =IFERROR(IF(AB13>4.5,1,2),0) -> 2 | AG13: =IFERROR(LEFT(AQ13,SEARCH(".",AQ13)-1),AQ13) | AH13: =IFERROR(LEFT(A13,SEARCH(".",A13)-1),A13) -> На ИБП | AI13: =IFERROR(LEFT(AP13,SEARCH(".",AP13)-1),AP13) -> #VALUE! | AJ13: =IF(C13=0,B13,C13) -> Питание на ИБП | AK13: =ROUNDUP(T13,2) -> 9.1 | AL13: =E13 -> 2 | AM13: =D13 -> На ИБП | AO13: =IF(V13=0,AD13,AE13&" L="&M13&"-"&AB13&"%") -> ВВГнг(А)-LS (3х2,5) L=22-1,28% | AP13: =RIGHT(A13,LEN(A13)-SEARCH(".",A13)) -> #VALUE! | AQ13: =IFERROR(RIGHT(AP13,LEN(AP13)-SEARCH(".",AP13)),"") | AR13: =IFERROR(IF(VLOOKUP(AH13,Потребители_обозначение,5,FALSE)=2,_xlfn.IFS(H13=3,VLOOKUP(E13,Справочная_двигатели,3,FALSE),H13=1,VLOOKUP(E13,Справочная_двигатели,5,TRUE)),0),0) -> 0 | AS13: =IFERROR(IF(VLOOKUP(AH13,Потребители_обозначение,5,FALSE)=3,VLOOKUP(E13,Справочная_ЛЭД,2,TRUE),0),0) -> 0 | AT13: =IF(AR13=0,AS13,AR13) -> 0 | AV13: 15.05 | AW13: 830B48
A14: =D14 -> 0 | B14: =IFERROR(IF(VLOOKUP(AH14,Потребители_обозначение,4,FALSE)=1,VLOOKUP(AH14,Потребители_обозначение,2,FALSE)&" "&VLOOKUP(AI14,Этаж_обозначение,2,FALSE)&" Пом. №"&AG14,VLOOKUP(AH14,Потребители_обозначение,2,FALSE)&" Шлейф №"&AI14),VLOOKUP(D14,Потребители_обозначение,2,FALSE)) -> #N/A | D14: R.1.05.6 | G14: 1 | I14: =IF(COUNT(AU14:AV14)=0,"",ROUNDUP(SUM(AU14:AV14),0)) | K14: =IF(OR(I14="",S14=""),"",IF(S14=1,MAX(0,M14-ROUNDUP(N(AV14),0)-4),ROUNDUP(N(AU14),0))) | L14: =IF(OR(I14="",S14=""),"",IF(S14=2,MAX(0,M14-ROUNDUP(N(AU14),0)-4),ROUNDUP(N(AV14),0))) | M14: =IFERROR(IF(VLOOKUP(AH14,Потребители_обозначение,4,FALSE)=1,VLOOKUP(AH14,Потребители_обозначение,3,FALSE)*(G14*2-1)+I14+VLOOKUP(AI14,Этаж_обозначение,3,FALSE)+VLOOKUP(AI14,Этаж_обозначение,4,FALSE),VLOOKUP(AH14,Потребители_обозначение,3,FALSE)*(G14*2-1)+I14),I14) -> 0 | P14: =IF(VLOOKUP(AH14,Потребители_обозначение,5,FALSE)=2,_xlfn.IFS(H14=3,VLOOKUP(E14,Справочная_двигатели,8,FALSE),H14=1,VLOOKUP(E14,Справочная_двигатели,10,TRUE)),0.95) -> #N/A | S14: 2 | T14: =_xlfn.IFS(H14=1,E14*1000/220,H14=3,E14/0.38/1.732) -> #N/A | U14: =IF(R14=0,VLOOKUP(T14,Автомат_номиналы,2,TRUE),R14) -> #N/A | V14: =IF(Q14=0,VLOOKUP(U14,Кабель_номиналы,2,TRUE),Q14) -> #N/A | W14: =VLOOKUP(V14,Кабель_сопротивление,3,FALSE) -> #N/A | X14: =VLOOKUP(V14,Кабель_сопротивление,2,FALSE) -> #N/A | Y14: {=_xlfn.IFS(H14=1,2,H14=3,1)} -> #N/A | Z14: =ROUND(SIN(ACOS(P14)),2) -> #N/A | AA14: =Y14*(W14*I14/V14+X14*I14*Z14/1000)*T14 -> #N/A | AB14: =ROUNDUP(AA14/220*100,2) -> #N/A | AC14: =_xlfn.IFS(H14=3,380,H14=1,220) -> #N/A | AD14: =VLOOKUP(N14,Кабель_обозначение,2,FALSE) -> #N/A | AE14: =IF(VLOOKUP(N14,Кабель_обозначение,3,FALSE)=1,AD14&" ("&O14&"х"&V14&")",AD14) -> #N/A | AF14: =IFERROR(IF(AB14>4.5,1,2),0) -> 0 | AG14: =IFERROR(LEFT(AQ14,SEARCH(".",AQ14)-1),AQ14) | AH14: =IFERROR(LEFT(A14,SEARCH(".",A14)-1),A14) -> 0 | AI14: =IFERROR(LEFT(AP14,SEARCH(".",AP14)-1),AP14) -> #VALUE! | AJ14: =IF(C14=0,B14,C14) -> #N/A | AK14: =ROUNDUP(T14,2) -> #N/A | AL14: =E14 -> 0 | AM14: =D14 -> 0 | AO14: =IF(V14=0,AD14,AE14&" L="&M14&"-"&AB14&"%") -> #N/A | AP14: =RIGHT(A14,LEN(A14)-SEARCH(".",A14)) -> #VALUE! | AQ14: =IFERROR(RIGHT(AP14,LEN(AP14)-SEARCH(".",AP14)),"") | AR14: =IFERROR(IF(VLOOKUP(AH14,Потребители_обозначение,5,FALSE)=2,_xlfn.IFS(H14=3,VLOOKUP(E14,Справочная_двигатели,3,FALSE),H14=1,VLOOKUP(E14,Справочная_двигатели,5,TRUE)),0),0) -> 0 | AS14: =IFERROR(IF(VLOOKUP(AH14,Потребители_обозначение,5,FALSE)=3,VLOOKUP(E14,Справочная_ЛЭД,2,TRUE),0),0) -> 0 | AT14: =IF(AR14=0,AS14,AR14) -> 0 | AV14: 14.92 | AW14: 830C22
A15: =D15 -> От ИБП | B15: =IFERROR(IF(VLOOKUP(AH15,Потребители_обозначение,4,FALSE)=1,VLOOKUP(AH15,Потребители_обозначение,2,FALSE)&" "&VLOOKUP(AI15,Этаж_обозначение,2,FALSE)&" Пом. №"&AG15,VLOOKUP(AH15,Потребители_обозначение,2,FALSE)&" Шлейф №"&AI15),VLOOKUP(D15,Потребители_обозначение,2,FALSE)) -> Питание от ИБП | D15: R.1.05.7 | G15: 1 | I15: =IF(COUNT(AU15:AV15)=0,"",ROUNDUP(SUM(AU15:AV15),0)) | K15: =IF(OR(I15="",S15=""),"",IF(S15=1,MAX(0,M15-ROUNDUP(N(AV15),0)-4),ROUNDUP(N(AU15),0))) | L15: =IF(OR(I15="",S15=""),"",IF(S15=2,MAX(0,M15-ROUNDUP(N(AU15),0)-4),ROUNDUP(N(AV15),0))) | M15: =IFERROR(IF(VLOOKUP(AH15,Потребители_обозначение,4,FALSE)=1,VLOOKUP(AH15,Потребители_обозначение,3,FALSE)*(G15*2-1)+I15+VLOOKUP(AI15,Этаж_обозначение,3,FALSE)+VLOOKUP(AI15,Этаж_обозначение,4,FALSE),VLOOKUP(AH15,Потребители_обозначение,3,FALSE)*(G15*2-1)+I15),I15) -> 22 | P15: =IF(VLOOKUP(AH15,Потребители_обозначение,5,FALSE)=2,_xlfn.IFS(H15=3,VLOOKUP(E15,Справочная_двигатели,8,FALSE),H15=1,VLOOKUP(E15,Справочная_двигатели,10,TRUE)),0.95) -> 0.95 | S15: 2 | T15: =_xlfn.IFS(H15=1,E15*1000/220,H15=3,E15/0.38/1.732) -> 9.0909091 | U15: =IF(R15=0,VLOOKUP(T15,Автомат_номиналы,2,TRUE),R15) -> 16 | V15: =IF(Q15=0,VLOOKUP(U15,Кабель_номиналы,2,TRUE),Q15) -> 2.5 | W15: =VLOOKUP(V15,Кабель_сопротивление,3,FALSE) -> 0.0175 | X15: =VLOOKUP(V15,Кабель_сопротивление,2,FALSE) -> 0.1 | Y15: {=_xlfn.IFS(H15=1,2,H15=3,1)} -> 2 | Z15: =ROUND(SIN(ACOS(P15)),2) -> 0.31 | AA15: =Y15*(W15*I15/V15+X15*I15*Z15/1000)*T15 -> 2.8124 | AB15: =ROUNDUP(AA15/220*100,2) -> 1.28 | AC15: =_xlfn.IFS(H15=3,380,H15=1,220) -> 220 | AD15: =VLOOKUP(N15,Кабель_обозначение,2,FALSE) -> ВВГнг(А)-LS | AE15: =IF(VLOOKUP(N15,Кабель_обозначение,3,FALSE)=1,AD15&" ("&O15&"х"&V15&")",AD15) -> ВВГнг(А)-LS (3х2,5) | AF15: =IFERROR(IF(AB15>4.5,1,2),0) -> 2 | AG15: =IFERROR(LEFT(AQ15,SEARCH(".",AQ15)-1),AQ15) | AH15: =IFERROR(LEFT(A15,SEARCH(".",A15)-1),A15) -> От ИБП | AI15: =IFERROR(LEFT(AP15,SEARCH(".",AP15)-1),AP15) -> #VALUE! | AJ15: =IF(C15=0,B15,C15) -> Питание от ИБП | AK15: =ROUNDUP(T15,2) -> 9.1 | AL15: =E15 -> 2 | AM15: =D15 -> От ИБП | AO15: =IF(V15=0,AD15,AE15&" L="&M15&"-"&AB15&"%") -> ВВГнг(А)-LS (3х2,5) L=22-1,28% | AP15: =RIGHT(A15,LEN(A15)-SEARCH(".",A15)) -> #VALUE! | AQ15: =IFERROR(RIGHT(AP15,LEN(AP15)-SEARCH(".",AP15)),"") | AR15: =IFERROR(IF(VLOOKUP(AH15,Потребители_обозначение,5,FALSE)=2,_xlfn.IFS(H15=3,VLOOKUP(E15,Справочная_двигатели,3,FALSE),H15=1,VLOOKUP(E15,Справочная_двигатели,5,TRUE)),0),0) -> 0 | AS15: =IFERROR(IF(VLOOKUP(AH15,Потребители_обозначение,5,FALSE)=3,VLOOKUP(E15,Справочная_ЛЭД,2,TRUE),0),0) -> 0 | AT15: =IF(AR15=0,AS15,AR15) -> 0 | AV15: 14.81 | AW15: 830AB9
A16: =D16 -> 0 | B16: =IFERROR(IF(VLOOKUP(AH16,Потребители_обозначение,4,FALSE)=1,VLOOKUP(AH16,Потребители_обозначение,2,FALSE)&" "&VLOOKUP(AI16,Этаж_обозначение,2,FALSE)&" Пом. №"&AG16,VLOOKUP(AH16,Потребители_обозначение,2,FALSE)&" Шлейф №"&AI16),VLOOKUP(D16,Потребители_обозначение,2,FALSE)) -> #N/A | D16: R.1.05.8 | G16: 1 | M16: =IFERROR(IF(VLOOKUP(AH16,Потребители_обозначение,4,FALSE)=1,VLOOKUP(AH16,Потребители_обозначение,3,FALSE)*(G16*2-1)+I16+VLOOKUP(AI16,Этаж_обозначение,3,FALSE)+VLOOKUP(AI16,Этаж_обозначение,4,FALSE),VLOOKUP(AH16,Потребители_обозначение,3,FALSE)*(G16*2-1)+I16),I16) -> 0 | P16: =IF(VLOOKUP(AH16,Потребители_обозначение,5,FALSE)=2,_xlfn.IFS(H16=3,VLOOKUP(E16,Справочная_двигатели,8,FALSE),H16=1,VLOOKUP(E16,Справочная_двигатели,10,TRUE)),0.95) -> #N/A | T16: =_xlfn.IFS(H16=1,E16*1000/220,H16=3,E16/0.38/1.732) -> #N/A | U16: =IF(R16=0,VLOOKUP(T16,Автомат_номиналы,2,TRUE),R16) -> #N/A | V16: =IF(Q16=0,VLOOKUP(U16,Кабель_номиналы,2,TRUE),Q16) -> #N/A | W16: =VLOOKUP(V16,Кабель_сопротивление,3,FALSE) -> #N/A | X16: =VLOOKUP(V16,Кабель_сопротивление,2,FALSE) -> #N/A | Y16: {=_xlfn.IFS(H16=1,2,H16=3,1)} -> #N/A | Z16: =ROUND(SIN(ACOS(P16)),2) -> #N/A | AA16: =Y16*(W16*I16/V16+X16*I16*Z16/1000)*T16 -> #N/A | AB16: =ROUNDUP(AA16/220*100,2) -> #N/A | AC16: =_xlfn.IFS(H16=3,380,H16=1,220) -> #N/A | AD16: =VLOOKUP(N16,Кабель_обозначение,2,FALSE) -> #N/A | AE16: =IF(VLOOKUP(N16,Кабель_обозначение,3,FALSE)=1,AD16&" ("&O16&"х"&V16&")",AD16) -> #N/A | AF16: =IFERROR(IF(AB16>4.5,1,2),0) -> 0 | AG16: =IFERROR(LEFT(AQ16,SEARCH(".",AQ16)-1),AQ16) | AH16: =IFERROR(LEFT(A16,SEARCH(".",A16)-1),A16) -> 0 | AI16: =IFERROR(LEFT(AP16,SEARCH(".",AP16)-1),AP16) -> #VALUE! | AJ16: =IF(C16=0,B16,C16) -> #N/A | AK16: =ROUNDUP(T16,2) -> #N/A | AL16: =E16 -> 0 | AM16: =D16 -> 0 | AO16: =IF(V16=0,AD16,AE16&" L="&M16&"-"&AB16&"%") -> #N/A | AP16: =RIGHT(A16,LEN(A16)-SEARCH(".",A16)) -> #VALUE! | AQ16: =IFERROR(RIGHT(AP16,LEN(AP16)-SEARCH(".",AP16)),"") | AR16: =IFERROR(IF(VLOOKUP(AH16,Потребители_обозначение,5,FALSE)=2,_xlfn.IFS(H16=3,VLOOKUP(E16,Справочная_двигатели,3,FALSE),H16=1,VLOOKUP(E16,Справочная_двигатели,5,TRUE)),0),0) -> 0 | AS16: =IFERROR(IF(VLOOKUP(AH16,Потребители_обозначение,5,FALSE)=3,VLOOKUP(E16,Справочная_ЛЭД,2,TRUE),0),0) -> 0 | AT16: =IF(AR16=0,AS16,AR16) -> 0 | AX16: полилиния 830ABB (13.3 м) общая с R.1.05.9 — не засчитана
A17: =D17 -> R.ЩР | B17: =IFERROR(IF(VLOOKUP(AH17,Потребители_обозначение,4,FALSE)=1,VLOOKUP(AH17,Потребители_обозначение,2,FALSE)&" "&VLOOKUP(AI17,Этаж_обозначение,2,FALSE)&" Пом. №"&AG17,VLOOKUP(AH17,Потребители_обозначение,2,FALSE)&" Шлейф №"&AI17),VLOOKUP(D17,Потребители_обозначение,2,FALSE)) -> #N/A | D17: R.1.05.9 | G17: 1 | M17: =IFERROR(IF(VLOOKUP(AH17,Потребители_обозначение,4,FALSE)=1,VLOOKUP(AH17,Потребители_обозначение,3,FALSE)*(G17*2-1)+I17+VLOOKUP(AI17,Этаж_обозначение,3,FALSE)+VLOOKUP(AI17,Этаж_обозначение,4,FALSE),VLOOKUP(AH17,Потребители_обозначение,3,FALSE)*(G17*2-1)+I17),I17) -> 4 | P17: =IF(VLOOKUP(AH17,Потребители_обозначение,5,FALSE)=2,_xlfn.IFS(H17=3,VLOOKUP(E17,Справочная_двигатели,8,FALSE),H17=1,VLOOKUP(E17,Справочная_двигатели,10,TRUE)),0.95) -> 0.95 | T17: =_xlfn.IFS(H17=1,E17*1000/220,H17=3,E17/0.38/1.732) -> 0.45454545 | U17: =IF(R17=0,VLOOKUP(T17,Автомат_номиналы,2,TRUE),R17) -> 6 | V17: =IF(Q17=0,VLOOKUP(U17,Кабель_номиналы,2,TRUE),Q17) -> 1.5 | W17: =VLOOKUP(V17,Кабель_сопротивление,3,FALSE) -> 0.0175 | X17: =VLOOKUP(V17,Кабель_сопротивление,2,FALSE) -> 0.11 | Y17: {=_xlfn.IFS(H17=1,2,H17=3,1)} -> 2 | Z17: =ROUND(SIN(ACOS(P17)),2) -> 0.31 | AA17: =Y17*(W17*I17/V17+X17*I17*Z17/1000)*T17 -> 0.042548242 | AB17: =ROUNDUP(AA17/220*100,2) -> 0.02 | AC17: =_xlfn.IFS(H17=3,380,H17=1,220) -> 220 | AD17: =VLOOKUP(N17,Кабель_обозначение,2,FALSE) -> #N/A | AE17: =IF(VLOOKUP(N17,Кабель_обозначение,3,FALSE)=1,AD17&" ("&O17&"х"&V17&")",AD17) -> #N/A | AF17: =IFERROR(IF(AB17>4.5,1,2),0) -> 2 | AG17: =IFERROR(LEFT(AQ17,SEARCH(".",AQ17)-1),AQ17) | AH17: =IFERROR(LEFT(A17,SEARCH(".",A17)-1),A17) -> R | AI17: =IFERROR(LEFT(AP17,SEARCH(".",AP17)-1),AP17) -> ЩР | AJ17: =IF(C17=0,B17,C17) -> Розетка щитовая | AK17: =ROUNDUP(T17,2) -> 0.46 | AL17: =E17 -> 0.1 | AM17: =D17 -> R.ЩР | AO17: =IF(V17=0,AD17,AE17&" L="&M17&"-"&AB17&"%") -> #N/A | AP17: =RIGHT(A17,LEN(A17)-SEARCH(".",A17)) -> ЩР | AQ17: =IFERROR(RIGHT(AP17,LEN(AP17)-SEARCH(".",AP17)),"") | AR17: =IFERROR(IF(VLOOKUP(AH17,Потребители_обозначение,5,FALSE)=2,_xlfn.IFS(H17=3,VLOOKUP(E17,Справочная_двигатели,3,FALSE),H17=1,VLOOKUP(E17,Справочная_двигатели,5,TRUE)),0),0) -> 0 | AS17: =IFERROR(IF(VLOOKUP(AH17,Потребители_обозначение,5,FALSE)=3,VLOOKUP(E17,Справочная_ЛЭД,2,TRUE),0),0) -> 0 | AT17: =IF(AR17=0,AS17,AR17) -> 0 | AX17: полилиния 830ABB (13.3 м) общая с R.1.05.8 — не засчитана
A18: =D18 -> 0 | B18: =IFERROR(IF(VLOOKUP(AH18,Потребители_обозначение,4,FALSE)=1,VLOOKUP(AH18,Потребители_обозначение,2,FALSE)&" "&VLOOKUP(AI18,Этаж_обозначение,2,FALSE)&" Пом. №"&AG18,VLOOKUP(AH18,Потребители_обозначение,2,FALSE)&" Шлейф №"&AI18),VLOOKUP(D18,Потребители_обозначение,2,FALSE)) -> #N/A | D18: R.1.05.10 | G18: 1 | I18: =IF(COUNT(AU18:AV18)=0,"",ROUNDUP(SUM(AU18:AV18),0)) | K18: =IF(OR(I18="",S18=""),"",IF(S18=1,MAX(0,M18-ROUNDUP(N(AV18),0)-4),ROUNDUP(N(AU18),0))) | L18: =IF(OR(I18="",S18=""),"",IF(S18=2,MAX(0,M18-ROUNDUP(N(AU18),0)-4),ROUNDUP(N(AV18),0))) | M18: =IFERROR(IF(VLOOKUP(AH18,Потребители_обозначение,4,FALSE)=1,VLOOKUP(AH18,Потребители_обозначение,3,FALSE)*(G18*2-1)+I18+VLOOKUP(AI18,Этаж_обозначение,3,FALSE)+VLOOKUP(AI18,Этаж_обозначение,4,FALSE),VLOOKUP(AH18,Потребители_обозначение,3,FALSE)*(G18*2-1)+I18),I18) -> 0 | P18: =IF(VLOOKUP(AH18,Потребители_обозначение,5,FALSE)=2,_xlfn.IFS(H18=3,VLOOKUP(E18,Справочная_двигатели,8,FALSE),H18=1,VLOOKUP(E18,Справочная_двигатели,10,TRUE)),0.95) -> #N/A | S18: 2 | T18: =_xlfn.IFS(H18=1,E18*1000/220,H18=3,E18/0.38/1.732) -> #N/A | U18: =IF(R18=0,VLOOKUP(T18,Автомат_номиналы,2,TRUE),R18) -> #N/A | V18: =IF(Q18=0,VLOOKUP(U18,Кабель_номиналы,2,TRUE),Q18) -> #N/A | W18: =VLOOKUP(V18,Кабель_сопротивление,3,FALSE) -> #N/A | X18: =VLOOKUP(V18,Кабель_сопротивление,2,FALSE) -> #N/A | Y18: {=_xlfn.IFS(H18=1,2,H18=3,1)} -> #N/A | Z18: =ROUND(SIN(ACOS(P18)),2) -> #N/A | AA18: =Y18*(W18*I18/V18+X18*I18*Z18/1000)*T18 -> #N/A | AB18: =ROUNDUP(AA18/220*100,2) -> #N/A | AC18: =_xlfn.IFS(H18=3,380,H18=1,220) -> #N/A | AD18: =VLOOKUP(N18,Кабель_обозначение,2,FALSE) -> #N/A | AE18: =IF(VLOOKUP(N18,Кабель_обозначение,3,FALSE)=1,AD18&" ("&O18&"х"&V18&")",AD18) -> #N/A | AF18: =IFERROR(IF(AB18>4.5,1,2),0) -> 0 | AG18: =IFERROR(LEFT(AQ18,SEARCH(".",AQ18)-1),AQ18) | AH18: =IFERROR(LEFT(A18,SEARCH(".",A18)-1),A18) -> 0 | AI18: =IFERROR(LEFT(AP18,SEARCH(".",AP18)-1),AP18) -> #VALUE! | AJ18: =IF(C18=0,B18,C18) -> #N/A | AK18: =ROUNDUP(T18,2) -> #N/A | AL18: =E18 -> 0 | AM18: =D18 -> 0 | AO18: =IF(V18=0,AD18,AE18&" L="&M18&"-"&AB18&"%") -> #N/A | AP18: =RIGHT(A18,LEN(A18)-SEARCH(".",A18)) -> #VALUE! | AQ18: =IFERROR(RIGHT(AP18,LEN(AP18)-SEARCH(".",AP18)),"") | AR18: =IFERROR(IF(VLOOKUP(AH18,Потребители_обозначение,5,FALSE)=2,_xlfn.IFS(H18=3,VLOOKUP(E18,Справочная_двигатели,3,FALSE),H18=1,VLOOKUP(E18,Справочная_двигатели,5,TRUE)),0),0) -> 0 | AS18: =IFERROR(IF(VLOOKUP(AH18,Потребители_обозначение,5,FALSE)=3,VLOOKUP(E18,Справочная_ЛЭД,2,TRUE),0),0) -> 0 | AT18: =IF(AR18=0,AS18,AR18) -> 0 | AV18: 9.84 | AW18: 830AB8
A19: =D19 -> 0 | B19: =IFERROR(IF(VLOOKUP(AH19,Потребители_обозначение,4,FALSE)=1,VLOOKUP(AH19,Потребители_обозначение,2,FALSE)&" "&VLOOKUP(AI19,Этаж_обозначение,2,FALSE)&" Пом. №"&AG19,VLOOKUP(AH19,Потребители_обозначение,2,FALSE)&" Шлейф №"&AI19),VLOOKUP(D19,Потребители_обозначение,2,FALSE)) -> #N/A | D19: R.1.06.1 | G19: 1 | I19: =IF(COUNT(AU19:AV19)=0,"",ROUNDUP(SUM(AU19:AV19),0)) | K19: =IF(OR(I19="",S19=""),"",IF(S19=1,MAX(0,M19-ROUNDUP(N(AV19),0)-4),ROUNDUP(N(AU19),0))) | L19: =IF(OR(I19="",S19=""),"",IF(S19=2,MAX(0,M19-ROUNDUP(N(AU19),0)-4),ROUNDUP(N(AV19),0))) | M19: =IFERROR(IF(VLOOKUP(AH19,Потребители_обозначение,4,FALSE)=1,VLOOKUP(AH19,Потребители_обозначение,3,FALSE)*(G19*2-1)+I19+VLOOKUP(AI19,Этаж_обозначение,3,FALSE)+VLOOKUP(AI19,Этаж_обозначение,4,FALSE),VLOOKUP(AH19,Потребители_обозначение,3,FALSE)*(G19*2-1)+I19),I19) -> 0 | P19: =IF(VLOOKUP(AH19,Потребители_обозначение,5,FALSE)=2,_xlfn.IFS(H19=3,VLOOKUP(E19,Справочная_двигатели,8,FALSE),H19=1,VLOOKUP(E19,Справочная_двигатели,10,TRUE)),0.95) -> #N/A | S19: 2 | T19: =_xlfn.IFS(H19=1,E19*1000/220,H19=3,E19/0.38/1.732) -> #N/A | U19: =IF(R19=0,VLOOKUP(T19,Автомат_номиналы,2,TRUE),R19) -> #N/A | V19: =IF(Q19=0,VLOOKUP(U19,Кабель_номиналы,2,TRUE),Q19) -> #N/A | W19: =VLOOKUP(V19,Кабель_сопротивление,3,FALSE) -> #N/A | X19: =VLOOKUP(V19,Кабель_сопротивление,2,FALSE) -> #N/A | Y19: {=_xlfn.IFS(H19=1,2,H19=3,1)} -> #N/A | Z19: =ROUND(SIN(ACOS(P19)),2) -> #N/A | AA19: =Y19*(W19*I19/V19+X19*I19*Z19/1000)*T19 -> #N/A | AB19: =ROUNDUP(AA19/220*100,2) -> #N/A | AC19: =_xlfn.IFS(H19=3,380,H19=1,220) -> #N/A | AD19: =VLOOKUP(N19,Кабель_обозначение,2,FALSE) -> #N/A | AE19: =IF(VLOOKUP(N19,Кабель_обозначение,3,FALSE)=1,AD19&" ("&O19&"х"&V19&")",AD19) -> #N/A | AF19: =IFERROR(IF(AB19>4.5,1,2),0) -> 0 | AG19: =IFERROR(LEFT(AQ19,SEARCH(".",AQ19)-1),AQ19) | AH19: =IFERROR(LEFT(A19,SEARCH(".",A19)-1),A19) -> 0 | AI19: =IFERROR(LEFT(AP19,SEARCH(".",AP19)-1),AP19) -> #VALUE! | AJ19: =IF(C19=0,B19,C19) -> #N/A | AK19: =ROUNDUP(T19,2) -> #N/A | AL19: =E19 -> 0 | AM19: =D19 -> 0 | AO19: =IF(V19=0,AD19,AE19&" L="&M19&"-"&AB19&"%") -> #N/A | AP19: =RIGHT(A19,LEN(A19)-SEARCH(".",A19)) -> #VALUE! | AQ19: =IFERROR(RIGHT(AP19,LEN(AP19)-SEARCH(".",AP19)),"") | AR19: =IFERROR(IF(VLOOKUP(AH19,Потребители_обозначение,5,FALSE)=2,_xlfn.IFS(H19=3,VLOOKUP(E19,Справочная_двигатели,3,FALSE),H19=1,VLOOKUP(E19,Справочная_двигатели,5,TRUE)),0),0) -> 0 | AS19: =IFERROR(IF(VLOOKUP(AH19,Потребители_обозначение,5,FALSE)=3,VLOOKUP(E19,Справочная_ЛЭД,2,TRUE),0),0) -> 0 | AT19: =IF(AR19=0,AS19,AR19) -> 0 | AV19: 23.68 | AW19: 830B4A
