Workbook
Name c_min: Объект!$C$7
Name dU_пит: Таблицы_норм!$BQ$31
Name Iдоп_1ж: Таблицы_норм!$BY$4:$BY$18
Name Iдоп_2ж: Таблицы_норм!$BZ$4:$BZ$17
Name Iдоп_3ж: Таблицы_норм!$CA$4:$CA$17
Name Iдоп_S: Таблицы_норм!$BX$4:$BX$18
Name k_пк: Объект!$C$9
Name R_пер: Объект!$C$6
Name Uн_лин: Таблицы_норм!$BQ$29
Name ρкз_Al: Объект!$C$5
Name ρкз_Cu: Объект!$C$4
Name Автомат_номиналы: Таблицы_норм!$F$4:$G$23
Name гофра_пвх: Справочная_потребители!$Z$4:$AB$9
Name гофра_пнд: Справочная_потребители!$AD$4:$AF$9
Name Запас_кабеля: Кабельный_журнал!$P$2
Name ИБП_cos_вх: Объект!$C$22
Name ИБП_cos_вых: Объект!$C$16
Name ИБП_k: Объект!$C$20
Name ИБП_t: Объект!$C$17
Name ИБП_U: Объект!$C$18
Name ИБП_загрузка: Объект!$C$15
Name ИБП_заряд: Объект!$C$21
Name ИБП_КПД: Объект!$C$19
Name ИБП_ряд: Объект!$C$24:$N$24
Name К_прокл: Таблицы_норм!$BQ$30
Name Кабель_диаметр: Справочная_потребители!$T$4:$X$503
Name Кабель_номиналы: Таблицы_норм!$I$4:$J$19
Name Кабель_обозначение: Кабели[]
Name Кабель_сопротивление: Таблицы_норм!$B$4:$D$19
Name Категории_ПЗ: Таблицы_норм!$BT$4:$BT$33
Name Ко_сил: Таблицы_норм!$BQ$14
Name Коды_вид: Коды[Вид нагрузки]
Name Коды_группа: Коды[Группа Кс]
Name Коды_код: Коды[Код]
Name Коды_пожарная: Коды[Пожарная]
Name Кс_К: Таблицы_норм!$BQ$4:$BQ$11
Name Кс_Р: Таблицы_норм!$BP$4:$BP$11
Name Кс75_k: Объект!$G$3:$G$14
Name Кс75_n: Объект!$F$3:$F$14
Name Методика: Объект!$C$8
Name Мин_автомат_БП: Таблицы_норм!$BF$5
Name Модели_список: OFFSET(Каталог!$AB$3,0,0,1+MAX(Каталог!$AA$4:$AA$500),1)
Name Модули_спр: Каталог!$C$4:$F$500
Name Потребители_обозначение: Коды[[Код]:[Сечение]]
Name Спецификация: Спецификация!$B$3:$J$60
Name Список_автоматов: OFFSET(Каталог!$X$3,0,0,1+MAX(Каталог!$W$4:$W$500),1)
Name Список_аппаратов: OFFSET(Каталог!$Z$4,0,0,MAX(1,MAX(Каталог!$Y$4:$Y$500)),1)
Name Список_модулей: OFFSET(Каталог!$AB$3,0,0,1+MAX(Каталог!$AA$4:$AA$500),1)
Name Список_произв: OFFSET(Каталог!$AD$3,0,0,1+MAX(Каталог!$AC$4:$AC$500),1)
Name Список_щитов: Щиты[Щит]
Name Справочная_двигатели: Справочная_потребители!$B$4:$K$37
Name Справочная_ЛЭД: Справочная_потребители!$M$4:$O$19
Name Справочная_ПТО: Таблицы_норм!$AJ$4:$AK$200
Name Столбцов_на_лист: Таблицы_норм!$BF$4
Name УГО_блоки: Таблицы_норм!$BA$4:$BC$30
Name УГО_спр: УГО[]
Name Управление_цвета: Таблицы_норм!$AQ$4:$AS$10
Name Щит_спец: Спецификация!$L$1
Name Этаж_обозначение: Этажи[]

Sheet Гайд
A1: ГАЙД ПО ОДНОЛИНЕЙКЕ v4
A2: Одна книга — один объект: все щиты, все линии, все расчёты. Связей между файлами нет. Текст написан по правилам ASD-STE100: одно действие в предложении, один термин — одно значение.
A3: Разделы 4–15 — порядок работы. На листах «Объект», «Щиты», «Шины» есть свой короткий гайд. Как и по каким нормам всё считается — лист «Методика».
A5: 1. ТЕРМИНЫ
B6: Термин | C6: Значение
B7: Объект | C7: Здание или комплекс. Одна книга = один объект.
B8: Щит | C8: Электрический щит объекта. Каждый щит — одна строка на листе «Щиты». | D8: Щиты!A10
B9: ВРУ (корневой щит) | C9: Щит без вышестоящего щита в книге: ГРЩ, ВРУ. Для него вводятся данные сети.
B10: Линия | C10: Отходящая цепь щита. Одна строка на листе «Линии» = одно место схемы. | D10: Линии!A3
B11: Номер линии | C11: Текст вида «Код.Помещение.№». Пример: R.1.05.4. Код ищется на листе «Коды».
B12: Место | C12: Колонка на схеме (шаг 20 мм). На листе A3 — 17 мест (настройка «Таблицы_норм» BF4).
B13: Вводной узел | C13: Первые места схемы щита (обычно 1–15): вводы, АВР, байпас. Вы рисуете их сами. Строки узла в схеме не рисуются.
B14: Фидер | C14: Линия, которая питает другой щит этой книги. Номер линии = имя щита — фидер найден автоматически.
B15: Группа | C15: Несколько линий на одном автомате. Автомат стоит в первой строке группы.
B16: Дифзащита | C16: Ток утечки защиты (УЗО, дифавтомат): 10, 30, 100, 300 мА. Пусто — по коду.
B17: Жёлтый столбец | C17: Ввод. Вводите данные только сюда.
B18: Серый столбец | C18: Расчёт. Значение считается само. Служебные столбцы свёрнуты кнопкой «+» над таблицей.
A20: 2. ПРАВИЛА КНИГИ
A21: ОСТОРОЖНО: Не сортируйте таблицу «Линии». Порядок строк = порядок мест и групп на схеме.
A22: ОСТОРОЖНО: Не переименовывайте листы, таблицы и заголовки столбцов. Формулы и программы AutoCAD ищут их по имени.
A23: ОСТОРОЖНО: Не вводите данные в серые столбцы и на лист «Однолинейка». Лист «Однолинейка» считается сам.
A24: ВНИМАНИЕ: Новую строку добавляйте внутри таблицы: правая кнопка на строке → «Вставить» → «Строки таблицы выше». Формулы продлятся сами.
A25: ВНИМАНИЕ: Перед массовой правкой сохраните копию книги. После макросов Ctrl+Z не работает.
A27: 3. ЛИСТЫ
B28: Лист | C28: Что на нём
B29: Проверка | C29: Все замечания объекта одним списком. Начинайте и заканчивайте работу здесь. | D29: Проверка!A1
B30: Объект | C30: Настройки объекта: методика, kп.к, ток КЗ, Кс силовых, ИБП. Внизу — гайд по настройке. | D30: Объект!B1
B31: Коды | C31: Коды потребителей, УГО, этажи, кабели. Таблицы растут сами. | D31: Коды!A3
B32: Щиты | C32: Щиты объекта: схема (ввод) и результат. Сверху — гайд. | D32: Щиты!A10
B33: Итоги_щитов | C33: Карточка щита для таблицы под однолинейкой и сводка по всем щитам. | D33: Итоги_щитов!C3
B34: Шины | C34: Тип шины вручную — только если не определяется сам. Сверху — гайд. | D34: Шины!A8
B35: Линии | C35: Главный лист ввода: все линии всех щитов. | D35: Линии!A2
B36: Режимы | C36: Нагрузка щита по вводам: нормальный, аварийный, пожар, категории, ИБП. | D36: Режимы!C3
B37: Расчёт_нагрузок | C37: Таблица нагрузок для пояснительной записки. | D37: Расчёт_нагрузок!C4
B38: Кабельный_журнал | C38: Журнал кабелей (как в v3.12) и сводка по маркам. | D38: Кабельный_журнал!A2
B39: Однолинейка | C39: Расчётный лист для AutoCAD (SXDRAW, SXLAYOUT). Не изменяйте его. | D39: Однолинейка!A1
B40: Каталог, Спецификация, Спецификация_авто | C40: Оборудование и спецификация. Щит — «Спецификация» D1. | D40: Спецификация!D1
B41: Бирки | C41: Строка на каждый провод: откуда — куда. | D41: Бирки!A3
B42: Методика | C42: Как считается каждая величина и по какой норме.
B43: Таблицы_норм | C43: Допустимые токи, сопротивления, номиналы, Кс быт, настройки сети. Обычно не меняют.
...

Sheet Проверка
A1: ПРОВЕРКА ОБЪЕКТА
A2: ="Замечаний: щиты — "&COUNTIF(Щиты[Замечания щита],"?*")&", линии — "&COUNTIF(Линии[Замечания],"?*")&". Методика: "&Методика -> Замечаний: щиты — 1, линии — 29. Методика: нормы 2026
A4: Щит | B4: Замечания щита | D4: Щит | E4: № места | F4: Номер линии | G4: Наименование | H4: Замечания | I4: Перейти
A5: {=_xlfn._xlws.FILTER(_xlfn.HSTACK(Щиты[Щит],Щиты[Замечания щита]),Щиты[Замечания щита]<>"","замечаний нет")} -> ЩР | B5: нет данных сети для ТКЗ: введите Iкз от сетевой организации или трансформатор | D5: {=_xlfn._xlws.FILTER(_xlfn.HSTACK(Линии[Щит],Линии[№ места],Линии[Номер линии],Линии[Наименование],Линии[Замечания],HYPERLINK("#'Линии'!C"&(Линии[_n]+2),"→")),Линии[Замечания]<>"","замечаний нет")} -> ЩР | E5: 20 | F5: R.1.02.1 | G5: Розеточная группа Пом. №02 | H5: дубль клеммы XT2 | I5: →
D6: ЩР | E6: 21 | F6: R.1.03.1 | G6: Розеточная группа Пом. №03 | H6: дубль клеммы XT2 | I6: →
D7: ЩР | E7: 36 | F7: R.1.05.10 | G7: Розеточная группа Пом. №05 | H7: дубль клеммы XT16 | I7: →
D8: ЩР | E8: 37 | F8: R.1.05.11 | G8: Розеточная группа Пом. №05 | H8: дубль клеммы XT17 | I8: →
D9: ЩР | E9: 39 | F9: R.1.06.2 | G9: Розеточная группа Пом. №06 | H9: дубль клеммы XT16 | I9: →
D10: ЩР | E10: 40 | F10: R.1.07.1 | G10: Розеточная группа Пом. №07 | H10: дубль клеммы XT17 | I10: →
D11: ЩР | E11: 50 | F11: L.1.01.1 | G11: Группа освещения Пом. №01 | H11: нет мощности | I11: →
D12: ЩР | E12: 53 | F12: L.1.04.1 | G12: Группа освещения Пом. №04 | H12: нет мощности | I12: →
D13: ЩР | E13: 54 | F13: L.1.04.2 | G13: Группа освещения Пом. №04 | H13: нет мощности | I13: →
D14: ЩР | E14: 55 | F14: L.1.06.2 | G14: Группа освещения Пом. №06 | H14: нет мощности | I14: →
D15: ЩР | E15: 56 | F15: L.1.08.2 | G15: Группа освещения Пом. №08 | H15: нет мощности | I15: →
D16: ЩР | E16: 57 | F16: L.1.10.2 | G16: Группа освещения Пом. №10 | H16: нет мощности | I16: →
D17: ЩР | E17: 58 | F17: L.1.14.1 | G17: Группа освещения Пом. №14 | H17: нет мощности | I17: →
... D33: ЩР | E33: 76 | F33: L.2.12.2 | G33: Группа освещения Пом. №12 | H33: нет мощности | I33: →

Sheet Объект
B1: ОБЪЕКТ: настройки
F2: Число силовых ЭП | G2: Кс (СП 256 табл. 7.5)
B3: Объект | D3: название и адрес | F3: 1 | G3: 1
B4: ρ меди для Iкз min, Ом·мм²/м | C4: 0.0263 | D4: ≈ 1,5·ρ20 (ГОСТ 28249 п. 2.4.2) | F4: 2 | G4: 1
B5: ρ алюминия для Iкз min, Ом·мм²/м | C5: 0.042 | D5: ≈ 1,5·ρ20 | F5: 3 | G5: 0.9
B6: Переходные сопротивления на щит, Ом | C6: 0.015 | D6: контакты и аппараты на каждый щит | F6: 5 | G6: 0.8
B7: c_min для Iкз min | C7: 0.95 | D7: МЭК 60909-0 | F7: 8 | G7: 0.75
B8: Методика расчёта | C8: нормы 2026 | D8: v3.12 — как старая книга (для сверки); нормы 2026 — исправления по СП 256 с Изм. 9 (см. «Методика») | F8: 10 | G8: 0.7
B9: kп.к — региональный коэффициент | C9: 1 | D9: СП 256 табл. 7.5а (ЦФО 0,81, СЗФО 0,91…); для частного дома по умолчанию 1 | F9: 15 | G9: 0.65
F10: 20 | G10: 0.65
B11: Сеть (Uн), К прокладки, Кс быт, Ко — «Справочная» BP:BQ. | F11: 30 | G11: 0.6
F12: 50 | G12: 0.55
F13: 100 | G13: 0.55
B14: ИБП (для щитов с шиной ИБП) | F14: 200 | G14: 0.5
B15: Допустимая загрузка ИБП | C15: 0.75
B16: cos φ на выходе ИБП | C16: 0.9
B17: Автономия, мин | C17: 15 | D17: мин
B18: Напряжение АКБ, В | C18: 240 | D18: В
B19: КПД инвертора | C19: 0.95
B20: Коэффициент разряда / старения АКБ | C20: 0.8
B21: Заряд АКБ, доля мощности | C21: 0.1
B22: cos φ на входе ИБП | C22: 0.95
B24: Ряд типоразмеров ИБП, кВА | C24: 6 | D24: 10 | E24: 15 | F24: 20 | G24: 30 | H24: 40 | I24: 60 | J24: 80 | K24: 100 | L24: 120 | M24: 160 | N24: 200
B28: КАК НАСТРАИВАТЬ ЛИСТ «ОБЪЕКТ»
B29: Лист задаёт настройки ВСЕГО объекта. Обычно меняют только C3 (название), C8 (методика) и C9 (kп.к). Остальное — по необходимости.
B30: C3 Объект — название и адрес. Идёт в таблицу для пояснительной записки.
B31: C4–C7 Ток КЗ: ρ меди/алюминия при нагреве, переходные сопротивления на каждый щит, c_min. Влияют на Iкз min в конце линий и проверку отключения ≤ 0,4 с. Значения по ГОСТ 28249 — не меняйте без причины.
B32: C8 Методика: «нормы 2026» — расчёт по СП 256 с Изм. 9 (cos φ силовых 0,8, Кс силовых по табл. 7.5, Ко только при бытовой + силовой нагрузке, отопление и ВНГ отдельно). «v3.12» — как старая книга, только для сверки.
B33: C9 kп.к — региональный коэффициент к бытовой нагрузке (СП 256 табл. 7.5а). Частный дом — 1. Многоквартирный дом — значение региона (ЦФО 0,81).
B34: F2:G14 Кс силовых по числу электроприёмников (СП 256 табл. 7.5, доля сантехники 100–85 %). Применяется к силовым линиям без ручного Кс в режиме «нормы 2026».
B35: B15:C22 ИБП — допустимая загрузка, cos φ, автономия, напряжение АКБ, КПД, разряд, заряд. Влияют на подбор ИБП и на нагрузку входа ИБП на вводе (лист «Режимы»).
B36: Где ещё настройки: Uн, общий К прокладки, таблица Кс быт, мест на лист схемы — лист «Таблицы_норм» (BF4, BQ29, BQ30, BP4:BQ11).

Sheet Коды
A1: КОДЫ ПОТРЕБИТЕЛЕЙ, УГО, ЭТАЖИ, КАБЕЛИ — новая строка дописывается сразу под таблицей, таблица растёт сама
A3: Код | B3: Наименование | C3: Опуск, м | D3: 1 - этаж/2 - шлейф | E3: Пуск: 1 нет/2 двигатель/3 свет | F3: Марка кабеля | G3: Жил | H3: Напряжение | I3: Фаз | J3: Сечение | K3: Вид нагрузки | L3: Группа Кс | M3: Пожарная | O3: Код (УГО) | P3: УГО | Q3: Дифзащита, мА (да = 30) | R3: Мин. автомат, А | S3: 3L клемм на линию | U3: Этаж | V3: Название этажа | W3: Подъём, м | X3: По другим этажам, м | Z3: Обозначение | AA3: Кабель | AB3: Сечение в марке (1 да / 2 нет)
A4: Ввод | B4: Ввод питающей линии | C4: 5 | D4: 1 | E4: 1 | L4: Нет | M4: нет | O4: Ввод | U4: 0 | V4: Цокольный этаж | Z4: мс | AA4: ВВГнг(А)-LS | AB4: 1
A5: На ИБП | B5: Питание на ИБП | C5: 5 | D5: 1 | E5: 1 | L5: Нет | M5: нет | O5: На ИБП | U5: 1 | Z5: мфр | AA5: ВВГнг(А)-FRLS | AB5: 1
A6: От ИБП | B6: Питание от ИБП | C6: 5 | D6: 1 | E6: 1 | L6: Нет | M6: нет | O6: От ИБП | U6: 2 | Z6: ютп | AA6: FTP-Cat.6-4х2х0.52 | AB6: 2
A7: R | B7: Розеточная группа | C7: 2 | D7: 1 | E7: 1 | F7: мс | G7: 3 | H7: 230 | I7: 1 | J7: 2.5 | K7: Розеточная сеть и бытовые приборы | L7: Быт | M7: нет | O7: R | P7: Розетка | Q7: да | R7: 16 | U7: 3 | V7: Третий этаж | Z7: ре | AA7: ПуГВ | AB7: 1
A8: L | B8: Группа освещения | C8: 1 | D8: 1 | E8: 1 | F8: мс | G8: 3 | H8: 230 | I8: 1 | J8: 1.5 | K8: Рабочее освещение | L8: Быт | M8: нет | O8: L | P8: Светильник | Q8: нет | R8: 10 | Z8: мб | AA8: ВБШвнг(А)-LS | AB8: 1
A9: LED | B9: Светодиодное освещение | C9: 1 | D9: 1 | E9: 1 | K9: Рабочее освещение | L9: Быт | M9: нет | O9: LED | P9: Светильник | Q9: нет | R9: 10 | Z9: кмс | AA9: КГВВнг(А)-LS | AB9: 1
A10: R.ШТК | B10: Шкаф слаботочных систем | C10: 2 | D10: 1 | E10: 1 | K10: Слаботочные системы, автоматизация, KNX | L10: Пост | M10: нет | O10: R.ШТК | P10: Розетка | Q10: нет | R10: 16 | Z10: кмб | AA10: КВБбШвнг(А)-LS 14x2.5 | AB10: 2
A11: R.ЩОПС | B11: Щит охранно-пожарной сигнализации | C11: 2 | D11: 1 | E11: 1 | K11: Системы безопасности и связи | L11: Пост | M11: нет | O11: R.ЩОПС | P11: Розетка | Q11: нет | R11: 16 | Z11: мшф | AA11: ППГнг(А)-HF | AB11: 1
A12: АСУ | B12: Питание системы автоматизации | C12: 1 | D12: 1 | E12: 1 | K12: Слаботочные системы, автоматизация, KNX | L12: Пост | M12: нет | O12: АСУ | P12: Прочее (прямоуг. с подписью) | Q12: нет | Z12: кн | AA12: J-Y(St)Y 2х2х0.8 | AB12: 2
A13: PS-KNX | B13: Блок питания шины KNX | C13: 1 | D13: 1 | E13: 1 | K13: Слаботочные системы, автоматизация, KNX | L13: Пост | M13: нет | O13: PS-KNX | Z13: кф | AA13: КИПЭВ 2х2х0.6 | AB13: 2
A14: В | B14: Вытяжной вентилятор | C14: 1 | D14: 1 | E14: 1 | K14: Вентиляция | L14: Быт | M14: нет | O14: В | P14: Привод (двигатель) | Q14: нет | Z14: кс | AA14: КСПВГ 4х0.35 | AB14: 2
A15: ТП | B15: Теплый пол | C15: 2 | D15: 1 | E15: 1 | K15: Электрический тёплый пол | L15: Быт | M15: нет | O15: ТП | P15: Нагреватель | Q15: да | Z15: кмс1 | AA15: КГВВнг(А)-LS (5х1)
A16: ЭK | B16: Шаровый электрокран | C16: 1 | D16: 1 | E16: 1 | K16: Приводы (шторы, ворота, краны) | L16: Пост | M16: нет | O16: ЭK | P16: Клапан | Q16: нет
A17: TE-O | B17: Управление сервоприводом отопления | C17: 1 | D17: 1 | E17: 1 | K17: Слаботочные системы, автоматизация, KNX | L17: Пост | M17: нет | O17: TE-O
A18: SH | B18: Моторзированная нагрузка | C18: 1 | D18: 1 | E18: 1 | K18: Приводы (шторы, ворота, краны) | L18: Быт | M18: нет | O18: SH | P18: Привод (двигатель) | Q18: нет | S18: 2
A19: DALI | B19: Контролер DALI | C19: 1 | D19: 2 | E19: 1 | K19: Рабочее освещение | L19: Быт | M19: нет | O19: DALI | P19: Светильник | Q19: нет | R19: 10
A20: АПС | B20: Реле АПС | C20: 1 | D20: 1 | E20: 1 | K20: Системы безопасности и связи | L20: Пост | M20: нет | O20: АПС
A21: K | B21: Внутренний блок кондиционера | C21: 1 | D21: 1 | E21: 1 | K21: Кондиционирование и увлажнение | L21: Быт | M21: нет | O21: K | P21: Привод (двигатель) | Q21: нет
A22: ПВ | B22: Приточно-вытяжная установка | C22: 1 | D22: 1 | E22: 1 | K22: Вентиляция | L22: Сил | M22: нет | O22: ПВ
A23: УВ | B23: Увлажнитель | C23: 1 | D23: 1 | E23: 1 | K23: Кондиционирование и увлажнение | L23: Быт | M23: нет | O23: УВ | P23: Привод (двигатель) | Q23: нет
A24: ПН | B24: Проточный водонагреватель | C24: 1 | D24: 1 | E24: 1 | K24: Водонагреватели | L24: Быт | M24: нет | O24: ПН | P24: Нагреватель | Q24: да
A25: WD | B25: Датчик протечки | C25: 0 | D25: 1 | E25: 1 | K25: Слаботочные системы, автоматизация, KNX | L25: Пост | M25: нет | O25: WD
A26: VK | B26: Выключатель нажимной | C26: 0 | D26: 1 | E26: 1 | K26: Слаботочные системы, автоматизация, KNX | L26: Пост | M26: нет | O26: VK
A27: КУП | B27: Коробка уравнивания потенциалов | C27: 1 | D27: 1 | E27: 1 | L27: Нет | M27: нет | O27: КУП
A28: PE | B28: Заземляющая шина | C28: 1 | D28: 1 | E28: 1 | L28: Нет | M28: нет | O28: PE
A29: R.GSM | B29: Щит усиления соловой связи | C29: 1 | D29: 1 | E29: 1 | K29: Системы безопасности и связи | L29: Пост | M29: нет | O29: R.GSM | P29: Розетка | Q29: нет | R29: 16
A30: TE-ТП | B30: Управление сервоприводом теплого пола | C30: 1 | D30: 1 | E30: 1 | K30: Слаботочные системы, автоматизация, KNX | L30: Пост | M30: нет | O30: TE-ТП
A31: ПУ | B31: Приточная установка | C31: 1 | D31: 1 | E31: 1 | K31: Вентиляция | L31: Сил | M31: нет | O31: ПУ | P31: Привод (двигатель) | Q31: нет
A32: LD | B32: Питание подсветок | C32: 3 | D32: 1 | E32: 1 | K32: Рабочее освещение | L32: Быт | M32: нет | O32: LD | P32: Светильник | Q32: нет | R32: 10
A33: КМН | B33: Электрокамин | C33: 1 | D33: 1 | E33: 1 | K33: Электроотопление (конвекторы, камины) | L33: Быт | M33: нет | O33: КМН | P33: Нагреватель | Q33: нет
O34: Доп. коды (нет в списке P — латиница/кириллица и т.п.)
O35: К | P35: Привод (двигатель) | Q35: нет
O36: ЭК | P36: Клапан | Q36: нет
O37: TE | P37: Сервопривод | Q37: нет
O38: ТЕ | P38: Сервопривод | Q38: нет

Sheet Щиты
B1: КАК ЗАПОЛНЯТЬ ЛИСТ «ЩИТЫ»
B2: ЩИТЫ: одна строка — один щит объекта. Жёлтые столбцы — ввод, серые — результат. Свёрнутые столбцы (кнопка «+» над таблицей) — подробности расчёта.
B3: Для КАЖДОГО щита: Щит (имя, как в «Линиях»), Вводов (1/2/3), АВР (да/нет), ИБП от (Ввод 1/2/3), Мест под вводной узел (обычно 15).
B4: «Питается от» обычно НЕ заполняйте: книга сама находит линию-фидер в «Линиях» (номер линии = имя щита, или столбец «Питает щит»).
B5: Только для ВРУ / ГРЩ (щит без вышестоящего): данные сети — Iкз min и Iкз max от сетевой организации, или «ТП» и мощность трансформатора; питающий кабель и аппарат. Без них ток КЗ не считается ни в одном щите.
B6: Результат: Руст, Рр, Iр, cos φ — щит вместе со всеми нижестоящими; ΔU до шин и Iкз — от ВРУ по фидерам; «Категория шины «Ввод»» — какую категорию даёт схема; «Замечания щита» — что исправить.
A8: СХЕМА ЩИТА (ввод для каждого щита) | G8: ТОЛЬКО ДЛЯ ВРУ / ГРЩ: сеть и питающий кабель (ввод) | U8: РЕЗУЛЬТАТ (считается сам)
A9: Щит | B9: Питается от | C9: Вводов | D9: АВР | E9: ИБП от | F9: Мест под вводной узел | G9: Питание: от (ТП / сеть) | H9: ΔU до питающего, % | I9: Iкз min от сети, А | J9: Iкз max от сети, кА | K9: Sтр, кВА | L9: Схема тр-ра | M9: Питающий кабель: S, мм² | N9: Жил | O9: Кабелей параллельно | P9: Длина, м | Q9: Материал | R9: In питающего аппарата, А | S9: Хар-ка аппарата | T9: Кат. питающей линии (ручн.) | U9: Питается от (итог) | V9: Замечания щита | W9: Линия фидера | X9: Руст, кВт | Y9: Рр, кВт | Z9: Iр, А | AA9: cos φ | AB9: ΔU до шин, % | AC9: Iкз min на шинах, А | AD9: Iкз max на шинах, кА | AE9: Категория шины «Ввод» | AF9: Путь | AG9: Корень | AH9: Уровень | AI9: _строка фидера | AJ9: _Руст собств | AK9: _быт собств | AL9: _сил собств | AM9: _пост собств | AN9: _P собств | AO9: _Pcos собств | AP9: _отоп собств | AQ9: _внг собств | AR9: Руст быт, кВт | AS9: Кс быт | AT9: Рр сил, кВт | AU9: Руст пост, кВт | AV9: Р отопления, кВт | AW9: Рр ВНГ, кВт | AX9: _n силовых | AY9: Кс силовых (табл. 7.5) | AZ9: Ко | BA9: Кс итог | BB9: P L1, кВт | BC9: P L2, кВт | BD9: P L3, кВт | BE9: _ΔU фидера | BF9: _ΔU пит. линии | BG9: _ΔU источника | BH9: _петля пит. кабеля | BI9: _Zсети | BJ9: _Zисточника | BK9: _Zфидера | BL9: Zпетли на шинах, Ом | BM9: _Zmax сети | BN9: _Zmax источника | BO9: _Zmax фидера | BP9: Zmax на шинах, Ом | BQ9: _ранг собств | BR9: Высшая категория нагрузки | BS9: Категория фидера | BT9: Iпуск max, А | BU9: Источник фидера | BV9: Пожарный фидер | BW9: Не обеспечено, линий
A10: ЩР | C10: 1 | D10: нет | E10: Ввод 1 | F10: 18 | U10: {=IF(Щиты[[#This Row],[Питается от]]<>"",Щиты[[#This Row],[Питается от]],IFERROR(INDEX(Линии[Щит],Щиты[[#This Row],[_строка фидера]]),""))} | V10: =_xlfn.TEXTJOIN("; ",TRUE,IF(AND(Щиты[[#This Row],[Питается от (итог)]]="",Щиты[[#This Row],[Zпетли на шинах, Ом]]=""),"нет данных сети для ТКЗ: введите Iкз от сетевой организации или трансформатор",""),IF(AND(Щиты[[#This Row],[Категория фидера]]<>"",IFERROR(MATCH(Щиты[[#This Row],[Категория фидера]],{"III","II","I","I особая"},0),1)<IFERROR(MATCH(Щиты[[#This Row],[Высшая категория нагрузки]],{"III","II","I","I особая"},0),1)),"фидер "&Щиты[[#This Row],[Категория фидера]]&" ниже нагрузки "&Щиты[[#This Row],[Высшая категория нагрузки]],""),IF(Щиты[[#This Row],[Не обеспечено, линий]]>0,"не обеспечена категория у "&Щиты[[#This Row],[Не обеспечено, линий]]&" линий",""),IF(AND(Щиты[[#This Row],[Питается от]]<>"",Щиты[[#This Row],[_строка фидера]]=""),"нет линии-фидера в «Линиях»: номер линии = имя щита или столбец «Питает щит»",""),IF(AND(ISNUMBER(Щиты[[#This Row],[ΔU до шин, %]]),Щиты[[#This Row],[ΔU до шин, %]]>4),"ΔU до шин "&FIXED(Щиты[[#This Row],[ΔU до шин, %]],2)&" % > 4 %","")) -> нет данных сети для ТКЗ: введите Iкз от сетевой организации или трансформатор | W10: {=IF(Щиты[[#This Row],[_строка фидера]]="","",INDEX(Линии[Номер линии],Щиты[[#This Row],[_строка фидера]]))} | X10: =SUMIFS(Щиты[_Руст собств],Щиты[Путь],"*|"&Щиты[[#This Row],[Щит]]&"|*") -> 5.52 | Y10: =k_пк*Щиты[[#This Row],[Руст быт, кВт]]*Щиты[[#This Row],[Кс быт]]+Щиты[[#This Row],[Ко]]*Щиты[[#This Row],[Рр сил, кВт]]+Щиты[[#This Row],[Руст пост, кВт]]+Щиты[[#This Row],[Р отопления, кВт]]+Щиты[[#This Row],[Рр ВНГ, кВт]] -> 4.416 | Z10: =IFERROR(MAX(MAX(Щиты[[#This Row],[P L1, кВт]],Щиты[[#This Row],[P L2, кВт]],Щиты[[#This Row],[P L3, кВт]])*Щиты[[#This Row],[Кс итог]]/((Uн_лин*1000/SQRT(3))/1000*Щиты[[#This Row],[cos φ]]),Щиты[[#This Row],[Рр, кВт]]/(SQRT(3)*Uн_лин*Щиты[[#This Row],[cos φ]])),0) -> 7.2928455 | AA10: =IFERROR(SUMIFS(Щиты[_Pcos собств],Щиты[Путь],"*|"&Щиты[[#This Row],[Щит]]&"|*")/SUMIFS(Щиты[_P собств],Щиты[Путь],"*|"&Щиты[[#This Row],[Щит]]&"|*"),0.95) -> 0.95 | AB10: {=SUMPRODUCT(--ISNUMBER(SEARCH("|"&Щиты[Щит]&"|",Щиты[[#This Row],[Путь]])),IFERROR(--Щиты[_ΔU фидера],0)+IFERROR(--Щиты[_ΔU источника],0))} -> 0 | AC10: =IF(ISNUMBER(Щиты[[#This Row],[Zпетли на шинах, Ом]]),c_min*(Uн_лин*1000/SQRT(3))/Щиты[[#This Row],[Zпетли на шинах, Ом]],"") | AD10: =IF(ISNUMBER(Щиты[[#This Row],[Zmax на шинах, Ом]]),1.05*(Uн_лин*1000/SQRT(3))/Щиты[[#This Row],[Zmax на шинах, Ом]]/1000,"") | AE10: {=_xlfn.LET(_xlpm.w,_xlfn.TEXTSPLIT(Щиты[[#This Row],[Путь]],"|"),_xlpm.names,_xlfn._xlws.FILTER(_xlpm.w,_xlpm.w<>""),_xlfn.REDUCE("",_xlpm.names,_xlfn.LAMBDA(_xlpm.acc,_xlpm.nm,_xlfn.LET(_xlpm.inp,N(_xlfn.XLOOKUP(_xlpm.nm,Щиты[Щит],Щиты[Вводов],1)),_xlpm.avr,LOWER(TRIM(_xlfn.XLOOKUP(_xlpm.nm,Щиты[Щит],Щиты[АВР],"нет")&"")),_xlpm.own,IF(_xlpm.inp>=2,IF(_xlpm.avr="да","I","II"),"III"),_xlpm.fr,_xlfn.XLOOKUP(_xlpm.nm,Щиты[Щит],Щиты[_строка фидера],""),_xlpm.bt,IF(_xlpm.fr="","",INDEX(Линии[Тип шины],_xlpm.fr)&""),_xlpm.man,TRIM(_xlfn.XLOOKUP(_xlpm.nm,Щиты[Щит],Щиты[Кат. питающей линии (ручн.)],"")&""),_xlpm.up,IF(_xlpm.acc="",_xlpm.man,IF(OR(_xlpm.bt="ИБП",_xlpm.bt="ДГУ"),"I особая",IF(_xlpm.bt="Одиночная","III",_xlpm.acc))),IF(_xlpm.own<>"III",_xlpm.own,IF(OR(_xlpm.up="I особая",_xlpm.up="I",_xlpm.up="II"),"II","III"))))))} -> III | AF10: {=_xlfn.LET(_xlpm.f,_xlfn.LAMBDA(_xlpm.x,IF(_xlpm.x="","",_xlfn.XLOOKUP(_xlpm.x,Щиты[Щит],Щиты[Питается от (итог)],"")&"")),_xlpm.п0,Щиты[[#This Row],[Щит]],_xlpm.п1,_xlpm.f(_xlpm.п0),_xlpm.п2,_xlpm.f(_xlpm.п1),_xlpm.п3,_xlpm.f(_xlpm.п2),_xlpm.п4,_xlpm.f(_xlpm.п3),_xlpm.п5,_xlpm.f(_xlpm.п4),_xlpm.п6,_xlpm.f(_xlpm.п5),_xlpm.п7,_xlpm.f(_xlpm.п6),"|"&_xlfn.TEXTJOIN("|",TRUE,_xlpm.п7,_xlpm.п6,_xlpm.п5,_xlpm.п4,_xlpm.п3,_xlpm.п2,_xlpm.п1,_xlpm.п0)&"|")} -> |ЩР| | AG10: =_xlfn.TEXTBEFORE(MID(Щиты[[#This Row],[Путь]],2,999),"|") -> ЩР | AH10: =LEN(Щиты[[#This Row],[Путь]])-LEN(SUBSTITUTE(Щиты[[#This Row],[Путь]],"|",""))-2 -> 0 | AI10: =IFERROR(_xlfn.XMATCH(Щиты[[#This Row],[Щит]],Линии[_фидер]),"") | AJ10: =SUMIFS(Линии[_Руст (без Нет)],Линии[Щит],Щиты[[#This Row],[Щит]]) -> 5.52 | AK10: =SUMIFS(Линии[_Руст быт],Линии[Щит],Щиты[[#This Row],[Щит]]) -> 5.52 | AL10: =SUMIFS(Линии[_Рр сил],Линии[Щит],Щиты[[#This Row],[Щит]]) -> 0 | AM10: =SUMIFS(Линии[_Руст пост],Линии[Щит],Щиты[[#This Row],[Щит]]) -> 0 | AN10: =SUMIFS(Линии[_P для cos],Линии[Щит],Щиты[[#This Row],[Щит]]) -> 5.52 | AO10: =SUMIFS(Линии[_P·cos],Линии[Щит],Щиты[[#This Row],[Щит]]) -> 5.244 | AP10: =SUMIFS(Линии[_Р отопления],Линии[Щит],Щиты[[#This Row],[Щит]]) -> 0 | AQ10: =SUMIFS(Линии[_Рр ВНГ],Линии[Щит],Щиты[[#This Row],[Щит]]) -> 0 | AR10: =SUMIFS(Щиты[_быт собств],Щиты[Путь],"*|"&Щиты[[#This Row],[Щит]]&"|*") -> 5.52 | AS10: {=_xlfn.LET(_xlpm.x,Щиты[[#This Row],[Руст быт, кВт]],_xlpm.m,MATCH(_xlpm.x,Кс_Р,1),IF(_xlpm.x>=INDEX(Кс_Р,ROWS(Кс_Р)),INDEX(Кс_К,ROWS(Кс_К)),INDEX(Кс_К,_xlpm.m)+(_xlpm.x-INDEX(Кс_Р,_xlpm.m))*(INDEX(Кс_К,_xlpm.m+1)-INDEX(Кс_К,_xlpm.m))/(INDEX(Кс_Р,_xlpm.m+1)-INDEX(Кс_Р,_xlpm.m))))} -> 0.8 | AT10: =SUMIFS(Щиты[_сил собств],Щиты[Путь],"*|"&Щиты[[#This Row],[Щит]]&"|*") -> 0 | AU10: =SUMIFS(Щиты[_пост собств],Щиты[Путь],"*|"&Щиты[[#This Row],[Щит]]&"|*") -> 0 | AV10: =SUMIFS(Щиты[_отоп собств],Щиты[Путь],"*|"&Щиты[[#This Row],[Щит]]&"|*") -> 0 | AW10: =SUMIFS(Щиты[_внг собств],Щиты[Путь],"*|"&Щиты[[#This Row],[Щит]]&"|*") -> 0 | AX10: =COUNTIFS(Линии[Щит],Щиты[[#This Row],[Щит]],Линии[Группа Кс (итог)],"Сил") -> 0 | AY10: {=_xlfn.LET(_xlpm.n,Щиты[[#This Row],[_n силовых]],IF(_xlpm.n<=1,1,IF(_xlpm.n>=MAX(Кс75_n),INDEX(Кс75_k,ROWS(Кс75_k)),_xlfn.LET(_xlpm.m,MATCH(_xlpm.n,Кс75_n,1),INDEX(Кс75_k,_xlpm.m)+(_xlpm.n-INDEX(Кс75_n,_xlpm.m))*(INDEX(Кс75_k,_xlpm.m+1)-INDEX(Кс75_k,_xlpm.m))/(INDEX(Кс75_n,_xlpm.m+1)-INDEX(Кс75_n,_xlpm.m))))))} -> 1 | AZ10: =IF(Методика="нормы 2026",IF(AND(Щиты[[#This Row],[Руст быт, кВт]]>0,Щиты[[#This Row],[Рр сил, кВт]]>0),Ко_сил,1),Ко_сил) -> 1 | BA10: =IF(Щиты[[#This Row],[Руст, кВт]]=0,0,Щиты[[#This Row],[Рр, кВт]]/Щиты[[#This Row],[Руст, кВт]]) -> 0.8 | BB10: =SUMIFS(Линии[Р, кВт],Линии[Щит],Щиты[[#This Row],[Щит]],Линии[Фаза],"L1,L2,L3",Линии[Группа Кс (итог)],"<>Нет")/3+SUMIFS(Линии[Р, кВт],Линии[Щит],Щиты[[#This Row],[Щит]],Линии[Фаза],"L1",Линии[Группа Кс (итог)],"<>Нет") -> 1.58 | BC10: =SUMIFS(Линии[Р, кВт],Линии[Щит],Щиты[[#This Row],[Щит]],Линии[Фаза],"L1,L2,L3",Линии[Группа Кс (итог)],"<>Нет")/3+SUMIFS(Линии[Р, кВт],Линии[Щит],Щиты[[#This Row],[Щит]],Линии[Фаза],"L2",Линии[Группа Кс (итог)],"<>Нет") -> 1.94 | BD10: =SUMIFS(Линии[Р, кВт],Линии[Щит],Щиты[[#This Row],[Щит]],Линии[Фаза],"L1,L2,L3",Линии[Группа Кс (итог)],"<>Нет")/3+SUMIFS(Линии[Р, кВт],Линии[Щит],Щиты[[#This Row],[Щит]],Линии[Фаза],"L3",Линии[Группа Кс (итог)],"<>Нет") -> 2 | BE10: {=IF(Щиты[[#This Row],[_строка фидера]]="","",INDEX(Линии[ΔU, %],Щиты[[#This Row],[_строка фидера]]))} | BF10: =IF(OR(N(Щиты[[#This Row],[Питающий кабель: S, мм²]])=0,N(Щиты[[#This Row],[Длина, м]])=0),0,(IF(Щиты[[#This Row],[Материал]]="алюминий",0.036,0.0225)*N(Щиты[[#This Row],[Длина, м]])/(N(Щиты[[#This Row],[Питающий кабель: S, мм²]])*MAX(1,N(Щиты[[#This Row],[Кабелей параллельно]])))*Щиты[[#This Row],[cos φ]]+0.00008*N(Щиты[[#This Row],[Длина, м]])/MAX(1,N(Щиты[[#This Row],[Кабелей параллельно]]))*SIN(ACOS(Щиты[[#This Row],[cos φ]])))*Щиты[[#This Row],[Iр, А]]/(Uн_лин*1000/SQRT(3))*100) -> 0 | BG10: =IF(Щиты[[#This Row],[Питается от (итог)]]<>"",0,IF(LEFT(UPPER(TRIM(Щиты[[#This Row],[Питание: от (ТП / сеть)]])),2)="ТП",0,N(Щиты[[#This Row],[ΔU до питающего, %]])+Щиты[[#This Row],[_ΔU пит. линии]])) -> 0 | BH10: =IF(N(Щиты[[#This Row],[Питающий кабель: S, мм²]])>0,2*IF(Щиты[[#This Row],[Материал]]="алюминий",ρкз_Al,ρкз_Cu)*N(Щиты[[#This Row],[Длина, м]])/(N(Щиты[[#This Row],[Питающий кабель: S, мм²]])*MAX(1,N(Щиты[[#This Row],[Кабелей параллельно]]))),0) -> 0 | BI10: =IF(Щиты[[#This Row],[Питается от (итог)]]<>"","",IF(N(Щиты[[#This Row],[Iкз min от сети, А]])>0,c_min*(Uн_лин*1000/SQRT(3))/Щиты[[#This Row],[Iкз min от сети, А]],IF(AND(LEFT(UPPER(TRIM(Щиты[[#This Row],[Питание: от (ТП / сеть)]])),2)="ТП",N(Щиты[[#This Row],[Sтр, кВА]])>0),0.055*Uн_лин^2/(Щиты[[#This Row],[Sтр, кВА]]/1000)*IF(Щиты[[#This Row],[Схема тр-ра]]="Y/Yн",3,1),""))) | BJ10: =IF(Щиты[[#This Row],[_Zсети]]="","",Щиты[[#This Row],[_Zсети]]+Щиты[[#This Row],[_петля пит. кабеля]]) | BK10: {=IF(Щиты[[#This Row],[_строка фидера]]="","",INDEX(Линии[_Zкабеля],Щиты[[#This Row],[_строка фидера]]))} | BL10: {=IF(_xlfn.XLOOKUP(Щиты[[#This Row],[Корень]],Щиты[Щит],Щиты[_Zисточника],"")="","",SUMPRODUCT(--ISNUMBER(SEARCH("|"&Щиты[Щит]&"|",Щиты[[#This Row],[Путь]])),IFERROR(--Щиты[_Zисточника],0)+IFERROR(--Щиты[_Zфидера],0))+SUMPRODUCT(--ISNUMBER(SEARCH("|"&Щиты[Щит]&"|",Щиты[[#This Row],[Путь]])))*R_пер)} | BM10: =IF(Щиты[[#This Row],[Питается от (итог)]]<>"","",IF(N(Щиты[[#This Row],[Iкз max от сети, кА]])>0,1.05*(Uн_лин*1000/SQRT(3))/(Щиты[[#This Row],[Iкз max от сети, кА]]*1000),IF(AND(LEFT(UPPER(TRIM(Щиты[[#This Row],[Питание: от (ТП / сеть)]])),2)="ТП",N(Щиты[[#This Row],[Sтр, кВА]])>0),0.055*Uн_лин^2/(Щиты[[#This Row],[Sтр, кВА]]/1000),""))) | BN10: =IF(Щиты[[#This Row],[_Zmax сети]]="","",Щиты[[#This Row],[_Zmax сети]]+IF(N(Щиты[[#This Row],[Питающий кабель: S, мм²]])>0,IF(Щиты[[#This Row],[Материал]]="алюминий",0.028,0.0175)*N(Щиты[[#This Row],[Длина, м]])/(N(Щиты[[#This Row],[Питающий кабель: S, мм²]])*MAX(1,N(Щиты[[#This Row],[Кабелей параллельно]]))),0)) | BO10: {=IF(Щиты[[#This Row],[_строка фидера]]="","",INDEX(Линии[_Zmax кабеля],Щиты[[#This Row],[_строка фидера]]))} | BP10: {=IF(_xlfn.XLOOKUP(Щиты[[#This Row],[Корень]],Щиты[Щит],Щиты[_Zmax источника],"")="","",SUMPRODUCT(--ISNUMBER(SEARCH("|"&Щиты[Щит]&"|",Щиты[[#This Row],[Путь]])),IFERROR(--Щиты[_Zmax источника],0)+IFERROR(--Щиты[_Zmax фидера],0)))} | BQ10: =_xlfn.MAXIFS(Линии[_ранг для фидера],Линии[Щит],Щиты[[#This Row],[Щит]]) -> 1 | BR10: {=IFERROR(INDEX({"III","II","I","I особая"},MAX(1,_xlfn.MAXIFS(Щиты[_ранг собств],Щиты[Путь],"*|"&Щиты[[#This Row],[Щит]]&"|*"))),"III")} -> III | BS10: {=IF(Щиты[[#This Row],[_строка фидера]]="","",INDEX(Линии[Категория (итог)],Щиты[[#This Row],[_строка фидера]]))} | BT10: =_xlfn.MAXIFS(Линии[Iпуск, А],Линии[Щит],Щиты[[#This Row],[Щит]]) -> 0 | BU10: {=IF(Щиты[[#This Row],[_строка фидера]]="","",INDEX(Линии[Источник для режимов],Щиты[[#This Row],[_строка фидера]]))} | BV10: {=IF(Щиты[[#This Row],[_строка фидера]]="","",INDEX(Линии[Пожарная (итог)],Щиты[[#This Row],[_строка фидера]]))} | BW10: =COUNTIFS(Линии[Щит],Щиты[[#This Row],[Щит]],Линии[Категория: проверка],"НЕ ОБЕСПЕЧЕНА") -> 0

Sheet Итоги_щитов
B1: ИТОГИ ПО ЩИТАМ (данные под однолинейку)
B3: Щит: | C3: ЩР | F3: Щит | G3: Питается от | H3: Руст, кВт | I3: Кс итог | J3: Рр, кВт | K3: cos φ | L3: Iр, А | M3: P L1, кВт | N3: P L2, кВт | O3: P L3, кВт | P3: ΔU до шин, % | Q3: Iкз min, А | R3: Iкз max, кА | S3: Категория
B4: Питается от | C4: =_xlfn.XLOOKUP($C$3,Щиты[Щит],Щиты[Питается от (итог)],"") | F4: {=_xlfn.HSTACK(Щиты[Щит],Щиты[Питается от (итог)],Щиты[Руст, кВт],Щиты[Кс итог],Щиты[Рр, кВт],Щиты[cos φ],Щиты[Iр, А],Щиты[P L1, кВт],Щиты[P L2, кВт],Щиты[P L3, кВт],Щиты[ΔU до шин, %],Щиты[Iкз min на шинах, А],Щиты[Iкз max на шинах, кА],Щиты[Категория шины «Ввод»])} -> ЩР | H4: 5.52 | I4: 0.8 | J4: 4.416 | K4: 0.95 | L4: 7.2928455 | M4: 1.58 | N4: 1.94 | O4: 2 | P4: 0 | S4: III
B5: Руст | C5: =_xlfn.XLOOKUP($C$3,Щиты[Щит],Щиты[Руст, кВт],"") -> 5.52 | D5: кВт
B6: в т. ч. бытовая | C6: =_xlfn.XLOOKUP($C$3,Щиты[Щит],Щиты[Руст быт, кВт],"") -> 5.52 | D6: кВт
B7: Кс быт (табл. 7.2) | C7: =_xlfn.XLOOKUP($C$3,Щиты[Щит],Щиты[Кс быт],"") -> 0.8
B8: Рр силовой (Σ P·Кс) | C8: =_xlfn.XLOOKUP($C$3,Щиты[Щит],Щиты[Рр сил, кВт],"") -> 0 | D8: кВт
B9: Руст постоянной | C9: =_xlfn.XLOOKUP($C$3,Щиты[Щит],Щиты[Руст пост, кВт],"") -> 0 | D9: кВт
B10: Р отопления (Кс 1) | C10: =_xlfn.XLOOKUP($C$3,Щиты[Щит],Щиты[Р отопления, кВт],"") -> 0 | D10: кВт
B11: Рр ВНГ (×0,7) | C11: =_xlfn.XLOOKUP($C$3,Щиты[Щит],Щиты[Рр ВНГ, кВт],"") -> 0 | D11: кВт
B12: Ко | C12: =_xlfn.XLOOKUP($C$3,Щиты[Щит],Щиты[Ко],"") -> 1
B13: Рр | C13: =_xlfn.XLOOKUP($C$3,Щиты[Щит],Щиты[Рр, кВт],"") -> 4.416 | D13: кВт
B14: Кс итог = Рр / Руст | C14: =_xlfn.XLOOKUP($C$3,Щиты[Щит],Щиты[Кс итог],"") -> 0.8
B15: cos φ | C15: =_xlfn.XLOOKUP($C$3,Щиты[Щит],Щиты[cos φ],"") -> 0.95
B16: Qр = Рр·tg φ | C16: =IFERROR(C13*TAN(ACOS(C15)),"") -> 1.451469 | D16: квар
B17: Sр | C17: =IFERROR(SQRT(C13^2+C16^2),"") -> 4.6484211 | D17: кВА
B18: Iр (по наиб. нагруженной фазе) | C18: =_xlfn.XLOOKUP($C$3,Щиты[Щит],Щиты[Iр, А],"") -> 7.2928455 | D18: А
B19: P L1 / L2 / L3 | C19: =IFERROR(FIXED(_xlfn.XLOOKUP($C$3,Щиты[Щит],Щиты[P L1, кВт],""),2)&" / "&FIXED(_xlfn.XLOOKUP($C$3,Щиты[Щит],Щиты[P L2, кВт],""),2)&" / "&FIXED(_xlfn.XLOOKUP($C$3,Щиты[Щит],Щиты[P L3, кВт],""),2),"") -> 1,58 / 1,94 / 2,00 | D19: кВт
B20: L1р / L2р / L3р (P·Кс итог) | C20: =IFERROR(FIXED(_xlfn.XLOOKUP($C$3,Щиты[Щит],Щиты[P L1, кВт],"")*C14,2)&" / "&FIXED(_xlfn.XLOOKUP($C$3,Щиты[Щит],Щиты[P L2, кВт],"")*C14,2)&" / "&FIXED(_xlfn.XLOOKUP($C$3,Щиты[Щит],Щиты[P L3, кВт],"")*C14,2),"") -> 1,26 / 1,55 / 1,60 | D20: кВт
B21: Перекос фаз (max−min)/max | C21: =IFERROR(_xlfn.LET(_xlpm.a,_xlfn.XLOOKUP($C$3,Щиты[Щит],Щиты[P L1, кВт],""),_xlpm.b,_xlfn.XLOOKUP($C$3,Щиты[Щит],Щиты[P L2, кВт],""),_xlpm.cc,_xlfn.XLOOKUP($C$3,Щиты[Щит],Щиты[P L3, кВт],""),(MAX(_xlpm.a,_xlpm.b,_xlpm.cc)-MIN(_xlpm.a,_xlpm.b,_xlpm.cc))/MAX(_xlpm.a,_xlpm.b,_xlpm.cc)*100),"") -> 21 | D21: %
B22: Наибольший пусковой ток | C22: =_xlfn.XLOOKUP($C$3,Щиты[Щит],Щиты[Iпуск max, А],"") -> 0 | D22: А
B23: Компенсация реактивной мощности | C23: =IFERROR(IF((TAN(ACOS(C15))-0.35)*C13<50,"не требуется (< 50 квар, СП 256 п. 7.3)",FIXED((TAN(ACOS(C15))-0.35)*C13,1)&" квар"),"") -> не требуется (< 50 квар, СП 256 п. 7.3)
B24: ΔU от ВРУ до шин | C24: =_xlfn.XLOOKUP($C$3,Щиты[Щит],Щиты[ΔU до шин, %],"") -> 0 | D24: %
B25: Iкз min (1ф) на шинах | C25: =_xlfn.XLOOKUP($C$3,Щиты[Щит],Щиты[Iкз min на шинах, А],"") | D25: А
B26: Iкз max (3ф) на шинах | C26: =_xlfn.XLOOKUP($C$3,Щиты[Щит],Щиты[Iкз max на шинах, кА],"") | D26: кА
B27: Категория шины «Ввод» | C27: =_xlfn.XLOOKUP($C$3,Щиты[Щит],Щиты[Категория шины «Ввод»],"") -> III
B29: Карточка слева — для таблицы под однолинейкой выбранного щита (скопируйте B4:D27 как значения). Справа — все щиты объекта.

Sheet Шины
B1: КАК ЗАПОЛНЯТЬ ЛИСТ «ШИНЫ»
B2: ШИНЫ: нужен, только если тип шины НЕ определяется сам. Обычно лист пустой.
B3: Как определяется сам: в «Линиях» в столбце «Шина» (в строке с автоматом) пишется имя шины. Имя содержит «ИБП» → шина ИБП (категория I особая); «ДГУ» → шина ДГУ; иначе — основная шина секции линии (Ввод 1/2/3 по столбцу «Секция»).
B4: Когда заполнять: имя шины не говорит о её типе. Пример: шина «ЩГП» питается от ИБП → строка: Шина = ЩГП, Щит = ЩР-1 (или пусто — для всех щитов), Тип = ИБП. Пример: «Шина вентиляции» без резерва → Тип = Одиночная (категория III).
B5: Типы: Ввод 1 / Ввод 2 / Ввод 3 — источник по секции; ИБП, ДГУ — отдельный источник (I особая); Одиночная — без резерва (III). Тип влияет на категорию линий и на режимы (лист «Режимы»).
A7: ШИНЫ: тип шины вручную. Без строки здесь — по имени (ИБП / ДГУ) или по секции линии (Ввод 1 / 2 / 3).
A8: Шина | B8: Щит | C8: Тип

Sheet Линии
A1: ЛИНИЯ (ввод) | P1: КАБЕЛЬ (ввод) | Z1: КАТЕГОРИИ (ввод) | AC1: СХЕМА (ввод) | AM1: DWG (заполняет DLN) | AR1: ЗАМЕЧАНИЯ | DE1: КАТЕГОРИИ (расчёт) | EP1: СХЕМА (расчёт)
A2: Щит | B2: № места | C2: Лист / место | D2: Номер линии | E2: Наименование | F2: Питает щит | G2: Мощность, кВт | H2: Кол-во потребителей (для длины) | I2: Кол-во фаз | J2: Напряжение | K2: Группа Кс (Быт/Сил/Пост/Отоп/ВНГ/Нет; пусто = по коду) | L2: Кс (для Сил) | M2: cos φ (ручн.) | N2: Секция (1/2/3; пусто = 1) | O2: Фаза (ручная) | P2: Длина линии (по плану) | Q2: Лоток | R2: Гофра ПВХ | S2: Гофра ПНД | T2: Потолок - 1/Пол - 2 | U2: Марка кабеля | V2: Кол-во жил | W2: Сечение (ручное) | X2: автомат (ручное) | Y2: К прокл. линии (пусто = общий) | Z2: Вид нагрузки (пусто = по коду) | AA2: Категория надёжности (ввод: I особая / I / II / III; пусто = III) | AB2: Пожарная (ввод: да / нет; пусто = по коду) | AC2: Шина | AD2: Автомат «авто» или текст | AE2: Дифзащита, мА | AF2: Аппарат 1 | AG2: Аппарат 2 | AH2: Аппарат 3 | AI2: Модуль | AJ2: Канал | AK2: Клемма | AL2: Режим | AM2: DWG: гофра ПВХ по плану, м | AN2: DWG: гофра ПНД по плану, м | AO2: DWG: хэндлы полилиний | AP2: DWG: примечание | AQ2: Доп информация из выноски | AR2: Замечания | AS2: _n | AT2: Код | AU2: _часть1 | AV2: Этаж/Шлейф | AW2: _часть2 | AX2: Помещение | AY2: Наименование по коду | AZ2: Наименование (итог) | BA2: _фидер | BB2: _№ щита | BC2: _мест узла | BD2: _№ места (итог) | BE2: _зона | BF2: Р, кВт | BG2: U, В | BH2: Фаз | BI2: Марка (итог) | BJ2: Жил | BK2: Сечение задано | BL2: _тип пуска | BM2: cos φ | BN2: Ток, А | BO2: Автомат | BP2: _k жил | BQ2: _К прокл | BR2: _столбец Iдоп | BS2: Сечение | BT2: _ρ | BU2: _x | BV2: _Lплан | BW2: Длина, м | BX2: _гофра ПВХ | BY2: _гофра ПНД | BZ2: _b | CA2: _sin | CB2: _ΔU, В | CC2: ΔU, % | CD2: ΔU от ВРУ, % | CE2: Допустимо ΔU, % | CF2: _кабель | CG2: _кабель с сечением | CH2: Кабель | CI2: _Zкабеля | CJ2: _Zmax кабеля | CK2: Zпетли в конце, Ом | CL2: Iкз min в конце линии, А | CM2: Iкз max в конце, кА | CN2: Группа Кс (итог) | CO2: Кс | CP2: Секция | CQ2: _Руст (без Нет) | CR2: _Руст быт | CS2: _Рр сил | CT2: _Руст пост | CU2: _Р отопления | CV2: _Рр ВНГ | CW2: _P для cos | CX2: _P·cos | CY2: _фаза № | CZ2: _фаза авто | DA2: _Iпуск двиг. | DB2: _Iпуск LED | DC2: Iпуск, А | DD2: Фаза | DE2: Категория (итог) | DF2: Пожарная (итог) | DG2: _шина группы | DH2: Шина (итог) | DI2: _секция № | DJ2: Тип шины | DK2: Источник для режимов | DL2: Категория обеспечена | DM2: _ранг категории | DN2: _ранг для фидера | DO2: Категория: проверка | DP2: _путь щита | DQ2: Вид нагрузки (итог) | DR2: Лист схемы | DS2: Кабель (строкой) | DT2: _Р схемы | DU2: _Ток схемы | DV2: _фаз | DW2: _дифзащита по коду, мА | DX2: _в кабель выше | DY2: _гр. | DZ2: _гр. (перенос) | EA2: _мин. по типу | EB2: _макс. автомат по кабелю | EC2: _ток группы | ED2: _номинал по току | EE2: _по току | EF2: _мин. по кабелям | EG2: _фаз гр. | EH2: Дифзащита группы, мА | EI2: _дифзащита гр. (0/1) | EJ2: _QF нач. | EK2: _QF гр. | EL2: _аппараты гр. | EM2: _БП/тр-р | EN2: _номинал | EO2: _полюса | EP2: Автомат (схема) | EQ2: _номинал итог | ER2: _префикс | ES2: _модуль нач. | ET2: _модуль гр. | EU2: _модель гр. | EV2: Канал (итог) | EW2: _посл. канал | EX2: _клемма | EY2: Клемма (итог) | EZ2: QF | FA2: _Модуль (схема) | FB2: Проверка автомата | FC2: Проверка канала | FD2: _In гр. | FE2: _автомат гр. | FF2: _дифзащита гр. (строки) | FG2: _мА гр. (строки) | FH2: Iкз / In | FI2: _кратность | FJ2: Отключение ≤ 0,4 с | FK2: Статус | FL2: Icu автомата, кА | FM2: Проверка Icu | FN2: _цепь для бирок | FO2: _цепь с кабелем | FP2: _бирка 1 | FQ2: _бирка 1 линия | FR2: _бирка 2 | FS2: _бирка 2 линия | FT2: _бирка 3 | FU2: _бирка 3 линия | FV2: _бирка 4 | FW2: _бирка 4 линия | FX2: _бирка 5 | FY2: _бирка 5 линия | FZ2: _бирка 6 | GA2: _бирка 6 линия | GB2: _модель (схема) | GC2: _цепь | GD2: _draw | GE2: _bus2 | GF2: _rcd | GG2: _chtype | GH2: _dev1 | GI2: _dev2 | GJ2: _dev3 | GK2: _УГО (рус) | GL2: _sym | GM2: _hasline | GN2: _тип автомата № | GO2: _аппарат 1 № | GP2: _аппарат 2 № | GQ2: _аппарат 3 № | GR2: _кабель клеммы | GS2: _вид клеммы № | GT2: _модуль № | GU2: _модель № | GV2: _уровень | GW2: _№ линии | GX2: _3L клемм | GY2: _доп. проходных
A3: ЩР | B3: 1 | C3: =IF(BD3="","",IF(BE3="вводной узел","узел ","")&"л."&(INT((BD3-1)/Столбцов_на_лист)+1)&" / "&(MOD(BD3-1,Столбцов_на_лист)+1)) -> узел л.1 / 1 | E3: =AY3 | AL3: вручную | AR3: =_xlfn.TEXTJOIN("; ",TRUE,FK3,IF(DO3="НЕ ОБЕСПЕЧЕНА","категория "&DE3&" не обеспечена (есть "&DL3&")",""),IF(LEFT(FM3,3)="Icu",FM3,""),IF(AND(D3<>"",BS3="Не исп"),"сечение не подобрано","")) | AS3: {=ROW()-ROW(Линии[#Headers])} -> 1 | AT3: =IF(D3="","",IFERROR(LEFT(D3,SEARCH(".",D3)-1),D3)) | AU3: =IFERROR(RIGHT(D3,LEN(D3)-SEARCH(".",D3)),"") | AV3: =IFERROR(LEFT(AU3,SEARCH(".",AU3)-1),AU3) | AW3: =IFERROR(RIGHT(AU3,LEN(AU3)-SEARCH(".",AU3)),"") | AX3: =IFERROR(LEFT(AW3,SEARCH(".",AW3)-1),AW3) | AY3: =IF(D3="","",IF(ISERROR(SEARCH(".",D3)),IFERROR(VLOOKUP(D3,Потребители_обозначение,2,FALSE)&"",""),IFERROR(IF(VLOOKUP(AT3,Потребители_обозначение,4,FALSE)=1,VLOOKUP(AT3,Потребители_обозначение,2,FALSE)&" "&VLOOKUP(AV3,Этаж_обозначение,2,FALSE)&" Пом. №"&AX3,VLOOKUP(AT3,Потребители_обозначение,2,FALSE)&" Шлейф №"&AV3),IFERROR(VLOOKUP(D3,Потребители_обозначение,2,FALSE),"")))) | AZ3: =IF(E3<>"",E3,AY3) | BA3: =IF(F3<>"",F3,IF(AND(D3<>"",D3<>A3,ISNUMBER(_xlfn.XMATCH(D3,Щиты[Щит]))),D3,"")) | BB3: =IFERROR(_xlfn.XMATCH(A3,Щиты[Щит]),0) -> 1 | BC3: =IFERROR(N(_xlfn.XLOOKUP(A3,Щиты[Щит],Щиты[Мест под вводной узел])),15) -> 18 | BD3: =IF(B3="-","",IF(ISNUMBER(B3),B3,_xlfn.LET(_xlpm.prev,IF(OR(AS3=1,A3<>A2),0,N(IF(AS3=1,"",BD2))),_xlpm.nx,_xlpm.prev+1,IF(AND(AL3<>"вручную",_xlpm.nx<=BC3),BC3+1,_xlpm.nx)))) -> 1 | BE3: =IF(BD3="","",IF(BD3<=BC3,"вводной узел","линии")) -> вводной узел | BF3: =IF(D3="","",IF(BA3<>"",IFERROR(_xlfn.XLOOKUP(BA3,Щиты[Щит],Щиты[Руст, кВт]),0),N(G3))) | BG3: =IF(J3<>"",J3,IF(D3="","",IFERROR(IF(VLOOKUP(AT3,Потребители_обозначение,8,FALSE)=0,"",VLOOKUP(AT3,Потребители_обозначение,8,FALSE)),""))) | BH3: =IF(I3<>"",I3,IF(D3="","",IFERROR(IF(VLOOKUP(AT3,Потребители_обозначение,9,FALSE)=0,"",VLOOKUP(AT3,Потребители_обозначение,9,FALSE)),""))) | BI3: =IF(U3<>"",U3,IF(D3="","",IFERROR(IF(VLOOKUP(AT3,Потребители_обозначение,6,FALSE)=0,"",VLOOKUP(AT3,Потребители_обозначение,6,FALSE)),""))) | BJ3: =IF(V3<>"",V3,IF(D3="","",IFERROR(IF(VLOOKUP(AT3,Потребители_обозначение,7,FALSE)=0,"",VLOOKUP(AT3,Потребители_обозначение,7,FALSE)),""))) | BK3: =IF(W3<>"",W3,IF(D3="","",IFERROR(IF(VLOOKUP(AT3,Потребители_обозначение,10,FALSE)=0,"",VLOOKUP(AT3,Потребители_обозначение,10,FALSE)),""))) | BL3: =IFERROR(VLOOKUP(AT3,Потребители_обозначение,5,FALSE),0) -> 0 | BM3: {=IF(D3="","",IF(BA3<>"",IFERROR(_xlfn.XLOOKUP(BA3,Щиты[Щит],Щиты[cos φ]),0.95),IF(ISNUMBER(M3),M3,IFERROR(IF(BL3=2,_xlfn.IFS(BH3=3,VLOOKUP(BF3,Справочная_двигатели,8,FALSE),BH3=1,VLOOKUP(BF3,Справочная_двигатели,10,TRUE)),IF(AND(Методика="нормы 2026",CN3="Сил"),0.8,0.95)),0.95))))} | BN3: {=IF(D3="","",IF(BA3<>"",IFERROR(_xlfn.XLOOKUP(BA3,Щиты[Щит],Щиты[Iр, А]),""),IFERROR(_xlfn.IFS(BH3=1,BF3/((Uн_лин/SQRT(3))*BM3),BH3=3,BF3/(SQRT(3)*Uн_лин*BM3)),"")))} | BO3: =IF(D3="","",IF(N(X3)=0,IFERROR(VLOOKUP(BN3,Автомат_номиналы,2,TRUE),""),X3)) | BP3: =IF(N(BJ3)=1,1,IF(BH3=1,1,IF(N(BJ3)>=4,0.92,1))) -> 1 | BQ3: =IF(ISNUMBER(Y3),Y3,К_прокл) -> 1 | BR3: =IF(N(BJ3)=1,1,IF(BH3=1,2,3)) -> 3 | BS3: {=IF(D3="","",IF(N(BK3)<>0,BK3,IFERROR(_xlfn.LET(_xlpm.need,BO3/(BP3*BQ3),_xlpm.t,CHOOSE(BR3,Iдоп_1ж,Iдоп_2ж,Iдоп_3ж),_xlpm.k,_xlfn.XMATCH(_xlpm.need,_xlpm.t,1),IF(ISNA(_xlpm.k),"Не исп",INDEX(Iдоп_S,_xlpm.k))),"Не исп")))} | BT3: =IFERROR(VLOOKUP(BS3,Кабель_сопротивление,3,FALSE),"") | BU3: =IFERROR(VLOOKUP(BS3,Кабель_сопротивление,2,FALSE),"") | BV3: =IF(P3<>"",P3,IF(COUNT(AM3,AN3)=0,"",ROUNDUP(SUM(AM3,AN3),0))) | BW3: =IF(D3="","",IFERROR(IF(VLOOKUP(AT3,Потребители_обозначение,4,FALSE)=1,VLOOKUP(AT3,Потребители_обозначение,3,FALSE)*(H3*2-1)+BV3+VLOOKUP(AV3,Этаж_обозначение,3,FALSE)+VLOOKUP(AV3,Этаж_обозначение,4,FALSE),VLOOKUP(AT3,Потребители_обозначение,3,FALSE)*(H3*2-1)+BV3),BV3)) | BX3: =IF(R3<>"",R3,IF(OR(BV3="",T3=""),"",IF(T3=1,MAX(0,BW3-ROUNDUP(N(AN3),0)-4),ROUNDUP(N(AM3),0)))) | BY3: =IF(S3<>"",S3,IF(OR(BV3="",T3=""),"",IF(T3=2,MAX(0,BW3-ROUNDUP(N(AM3),0)-4),ROUNDUP(N(AN3),0)))) | BZ3: =IF(BH3=1,2,IF(BH3=3,1,"")) | CA3: =IFERROR(ROUND(SIN(ACOS(BM3)),2),"") | CB3: =IFERROR(BZ3*(BT3*BW3/BS3*BM3+BU3*BW3*CA3/1000)*BN3,"") | CC3: =IFERROR(ROUNDUP(CB3/((Uн_лин/SQRT(3))*1000)*100,2),"") | CD3: =IF(ISNUMBER(CC3),CC3+IFERROR(_xlfn.XLOOKUP(A3,Щиты[Щит],Щиты[ΔU до шин, %]),0),"") | CE3: =IF(D3="","",IF(IFERROR(VLOOKUP(AT3,УГО_спр,2,FALSE),"")="Светильник",3,4)+IF(Методика="нормы 2026",MIN(0.5,MAX(0,N(BW3)-100)*0.005),0)) | CF3: =IFERROR(VLOOKUP(BI3,Кабель_обозначение,2,FALSE),"") | CG3: =IFERROR(IF(VLOOKUP(BI3,Кабель_обозначение,3,FALSE)=1,CF3&" ("&BJ3&"х"&BS3&")",CF3),"") | CH3: =IF(OR(D3="",CF3="",AND(G3<>"",NOT(ISNUMBER(G3)))),"",IF(BS3=0,CF3,CG3&CHAR(10)&"L="&BW3&"-"&CC3&"%")) | CI3: =IFERROR(2*ρкз_Cu*BW3/BS3,"") | CJ3: =IFERROR(0.0175*N(BW3)/BS3,"") | CK3: =IFERROR(IF(OR(D3="",NOT(ISNUMBER(BS3)),N(BW3)=0),"",_xlfn.XLOOKUP(A3,Щиты[Щит],Щиты[Zпетли на шинах, Ом])+CI3),"") | CL3: =IF(ISNUMBER(CK3),c_min*(Uн_лин*1000/SQRT(3))/CK3,"") | CM3: =IFERROR(IF(OR(D3="",NOT(ISNUMBER(BS3))),"",1.05*(Uн_лин*1000/SQRT(3))/(_xlfn.XLOOKUP(A3,Щиты[Щит],Щиты[Zmax на шинах, Ом])+CJ3)/1000),"") | CN3: =IF(D3="","",IF(BA3<>"","Щит",IF(K3<>"",K3,IF(ISNUMBER(L3),"Сил",IF(IFERROR(_xlfn.XLOOKUP(AT3,Коды_код,Коды_группа)&"","")="","Быт",_xlfn.XLOOKUP(AT3,Коды_код,Коды_группа)&""))))) | CO3: =IF(CN3="Щит","щит",IF(CN3="","",IF(CN3="Быт",IFERROR(_xlfn.XLOOKUP(A3,Щиты[Щит],Щиты[Кс быт]),1),IF(CN3="Сил",IF(ISNUMBER(L3),L3,IF(Методика="нормы 2026",IFERROR(_xlfn.XLOOKUP(A3,Щиты[Щит],Щиты[Кс силовых (табл. 7.5)]),1),1)),IF(OR(CN3="Пост",CN3="Отоп"),1,IF(CN3="ВНГ",0.7,0)))))) | CP3: =IF(CN3="","",IFERROR(MIN(3,MAX(1,INT(--N3))),1)) | CQ3: =IF(OR(CN3="",CN3="Нет",CN3="Щит"),0,N(BF3)) -> 0 | CR3: =IF(CN3="Быт",N(BF3),0) -> 0 | CS3: =IF(CN3="Сил",N(BF3)*N(CO3),0) -> 0 | CT3: =IF(CN3="Пост",N(BF3),0) -> 0 | CU3: =IF(CN3="Отоп",N(BF3),0) -> 0 | CV3: =IF(CN3="ВНГ",N(BF3)*0.7,0) -> 0 | CW3: =IF(OR(D3="",CN3="Щит"),0,N(BF3)) -> 0 | CX3: =IF(OR(D3="",CN3="Щит"),0,N(BF3)*N(BM3)) -> 0 | CY3: =_xlfn.LET(_xlpm.prev,IF(OR(OR(AS3=1,A3<>A2)),0,N(IF(AS3=1,"",CY2))),IF(OR(D3="",BH3=3),_xlpm.prev,IF(_xlpm.prev>=3,1,_xlpm.prev+1))) -> 0 | CZ3: =IF(D3="","",IF(BH3=3,"L1,L2,L3","L"&MAX(1,CY3))) | DA3: {=IFERROR(IF(BL3=2,_xlfn.IFS(BH3=3,VLOOKUP(BF3,Справочная_двигатели,3,FALSE),BH3=1,VLOOKUP(BF3,Справочная_двигатели,5,TRUE)),0),0)} -> 0 | DB3: =IFERROR(IF(BL3=3,VLOOKUP(BF3,Справочная_ЛЭД,2,TRUE),0),0) -> 0 | DC3: =IF(D3="","",IF(DA3=0,DB3,DA3)) | DD3: =IF(D3="","",IF(O3="упр","",IF(O3="",CZ3,IF(O3&""="1,2,3","L1,L2,L3","L"&O3)))) | DE3: {=IF(D3="","",IFERROR(INDEX({"I особая","I","II","III"},MATCH(TRIM(AA3&""),{"I особая","I","II","III"},0)),"III"))} | DF3: =IF(D3="","",IF(TRIM(AB3&"")<>"",IF(LOWER(TRIM(AB3&""))="да","да","нет"),IF(IFERROR(_xlfn.XLOOKUP(AT3,Коды_код,Коды_пожарная),"")="да","да","нет"))) | DG3: =IF(AC3<>"",AC3,IF(AD3<>"","",IF(EK3="","",IF(AS3=1,"",DG2)))) | DH3: =IF(D3="","",IF(DG3="","основная",DG3)) | DI3: =IFERROR(MIN(3,MAX(1,INT(--N3))),1) -> 1 | DJ3: {=IF(D3="","",_xlfn.LET(_xlpm.t,IFERROR(_xlfn.XLOOKUP(1,(Шины[Шина]=DH3)*(((Шины[Щит]=A3)+(Шины[Щит]=""))>0),Шины[Тип]),"")&"",IF(_xlpm.t<>"",_xlpm.t,IF(ISNUMBER(SEARCH("ИБП",DH3)),"ИБП",IF(ISNUMBER(SEARCH("ДГУ",DH3)),"ДГУ","Ввод "&DI3)))))} | DK3: =IF(D3="","",IF(OR(DJ3="ИБП",DJ3="ДГУ"),DJ3,IF(LEFT(DJ3,5)="Ввод ",DJ3,"Ввод "&DI3))) | DL3: =IF(D3="","",IF(OR(DJ3="ИБП",DJ3="ДГУ"),"I особая",IF(DJ3="Одиночная","III",_xlfn.XLOOKUP(A3,Щиты[Щит],Щиты[Категория шины «Ввод»],"III")))) | DM3: =IF(D3="",0,IFERROR(MATCH(DE3,{"III","II","I","I особая"},0),1)) -> 0 | DN3: =IF(OR(DJ3="ИБП",DJ3="ДГУ"),MIN(DM3,3),DM3) -> 0 | DO3: =IF(D3="","",IF(DM3>IFERROR(MATCH(DL3,{"III","II","I","I особая"},0),1),"НЕ ОБЕСПЕЧЕНА","ОК")) | DP3: =IF(A3="","",_xlfn.XLOOKUP(A3,Щиты[Щит],Щиты[Путь],"")) -> |ЩР| | DQ3: =IF(D3="","",IF(Z3<>"",Z3,IF(IFERROR(_xlfn.XLOOKUP(AT3,Коды_код,Коды_вид)&"","")="","Прочее",_xlfn.XLOOKUP(AT3,Коды_код,Коды_вид)&""))) | DR3: =IF(BD3="","",INT((BD3-1)/Столбцов_на_лист)+1) -> 1 | DS3: =IF(D3="","",SUBSTITUTE(CH3,CHAR(10)," ")) | DT3: =IF(D3="","",IFERROR(--BF3,"")) | DU3: =IF(D3="","",IFERROR(ROUNDUP(BN3,2),"")) | DV3: =IF(D3="","",IFERROR(--BH3,1)) | DW3: =IF(AT3="",0,_xlfn.LET(_xlpm.v,IFERROR(VLOOKUP(D3,УГО_спр,3,FALSE),IFERROR(VLOOKUP(AT3,УГО_спр,3,FALSE),IFERROR(VLOOKUP(LEFT(AT3,2),УГО_спр,3,FALSE),""))),IF(_xlpm.v="да",30,IF(ISNUMBER(_xlpm.v),_xlpm.v,0)))) -> 0 | DX3: =IF(OR(AJ3="+",AND(D3<>"",D3=IF(AS3=1,"",D2))),1,0) -> 0 | DY3: =IF(BD3="","",IF(AD3<>"",COUNTIFS(A$3:A3,A3,AD$3:AD3,"?*"),IF(OR(OR(AS3=1,A3<>A2),AL3="вручную"),"",IF(AS3=1,"",DZ2)))) | DZ3: =IF(BD3="",IF(OR(AS3=1,A3<>A2),"",IF(AS3=1,"",DZ2)),DY3) | EA3: =IF(D3="",0,MAX(IFERROR(--X3,0),IFERROR(--VLOOKUP(D3,УГО_спр,4,FALSE),IFERROR(--VLOOKUP(AT3,УГО_спр,4,FALSE),IFERROR(--VLOOKUP(LEFT(AT3,2),УГО_спр,4,FALSE),0))))) -> 0 | EB3: =IF(D3="","",IFERROR(LOOKUP(INDEX(CHOOSE(BR3,Iдоп_1ж,Iдоп_2ж,Iдоп_3ж),MATCH(BS3,Iдоп_S,0))*BP3*BQ3,{6,10,16,20,25,32,40,50,63,80,100,125,160,200,250,315,400,500,630}),"")) | EC3: =IF(AD3="","",SUMIFS(Линии[_Ток схемы],Линии[_гр.],DY3,Линии[Щит],A3,Линии[_в кабель выше],0)) | ED3: =IF(AD3="","",IFERROR(VLOOKUP(EC3,Автомат_номиналы,2,TRUE),"")) | EE3: =IF(AD3="","",MAX(N(ED3),_xlfn.MAXIFS(Линии[_мин. по типу],Линии[_гр.],DY3,Линии[Щит],A3))) | EF3: =IF(AD3="","",_xlfn.MINIFS(Линии[_макс. автомат по кабелю],Линии[_гр.],DY3,Линии[Щит],A3)) | EG3: =IF(AD3="","",MAX(1,_xlfn.MAXIFS(Линии[_фаз],Линии[_гр.],DY3,Линии[Щит],A3))) | EH3: =IF(AD3="","",IF(AND(AD3<>"авто",AD3<>"+"),IF(ISNUMBER(SEARCH("мА",AD3)),IFERROR(--TRIM(RIGHT(SUBSTITUTE(LEFT(AD3,SEARCH("мА",AD3)-1)," ",REPT(" ",9)),6)),30),0),IF(AE3="нет",0,IF(ISNUMBER(AE3),AE3,IF(AE3="да",30,_xlfn.MINIFS(Линии[_дифзащита по коду, мА],Линии[_гр.],DY3,Линии[Щит],A3,Линии[_дифзащита по коду, мА],">0")))))) | EI3: =IF(AD3="","",IF(N(EH3)>0,1,0)) | EJ3: =IF(AD3="","",IF(EI3=1,"QFD","QF")&DY3) | EK3: =IF(EJ3<>"",EJ3,IF(OR(OR(AS3=1,A3<>A2),AL3="вручную"),"",IF(AS3=1,"",EK2))) | EL3: =IF(EJ3<>"",_xlfn.TEXTJOIN(" → ",TRUE,AF3,AG3,AH3),IF(EK3="","",IF(AS3=1,"",EL2))) | EM3: =IF(EL3="",0,IF(OR(LEFT(EL3,2)="T ",LEFT(EL3,2)="Т ",ISNUMBER(SEARCH("→ T ",EL3)),ISNUMBER(SEARCH("→ Т ",EL3)),ISNUMBER(SEARCH("БП",EL3))),1,0)) -> 0 | EN3: =IF(AD3="","",IF(EM3=1,MAX(EE3,Мин_автомат_БП),EE3)) | EO3: =IF(AD3="","",IF(EG3>=3,IF(EI3=1,"4P","3P"),IF(EI3=1,"2P","1P"))) | EP3: =IF(AD3="","",IF(AND(AD3<>"авто",AD3<>"+"),AD3,EO3&" С"&EN3&"А"&IF(EI3=1," "&EH3&"мА",""))) | EQ3: =IF(EP3="","",_xlfn.LET(_xlpm.t,SUBSTITUTE(SUBSTITUTE(UPPER(EP3),"С","C"),"А","A"),_xlpm.c,FIND("C",_xlpm.t),IFERROR(--MID(_xlpm.t,_xlpm.c+1,FIND("A",_xlpm.t&"A",_xlpm.c)-_xlpm.c-1),""))) | ER3: =IF(OR(AI3="",AI3="-"),"",IFERROR(VLOOKUP(AI3,Модули_спр,2,FALSE),"R")) | ES3: =IF(ER3="","",ER3&"."&COUNTIFS(A$3:A3,A3,ER$3:ER3,ER3)) | ET3: =IF(AI3="-","",IF(ES3<>"",ES3,IF(OR(AS3=1,A3<>A2),"",IF(AS3=1,"",ET2)))) | EU3: =IF(ET3="","",IF(AND(AI3<>"",AI3<>"-"),AI3,IF(AS3=1,"",EU2))) | EV3: =IF(AJ3="=",IF(AS3=1,"",EW2),IF(ISNUMBER(AJ3),AJ3,IF(ET3="","",IF(OR(D3<>"",AJ3="+",AJ3="р"),IF(OR(ES3<>"",IF(AS3=1,"",EW2)=""),1,IF(AS3=1,"",EW2)+1),"")))) | EW3: =IF(EV3<>"",EV3,IF(OR(OR(AS3=1,A3<>A2),AI3="-",ES3<>""),"",IF(AS3=1,"",EW2))) | EX3: =IF(AJ3="б/к",0,IF(OR(ISNUMBER(SEARCH("L=",CH3)),AJ3="+",AJ3="="),1,0)) -> 0 | EY3: =IF(AK3="нет","",IF(AK3<>"",AK3,IF(EX3=1,"XT"&COUNTIFS(A$3:A3,A3,EX$3:EX3,1),""))) | EZ3: =IF(OR(D3<>"",EV3<>"",EX3=1),EK3,"") | FA3: =IF(OR(EV3<>"",AND(AI3<>"",AI3<>"-")),ET3,"") | FB3: =IF(AD3="","",IF(NOT(ISNUMBER(EQ3)),"",IF(EC3>EQ3,"ПЕРЕГРУЗ",IF(AND(EM3=0,EF3>0,EQ3>EF3),"КАБЕЛЬ НЕ ЗАЩИЩЁН","ok")))) | FC3: =IF(OR(EV3="",ET3=""),"",IF(EV3>IFERROR(VLOOKUP(EU3,Модули_спр,3,FALSE),99),"ЛИШНИЙ КАНАЛ",IF(AND(AJ3<>"=",COUNTIFS(Линии[_модуль гр.],ET3,Линии[Канал (итог)],EV3,Линии[Канал],"<>=",Линии[Щит],A3)>1),"ДУБЛЬ КАНАЛА",""))) | FD3: =IF(AD3<>"",EQ3,IF(EK3="","",IF(AS3=1,"",FD2))) | FE3: =IF(AD3<>"",EP3,IF(EK3="","",IF(AS3=1,"",FE2))) | FF3: =IF(AD3<>"",EI3,IF(EK3="","",IF(AS3=1,"",FF2))) | FG3: =IF(AD3<>"",EH3,IF(EK3="","",IF(AS3=1,"",FG2))) | FH3: =IFERROR(IF(ISNUMBER(CL3),CL3/IFERROR(--FD3,N(BO3)),""),"") | FI3: =IF(OR(ISNUMBER(SEARCH(" B"," "&FE3)),ISNUMBER(SEARCH(" В"," "&FE3))),5,IF(ISNUMBER(SEARCH(" D"," "&FE3)),20,10)) -> 10 | FJ3: =IF(NOT(ISNUMBER(FH3)),"",IF(FH3>=FI3,"ok",IF(N(FF3)=1,"ok (дифзащита "&FG3&" мА)","мало: Iкз < "&FI3&"·In"))) | FK3: =IF(AND(D3="",EZ3=""),"",_xlfn.TEXTJOIN("; ",TRUE,IF(AND(D3<>"",DD3=""),"нет фазы",""),IF(AND(D3<>"",N(DT3)=0,CN3<>"Нет"),"нет мощности",""),IF(AND(EY3<>"",COUNTIFS(Линии[Щит],A3,Линии[Клемма (итог)],EY3)>1),"дубль клеммы "&EY3,""),IF(AND(FB3<>"",FB3<>"ok"),FB3,""),IF(FC3<>"",FC3,""),IF(AND(ISNUMBER(SEARCH("(5х",DS3)),N(DV3)=1),"5 жил на 1 фазе",""),IF(AND(AT3="R",AD3<>"",OR(N(EH3)=0,N(EH3)>30)),"розетка без дифзащиты до 30 мА",""),IFERROR(IF(AND(ISNUMBER(CD3),CD3>CE3),"потери "&FIXED(CD3,1)&" % > "&CE3&" %",""),""),IFERROR(IF(LEFT(FJ3,4)="мало","Iкз мало — отключение > 0,4 с",""),""),IF(AND(D3<>"",BD3=""),"не на схеме",""))) | FL3: =IF(AD3="","",_xlfn.LET(_xlpm.t,IFERROR(_xlfn.XLOOKUP(EP3,Каталог!$U$4:$U$500,Каталог!$G$4:$G$500),""),_xlpm.k,SEARCH("кА",_xlpm.t),IFERROR(--TRIM(RIGHT(SUBSTITUTE(MID(_xlpm.t,MAX(1,_xlpm.k-4),_xlpm.k-MAX(1,_xlpm.k-4))," ",REPT(" ",9)),5)),""))) | FM3: =IF(OR(FL3="",AD3=""),"",IF(_xlfn.XLOOKUP(A3,Щиты[Щит],Щиты[Iкз max на шинах, кА],"")="","",IF(FL3<_xlfn.XLOOKUP(A3,Щиты[Щит],Щиты[Iкз max на шинах, кА]),"Icu "&FL3&" кА < Iкз max","ok"))) | FN3: =IF(OR(AL3="вручную",BD3="",AND(D3="",EY3="")),"",_xlfn.TEXTJOIN("|",TRUE,EK3,SUBSTITUTE(EL3," → ","|"),IF(ET3<>"",ET3&IF(EV3<>""," к."&EV3,""),""),EY3)) | FO3: =IF(FN3="","",FN3&IF(D3<>"","|кабель "&CG3&" → "&AZ3,"")) | FP3: {=IF(FO3="","",_xlfn.LET(_xlpm.nd,_xlfn.TEXTSPLIT(FO3,"|"),IF(COLUMNS(_xlpm.nd)>1,A3&"¦"&INDEX(_xlpm.nd,1)&"¦"&INDEX(_xlpm.nd,2),"")))} | FQ3: =IF(FP3="","",D3&"¦"&AZ3) | FR3: {=IF(FO3="","",_xlfn.LET(_xlpm.nd,_xlfn.TEXTSPLIT(FO3,"|"),IF(COLUMNS(_xlpm.nd)>2,A3&"¦"&INDEX(_xlpm.nd,2)&"¦"&INDEX(_xlpm.nd,3),"")))} | FS3: =IF(FR3="","",D3&"¦"&AZ3) | FT3: {=IF(FO3="","",_xlfn.LET(_xlpm.nd,_xlfn.TEXTSPLIT(FO3,"|"),IF(COLUMNS(_xlpm.nd)>3,A3&"¦"&INDEX(_xlpm.nd,3)&"¦"&INDEX(_xlpm.nd,4),"")))} | FU3: =IF(FT3="","",D3&"¦"&AZ3) | FV3: {=IF(FO3="","",_xlfn.LET(_xlpm.nd,_xlfn.TEXTSPLIT(FO3,"|"),IF(COLUMNS(_xlpm.nd)>4,A3&"¦"&INDEX(_xlpm.nd,4)&"¦"&INDEX(_xlpm.nd,5),"")))} | FW3: =IF(FV3="","",D3&"¦"&AZ3) | FX3: {=IF(FO3="","",_xlfn.LET(_xlpm.nd,_xlfn.TEXTSPLIT(FO3,"|"),IF(COLUMNS(_xlpm.nd)>5,A3&"¦"&INDEX(_xlpm.nd,5)&"¦"&INDEX(_xlpm.nd,6),"")))} | FY3: =IF(FX3="","",D3&"¦"&AZ3) | FZ3: {=IF(FO3="","",_xlfn.LET(_xlpm.nd,_xlfn.TEXTSPLIT(FO3,"|"),IF(COLUMNS(_xlpm.nd)>6,A3&"¦"&INDEX(_xlpm.nd,6)&"¦"&INDEX(_xlpm.nd,7),"")))} | GA3: =IF(FZ3="","",D3&"¦"&AZ3) | GB3: =IF(FA3="","",EU3) | GC3: =IF(AND(D3="",EV3="",EY3=""),"",_xlfn.TEXTJOIN(" → ",TRUE,EK3,EL3,IF(ET3<>"",ET3&IF(EV3<>""," к."&EV3,""),IF(EV3<>"","к."&EV3,"")),EY3,IF(DX3=1,"(в кабель выше)",""))) | GD3: =IF(OR(BD3="",AL3="вручную",AND(BE3="вводной узел",AL3<>"рисовать")),0,1) -> 0 | GE3: =IF(AC3="",0,1) -> 0 | GF3: =IF(EJ3="",0,IF(LEFT(EJ3,3)="QFD",1,0)) -> 0 | GG3: =IF(AJ3="=","=",IF(AJ3="+","+",IF(AJ3="р","R",""))) | GH3: =IF(AF3="","",IF(OR(LEFT(AF3,1)="T",LEFT(AF3,1)="Т"),"T",IF(LEFT(UPPER(AF3),2)="БП","PS",IF(OR(LEFT(UPPER(AF3),2)="МК",LEFT(UPPER(AF3),2)="MK"),"MK",IF(OR(LEFT(UPPER(AF3),2)="КМ",LEFT(UPPER(AF3),2)="KM"),"KM","X"))))) | GI3: =IF(AG3="","",IF(OR(LEFT(AG3,1)="T",LEFT(AG3,1)="Т"),"T",IF(LEFT(UPPER(AG3),2)="БП","PS",IF(OR(LEFT(UPPER(AG3),2)="МК",LEFT(UPPER(AG3),2)="MK"),"MK",IF(OR(LEFT(UPPER(AG3),2)="КМ",LEFT(UPPER(AG3),2)="KM"),"KM","X"))))) | GJ3: =IF(AH3="","",IF(OR(LEFT(AH3,1)="T",LEFT(AH3,1)="Т"),"T",IF(LEFT(UPPER(AH3),2)="БП","PS",IF(OR(LEFT(UPPER(AH3),2)="МК",LEFT(UPPER(AH3),2)="MK"),"MK",IF(OR(LEFT(UPPER(AH3),2)="КМ",LEFT(UPPER(AH3),2)="KM"),"KM","X"))))) | GK3: =IF(D3="","",IFERROR(VLOOKUP(D3,УГО_спр,2,FALSE),IFERROR(VLOOKUP(AT3,УГО_спр,2,FALSE),IFERROR(VLOOKUP(LEFT(AT3,2),УГО_спр,2,FALSE),"")))) | GL3: =IF(D3="","",IF(OR(GK3="",GK3=0),"BOX",IFERROR(IF(VLOOKUP(GK3,УГО_блоки,3,FALSE)&""<>"",VLOOKUP(GK3,УГО_блоки,3,FALSE),VLOOKUP(GK3,УГО_блоки,2,FALSE)),GK3))) | GM3: =IF(D3="",0,1) -> 0 | GN3: =IF(EP3="","",IF(COUNTIF(EP$3:EP3,EP3)=1,MAX(GN$2:GN2)+1,"")) | GO3: =IF(AF3="","",IF(COUNTIF(AF$3:AF3,AF3)+COUNTIF(AG$2:AG2,AF3)+COUNTIF(AH$2:AH2,AF3)=1,MAX(GO$2:GQ2)+1,"")) | GP3: =IF(AG3="","",IF(COUNTIF(AF$3:AF3,AG3)+COUNTIF(AG$3:AG3,AG3)+COUNTIF(AH$2:AH2,AG3)=1,MAX(GO$2:GQ2,GO3)+1,"")) | GQ3: =IF(AH3="","",IF(COUNTIF(AF$3:AF3,AH3)+COUNTIF(AG$3:AG3,AH3)+COUNTIF(AH$3:AH3,AH3)=1,MAX(GO$2:GQ2,GO3,GP3)+1,"")) | GR3: =IF(EX3=1,IFERROR(MID(DS3,FIND(" (",DS3)+2,FIND(")",DS3,FIND(" (",DS3))-FIND(" (",DS3)-2),"?"),"") | GS3: =IF(GR3="","",IF(COUNTIF(GR$3:GR3,GR3)=1,MAX(GS$2:GS2)+1,"")) | GT3: =IF(ES3="","",COUNTIF(ES$3:ES3,"?*")) | GU3: =IF(OR(ES3="",EU3=""),"",IF(COUNTIFS(ES$3:ES3,"?*",EU$3:EU3,EU3)=1,MAX(GU$2:GU2)+1,"")) | GV3: =IF(FK3="",0,IF(OR(ISNUMBER(SEARCH("дубль",FK3)),ISNUMBER(SEARCH("ПЕРЕГРУЗ",FK3)),ISNUMBER(SEARCH("ЗАЩИЩ",FK3)),ISNUMBER(SEARCH("КАНАЛ",FK3)),ISNUMBER(SEARCH("без диф",FK3))),2,1)) -> 0 | GW3: =IF(D3="","",COUNTIF(D$3:D3,"?*")) | GX3: =IF(EX3<>1,0,_xlfn.LET(_xlpm.k,MAX(IFERROR(--VLOOKUP(D3,УГО_спр,5,FALSE),0),IFERROR(--VLOOKUP(AT3,УГО_спр,5,FALSE),0),IFERROR(--VLOOKUP(LEFT(AT3,2),УГО_спр,5,FALSE),0)),IF(_xlpm.k>0,_xlpm.k,IF(IFERROR(--LEFT(SUBSTITUTE(GR3,"x","х"),FIND("х",SUBSTITUTE(GR3,"x","х"))-1),3)>3,Каталог!$S$9,1)))) -> 0 | GY3: =IF(EX3<>1,0,MAX(0,IFERROR(--LEFT(SUBSTITUTE(GR3,"x","х"),FIND("х",SUBSTITUTE(GR3,"x","х"))-1),3)-3*GX3)) -> 0
